2017-03-28 03:24:00,927 [Thread-2:20300] [django.request:256] [base:handle_uncaught_exception] [ERROR]- Internal Server Error: /
Traceback (most recent call last):
  File "e:\python27\lib\site-packages\django\core\handlers\base.py", line 132, in get_response
    response = wrapped_callback(request, *callback_args, **callback_kwargs)
  File "F:\workspaces\Linux_learn2\blog\views.py", line 58, in index
    return render(request, 'index.html', locals())
  File "e:\python27\lib\site-packages\django\shortcuts.py", line 67, in render
    template_name, context, request=request, using=using)
  File "e:\python27\lib\site-packages\django\template\loader.py", line 99, in render_to_string
    return template.render(context, request)
  File "e:\python27\lib\site-packages\django\template\backends\django.py", line 74, in render
    return self.template.render(context)
  File "e:\python27\lib\site-packages\django\template\base.py", line 208, in render
    with context.bind_template(self):
  File "e:\python27\Lib\contextlib.py", line 17, in __enter__
    return self.gen.next()
  File "e:\python27\lib\site-packages\django\template\context.py", line 235, in bind_template
    updates.update(processor(self.request))
  File "F:\workspaces\Linux_learn2\blog\views.py", line 26, in global_setting
    archive_list = Article.objects.distinct_date()
  File "F:\workspaces\Linux_learn2\blog\models.py", line 58, in distinct_date
    date = date['date_publish'].strftime('%Y/%m鏂囩珷瀛樻。')
UnicodeEncodeError: 'ascii' codec can't encode characters in position 5-8: ordinal not in range(128)
2017-03-28 03:24:01,526 [Thread-3:20236] [django.request:170] [base:get_response] [WARNING]- Not Found: /favicon.ico
2017-03-28 03:25:27,661 [Thread-2:19284] [django.request:256] [base:handle_uncaught_exception] [ERROR]- Internal Server Error: /
Traceback (most recent call last):
  File "e:\python27\lib\site-packages\django\core\handlers\base.py", line 132, in get_response
    response = wrapped_callback(request, *callback_args, **callback_kwargs)
  File "F:\workspaces\Linux_learn2\blog\views.py", line 58, in index
    return render(request, 'index.html', locals())
  File "e:\python27\lib\site-packages\django\shortcuts.py", line 67, in render
    template_name, context, request=request, using=using)
  File "e:\python27\lib\site-packages\django\template\loader.py", line 99, in render_to_string
    return template.render(context, request)
  File "e:\python27\lib\site-packages\django\template\backends\django.py", line 74, in render
    return self.template.render(context)
  File "e:\python27\lib\site-packages\django\template\base.py", line 208, in render
    with context.bind_template(self):
  File "e:\python27\Lib\contextlib.py", line 17, in __enter__
    return self.gen.next()
  File "e:\python27\lib\site-packages\django\template\context.py", line 235, in bind_template
    updates.update(processor(self.request))
  File "F:\workspaces\Linux_learn2\blog\views.py", line 26, in global_setting
    archive_list = Article.objects.distinct_date()
  File "F:\workspaces\Linux_learn2\blog\models.py", line 58, in distinct_date
    date = date['date_publish'].strftime('%Y/%m鏂囩珷瀛樻。')
UnicodeEncodeError: 'ascii' codec can't encode characters in position 5-8: ordinal not in range(128)
2017-03-28 03:27:44,500 [Thread-2:21448] [django.request:256] [base:handle_uncaught_exception] [ERROR]- Internal Server Error: /
Traceback (most recent call last):
  File "e:\python27\lib\site-packages\django\core\handlers\base.py", line 132, in get_response
    response = wrapped_callback(request, *callback_args, **callback_kwargs)
  File "F:\workspaces\Linux_learn2\blog\views.py", line 58, in index
    return render(request, 'index.html', locals())
  File "e:\python27\lib\site-packages\django\shortcuts.py", line 67, in render
    template_name, context, request=request, using=using)
  File "e:\python27\lib\site-packages\django\template\loader.py", line 99, in render_to_string
    return template.render(context, request)
  File "e:\python27\lib\site-packages\django\template\backends\django.py", line 74, in render
    return self.template.render(context)
  File "e:\python27\lib\site-packages\django\template\base.py", line 208, in render
    with context.bind_template(self):
  File "e:\python27\Lib\contextlib.py", line 17, in __enter__
    return self.gen.next()
  File "e:\python27\lib\site-packages\django\template\context.py", line 235, in bind_template
    updates.update(processor(self.request))
  File "F:\workspaces\Linux_learn2\blog\views.py", line 26, in global_setting
    archive_list = Article.objects.distinct_date()
  File "F:\workspaces\Linux_learn2\blog\models.py", line 58, in distinct_date
    date = date['date_publish'].strftime('%Y/%m鏂囩珷瀛樻。')
UnicodeEncodeError: 'ascii' codec can't encode characters in position 5-8: ordinal not in range(128)
2017-03-28 03:28:17,415 [Thread-2:21388] [django.request:256] [base:handle_uncaught_exception] [ERROR]- Internal Server Error: /
Traceback (most recent call last):
  File "e:\python27\lib\site-packages\django\core\handlers\base.py", line 132, in get_response
    response = wrapped_callback(request, *callback_args, **callback_kwargs)
  File "F:\workspaces\Linux_learn2\blog\views.py", line 58, in index
    return render(request, 'index.html', locals())
  File "e:\python27\lib\site-packages\django\shortcuts.py", line 67, in render
    template_name, context, request=request, using=using)
  File "e:\python27\lib\site-packages\django\template\loader.py", line 99, in render_to_string
    return template.render(context, request)
  File "e:\python27\lib\site-packages\django\template\backends\django.py", line 74, in render
    return self.template.render(context)
  File "e:\python27\lib\site-packages\django\template\base.py", line 208, in render
    with context.bind_template(self):
  File "e:\python27\Lib\contextlib.py", line 17, in __enter__
    return self.gen.next()
  File "e:\python27\lib\site-packages\django\template\context.py", line 235, in bind_template
    updates.update(processor(self.request))
  File "F:\workspaces\Linux_learn2\blog\views.py", line 26, in global_setting
    archive_list = Article.objects.distinct_date()
  File "F:\workspaces\Linux_learn2\blog\models.py", line 57, in distinct_date
    date = date['date_publish'].strftime('%Y/%m鏂囩珷瀛?)
UnicodeEncodeError: 'ascii' codec can't encode characters in position 5-7: ordinal not in range(128)
2017-03-28 03:28:46,092 [Thread-2:20860] [django.request:256] [base:handle_uncaught_exception] [ERROR]- Internal Server Error: /
Traceback (most recent call last):
  File "e:\python27\lib\site-packages\django\core\handlers\base.py", line 132, in get_response
    response = wrapped_callback(request, *callback_args, **callback_kwargs)
  File "F:\workspaces\Linux_learn2\blog\views.py", line 58, in index
    return render(request, 'index.html', locals())
  File "e:\python27\lib\site-packages\django\shortcuts.py", line 67, in render
    template_name, context, request=request, using=using)
  File "e:\python27\lib\site-packages\django\template\loader.py", line 99, in render_to_string
    return template.render(context, request)
  File "e:\python27\lib\site-packages\django\template\backends\django.py", line 74, in render
    return self.template.render(context)
  File "e:\python27\lib\site-packages\django\template\base.py", line 208, in render
    with context.bind_template(self):
  File "e:\python27\Lib\contextlib.py", line 17, in __enter__
    return self.gen.next()
  File "e:\python27\lib\site-packages\django\template\context.py", line 235, in bind_template
    updates.update(processor(self.request))
  File "F:\workspaces\Linux_learn2\blog\views.py", line 26, in global_setting
    archive_list = Article.objects.distinct_date()
  File "F:\workspaces\Linux_learn2\blog\models.py", line 57, in distinct_date
    date = date['date_publish'].strftime('%Y/%m鏂囩珷瀛樻。')
UnicodeEncodeError: 'ascii' codec can't encode characters in position 5-8: ordinal not in range(128)
2017-03-28 03:29:24,821 [Thread-2:21700] [django.request:256] [base:handle_uncaught_exception] [ERROR]- Internal Server Error: /
Traceback (most recent call last):
  File "e:\python27\lib\site-packages\django\core\handlers\base.py", line 132, in get_response
    response = wrapped_callback(request, *callback_args, **callback_kwargs)
  File "F:\workspaces\Linux_learn2\blog\views.py", line 58, in index
    return render(request, 'index.html', locals())
  File "e:\python27\lib\site-packages\django\shortcuts.py", line 67, in render
    template_name, context, request=request, using=using)
  File "e:\python27\lib\site-packages\django\template\loader.py", line 99, in render_to_string
    return template.render(context, request)
  File "e:\python27\lib\site-packages\django\template\backends\django.py", line 74, in render
    return self.template.render(context)
  File "e:\python27\lib\site-packages\django\template\base.py", line 208, in render
    with context.bind_template(self):
  File "e:\python27\Lib\contextlib.py", line 17, in __enter__
    return self.gen.next()
  File "e:\python27\lib\site-packages\django\template\context.py", line 235, in bind_template
    updates.update(processor(self.request))
  File "F:\workspaces\Linux_learn2\blog\views.py", line 26, in global_setting
    archive_list = Article.objects.distinct_date
  File "F:\workspaces\Linux_learn2\blog\models.py", line 58, in distinct_date
    date = date['date_publish'].strftime('%Y/%m鏂囩珷瀛樻。')
UnicodeEncodeError: 'ascii' codec can't encode characters in position 5-8: ordinal not in range(128)
2017-03-28 03:30:38,016 [Thread-2:18860] [django.request:256] [base:handle_uncaught_exception] [ERROR]- Internal Server Error: /
Traceback (most recent call last):
  File "e:\python27\lib\site-packages\django\core\handlers\base.py", line 132, in get_response
    response = wrapped_callback(request, *callback_args, **callback_kwargs)
  File "F:\workspaces\Linux_learn2\blog\views.py", line 58, in index
    return render(request, 'index.html', locals())
  File "e:\python27\lib\site-packages\django\shortcuts.py", line 67, in render
    template_name, context, request=request, using=using)
  File "e:\python27\lib\site-packages\django\template\loader.py", line 99, in render_to_string
    return template.render(context, request)
  File "e:\python27\lib\site-packages\django\template\backends\django.py", line 74, in render
    return self.template.render(context)
  File "e:\python27\lib\site-packages\django\template\base.py", line 208, in render
    with context.bind_template(self):
  File "e:\python27\Lib\contextlib.py", line 17, in __enter__
    return self.gen.next()
  File "e:\python27\lib\site-packages\django\template\context.py", line 235, in bind_template
    updates.update(processor(self.request))
  File "F:\workspaces\Linux_learn2\blog\views.py", line 26, in global_setting
    archive_list = Article.objects.distinct_date()
  File "F:\workspaces\Linux_learn2\blog\models.py", line 57, in distinct_date
    date = date['date_publish'].strftime('%Y/%m'&"鏂囩珷瀛樻。")
TypeError: unsupported operand type(s) for &: 'unicode' and 'unicode'
2017-03-28 13:53:10,082 [Thread-25:10832] [django.request:170] [base:get_response] [WARNING]- Not Found: /favicon.ico
2017-03-28 14:07:07,487 [Thread-24:13184] [django.request:170] [base:get_response] [WARNING]- Not Found: /portal.php
2017-03-30 05:17:54,134 [Thread-25:15552] [django.request:170] [base:get_response] [WARNING]- Not Found: /favicon.ico
2017-03-30 05:18:13,973 [Thread-38:17072] [django.request:170] [base:get_response] [WARNING]- Not Found: /re
2017-04-02 22:44:03,492 [Thread-25:11000] [django.request:170] [base:get_response] [WARNING]- Not Found: /favicon.ico
2017-04-02 23:26:28,214 [Thread-41:12052] [django.request:256] [base:handle_uncaught_exception] [ERROR]- Internal Server Error: /
Traceback (most recent call last):
  File "e:\python27\lib\site-packages\django\core\handlers\base.py", line 132, in get_response
    response = wrapped_callback(request, *callback_args, **callback_kwargs)
  File "F:\workspaces\Linux_learn2\blog\views.py", line 61, in index
    return render(request, 'index.html', locals())
  File "e:\python27\lib\site-packages\django\shortcuts.py", line 67, in render
    template_name, context, request=request, using=using)
  File "e:\python27\lib\site-packages\django\template\loader.py", line 99, in render_to_string
    return template.render(context, request)
  File "e:\python27\lib\site-packages\django\template\backends\django.py", line 74, in render
    return self.template.render(context)
  File "e:\python27\lib\site-packages\django\template\base.py", line 209, in render
    return self._render(context)
  File "e:\python27\lib\site-packages\django\template\base.py", line 201, in _render
    return self.nodelist.render(context)
  File "e:\python27\lib\site-packages\django\template\base.py", line 903, in render
    bit = self.render_node(node, context)
  File "e:\python27\lib\site-packages\django\template\debug.py", line 79, in render_node
    return node.render(context)
  File "e:\python27\lib\site-packages\django\template\loader_tags.py", line 113, in render
    compiled_parent = self.get_parent(context)
  File "e:\python27\lib\site-packages\django\template\loader_tags.py", line 110, in get_parent
    return context.template.engine.get_template(parent)
  File "e:\python27\lib\site-packages\django\template\engine.py", line 167, in get_template
    template, origin = self.find_template(template_name, dirs)
  File "e:\python27\lib\site-packages\django\template\engine.py", line 141, in find_template
    source, display_name = loader(name, dirs)
  File "e:\python27\lib\site-packages\django\template\loaders\base.py", line 13, in __call__
    return self.load_template(template_name, template_dirs)
  File "e:\python27\lib\site-packages\django\template\loaders\base.py", line 23, in load_template
    template = Template(source, origin, template_name, self.engine)
  File "e:\python27\lib\site-packages\django\template\base.py", line 190, in __init__
    self.nodelist = engine.compile_string(template_string, origin)
  File "e:\python27\lib\site-packages\django\template\engine.py", line 261, in compile_string
    return parser.parse()
  File "e:\python27\lib\site-packages\django\template\base.py", line 341, in parse
    compiled_result = compile_func(self, token)
  File "e:\python27\lib\site-packages\django\template\defaulttags.py", line 872, in do_for
    nodelist_loop = parser.parse(('empty', 'endfor',))
  File "e:\python27\lib\site-packages\django\template\base.py", line 317, in parse
    filter_expression = self.compile_filter(token.contents)
  File "e:\python27\lib\site-packages\django\template\base.py", line 423, in compile_filter
    return FilterExpression(token, self)
  File "e:\python27\lib\site-packages\django\template\base.py", line 639, in __init__
    "from '%s'" % (token[upto:], token))
TemplateSyntaxError: Could not parse the remainder: '% endfor %' from '% endfor %'
2017-04-02 23:39:51,163 [Thread-2:12968] [django.request:170] [base:get_response] [WARNING]- Not Found: /admin]
2017-04-03 00:01:32,553 [Thread-12:11904] [django.request:256] [base:handle_uncaught_exception] [ERROR]- Internal Server Error: /article/
Traceback (most recent call last):
  File "e:\python27\lib\site-packages\django\core\handlers\base.py", line 132, in get_response
    response = wrapped_callback(request, *callback_args, **callback_kwargs)
  File "F:\workspaces\Linux_learn2\blog\views.py", line 128, in article
    return render(request, 'article.html', locals())
  File "e:\python27\lib\site-packages\django\shortcuts.py", line 67, in render
    template_name, context, request=request, using=using)
  File "e:\python27\lib\site-packages\django\template\loader.py", line 99, in render_to_string
    return template.render(context, request)
  File "e:\python27\lib\site-packages\django\template\backends\django.py", line 74, in render
    return self.template.render(context)
  File "e:\python27\lib\site-packages\django\template\base.py", line 209, in render
    return self._render(context)
  File "e:\python27\lib\site-packages\django\template\base.py", line 201, in _render
    return self.nodelist.render(context)
  File "e:\python27\lib\site-packages\django\template\base.py", line 903, in render
    bit = self.render_node(node, context)
  File "e:\python27\lib\site-packages\django\template\debug.py", line 79, in render_node
    return node.render(context)
  File "e:\python27\lib\site-packages\django\template\loader_tags.py", line 113, in render
    compiled_parent = self.get_parent(context)
  File "e:\python27\lib\site-packages\django\template\loader_tags.py", line 110, in get_parent
    return context.template.engine.get_template(parent)
  File "e:\python27\lib\site-packages\django\template\engine.py", line 167, in get_template
    template, origin = self.find_template(template_name, dirs)
  File "e:\python27\lib\site-packages\django\template\engine.py", line 141, in find_template
    source, display_name = loader(name, dirs)
  File "e:\python27\lib\site-packages\django\template\loaders\base.py", line 13, in __call__
    return self.load_template(template_name, template_dirs)
  File "e:\python27\lib\site-packages\django\template\loaders\base.py", line 23, in load_template
    template = Template(source, origin, template_name, self.engine)
  File "e:\python27\lib\site-packages\django\template\base.py", line 190, in __init__
    self.nodelist = engine.compile_string(template_string, origin)
  File "e:\python27\lib\site-packages\django\template\engine.py", line 261, in compile_string
    return parser.parse()
  File "e:\python27\lib\site-packages\django\template\base.py", line 341, in parse
    compiled_result = compile_func(self, token)
  File "e:\python27\lib\site-packages\django\template\defaulttags.py", line 872, in do_for
    nodelist_loop = parser.parse(('empty', 'endfor',))
  File "e:\python27\lib\site-packages\django\template\base.py", line 317, in parse
    filter_expression = self.compile_filter(token.contents)
  File "e:\python27\lib\site-packages\django\template\base.py", line 423, in compile_filter
    return FilterExpression(token, self)
  File "e:\python27\lib\site-packages\django\template\base.py", line 639, in __init__
    "from '%s'" % (token[upto:], token))
TemplateSyntaxError: Could not parse the remainder: '/article/?id=article_click_count.id' from '/article/?id=article_click_count.id'
2017-04-03 00:02:45,361 [Thread-15:14848] [django.request:256] [base:handle_uncaught_exception] [ERROR]- Internal Server Error: /
Traceback (most recent call last):
  File "e:\python27\lib\site-packages\django\core\handlers\base.py", line 132, in get_response
    response = wrapped_callback(request, *callback_args, **callback_kwargs)
  File "F:\workspaces\Linux_learn2\blog\views.py", line 64, in index
    return render(request, 'index.html', locals())
  File "e:\python27\lib\site-packages\django\shortcuts.py", line 67, in render
    template_name, context, request=request, using=using)
  File "e:\python27\lib\site-packages\django\template\loader.py", line 99, in render_to_string
    return template.render(context, request)
  File "e:\python27\lib\site-packages\django\template\backends\django.py", line 74, in render
    return self.template.render(context)
  File "e:\python27\lib\site-packages\django\template\base.py", line 209, in render
    return self._render(context)
  File "e:\python27\lib\site-packages\django\template\base.py", line 201, in _render
    return self.nodelist.render(context)
  File "e:\python27\lib\site-packages\django\template\base.py", line 903, in render
    bit = self.render_node(node, context)
  File "e:\python27\lib\site-packages\django\template\debug.py", line 79, in render_node
    return node.render(context)
  File "e:\python27\lib\site-packages\django\template\loader_tags.py", line 113, in render
    compiled_parent = self.get_parent(context)
  File "e:\python27\lib\site-packages\django\template\loader_tags.py", line 110, in get_parent
    return context.template.engine.get_template(parent)
  File "e:\python27\lib\site-packages\django\template\engine.py", line 167, in get_template
    template, origin = self.find_template(template_name, dirs)
  File "e:\python27\lib\site-packages\django\template\engine.py", line 141, in find_template
    source, display_name = loader(name, dirs)
  File "e:\python27\lib\site-packages\django\template\loaders\base.py", line 13, in __call__
    return self.load_template(template_name, template_dirs)
  File "e:\python27\lib\site-packages\django\template\loaders\base.py", line 23, in load_template
    template = Template(source, origin, template_name, self.engine)
  File "e:\python27\lib\site-packages\django\template\base.py", line 190, in __init__
    self.nodelist = engine.compile_string(template_string, origin)
  File "e:\python27\lib\site-packages\django\template\engine.py", line 261, in compile_string
    return parser.parse()
  File "e:\python27\lib\site-packages\django\template\base.py", line 341, in parse
    compiled_result = compile_func(self, token)
  File "e:\python27\lib\site-packages\django\template\defaulttags.py", line 872, in do_for
    nodelist_loop = parser.parse(('empty', 'endfor',))
  File "e:\python27\lib\site-packages\django\template\base.py", line 317, in parse
    filter_expression = self.compile_filter(token.contents)
  File "e:\python27\lib\site-packages\django\template\base.py", line 423, in compile_filter
    return FilterExpression(token, self)
  File "e:\python27\lib\site-packages\django\template\base.py", line 639, in __init__
    "from '%s'" % (token[upto:], token))
TemplateSyntaxError: Could not parse the remainder: '/article/?id=article_click_count.id' from '/article/?id=article_click_count.id'
2017-04-03 00:11:12,974 [Thread-54:14796] [django.request:256] [base:handle_uncaught_exception] [ERROR]- Internal Server Error: /
Traceback (most recent call last):
  File "e:\python27\lib\site-packages\django\core\handlers\base.py", line 132, in get_response
    response = wrapped_callback(request, *callback_args, **callback_kwargs)
  File "F:\workspaces\Linux_learn2\blog\views.py", line 64, in index
    return render(request, 'index.html', locals())
  File "e:\python27\lib\site-packages\django\shortcuts.py", line 67, in render
    template_name, context, request=request, using=using)
  File "e:\python27\lib\site-packages\django\template\loader.py", line 99, in render_to_string
    return template.render(context, request)
  File "e:\python27\lib\site-packages\django\template\backends\django.py", line 74, in render
    return self.template.render(context)
  File "e:\python27\lib\site-packages\django\template\base.py", line 209, in render
    return self._render(context)
  File "e:\python27\lib\site-packages\django\template\base.py", line 201, in _render
    return self.nodelist.render(context)
  File "e:\python27\lib\site-packages\django\template\base.py", line 903, in render
    bit = self.render_node(node, context)
  File "e:\python27\lib\site-packages\django\template\debug.py", line 79, in render_node
    return node.render(context)
  File "e:\python27\lib\site-packages\django\template\loader_tags.py", line 135, in render
    return compiled_parent._render(context)
  File "e:\python27\lib\site-packages\django\template\base.py", line 201, in _render
    return self.nodelist.render(context)
  File "e:\python27\lib\site-packages\django\template\base.py", line 903, in render
    bit = self.render_node(node, context)
  File "e:\python27\lib\site-packages\django\template\debug.py", line 79, in render_node
    return node.render(context)
  File "e:\python27\lib\site-packages\django\template\defaulttags.py", line 507, in render
    six.reraise(*exc_info)
  File "e:\python27\lib\site-packages\django\template\defaulttags.py", line 493, in render
    url = reverse(view_name, args=args, kwargs=kwargs, current_app=current_app)
  File "e:\python27\lib\site-packages\django\core\urlresolvers.py", line 579, in reverse
    return force_text(iri_to_uri(resolver._reverse_with_prefix(view, prefix, *args, **kwargs)))
  File "e:\python27\lib\site-packages\django\core\urlresolvers.py", line 496, in _reverse_with_prefix
    (lookup_view_s, args, kwargs, len(patterns), patterns))
NoReverseMatch: Reverse for 'regdit' with arguments '()' and keyword arguments '{}' not found. 0 pattern(s) tried: []
2017-04-03 00:11:23,875 [Thread-3:14864] [django.request:256] [base:handle_uncaught_exception] [ERROR]- Internal Server Error: /reg
Traceback (most recent call last):
  File "e:\python27\lib\site-packages\django\core\handlers\base.py", line 132, in get_response
    response = wrapped_callback(request, *callback_args, **callback_kwargs)
  File "F:\workspaces\Linux_learn2\blog\views.py", line 181, in do_reg
    return render(request, 'regdit.html', locals())
  File "e:\python27\lib\site-packages\django\shortcuts.py", line 67, in render
    template_name, context, request=request, using=using)
  File "e:\python27\lib\site-packages\django\template\loader.py", line 99, in render_to_string
    return template.render(context, request)
  File "e:\python27\lib\site-packages\django\template\backends\django.py", line 74, in render
    return self.template.render(context)
  File "e:\python27\lib\site-packages\django\template\base.py", line 209, in render
    return self._render(context)
  File "e:\python27\lib\site-packages\django\template\base.py", line 201, in _render
    return self.nodelist.render(context)
  File "e:\python27\lib\site-packages\django\template\base.py", line 903, in render
    bit = self.render_node(node, context)
  File "e:\python27\lib\site-packages\django\template\debug.py", line 79, in render_node
    return node.render(context)
  File "e:\python27\lib\site-packages\django\template\defaulttags.py", line 507, in render
    six.reraise(*exc_info)
  File "e:\python27\lib\site-packages\django\template\defaulttags.py", line 493, in render
    url = reverse(view_name, args=args, kwargs=kwargs, current_app=current_app)
  File "e:\python27\lib\site-packages\django\core\urlresolvers.py", line 579, in reverse
    return force_text(iri_to_uri(resolver._reverse_with_prefix(view, prefix, *args, **kwargs)))
  File "e:\python27\lib\site-packages\django\core\urlresolvers.py", line 496, in _reverse_with_prefix
    (lookup_view_s, args, kwargs, len(patterns), patterns))
NoReverseMatch: Reverse for 'reg' with arguments '()' and keyword arguments '{}' not found. 0 pattern(s) tried: []
2017-04-03 00:11:28,173 [Thread-5:14452] [django.request:256] [base:handle_uncaught_exception] [ERROR]- Internal Server Error: /reg
Traceback (most recent call last):
  File "e:\python27\lib\site-packages\django\core\handlers\base.py", line 132, in get_response
    response = wrapped_callback(request, *callback_args, **callback_kwargs)
  File "F:\workspaces\Linux_learn2\blog\views.py", line 181, in do_reg
    return render(request, 'regdit.html', locals())
  File "e:\python27\lib\site-packages\django\shortcuts.py", line 67, in render
    template_name, context, request=request, using=using)
  File "e:\python27\lib\site-packages\django\template\loader.py", line 99, in render_to_string
    return template.render(context, request)
  File "e:\python27\lib\site-packages\django\template\backends\django.py", line 74, in render
    return self.template.render(context)
  File "e:\python27\lib\site-packages\django\template\base.py", line 209, in render
    return self._render(context)
  File "e:\python27\lib\site-packages\django\template\base.py", line 201, in _render
    return self.nodelist.render(context)
  File "e:\python27\lib\site-packages\django\template\base.py", line 903, in render
    bit = self.render_node(node, context)
  File "e:\python27\lib\site-packages\django\template\debug.py", line 79, in render_node
    return node.render(context)
  File "e:\python27\lib\site-packages\django\template\defaulttags.py", line 507, in render
    six.reraise(*exc_info)
  File "e:\python27\lib\site-packages\django\template\defaulttags.py", line 493, in render
    url = reverse(view_name, args=args, kwargs=kwargs, current_app=current_app)
  File "e:\python27\lib\site-packages\django\core\urlresolvers.py", line 579, in reverse
    return force_text(iri_to_uri(resolver._reverse_with_prefix(view, prefix, *args, **kwargs)))
  File "e:\python27\lib\site-packages\django\core\urlresolvers.py", line 496, in _reverse_with_prefix
    (lookup_view_s, args, kwargs, len(patterns), patterns))
NoReverseMatch: Reverse for 'reg' with arguments '()' and keyword arguments '{}' not found. 0 pattern(s) tried: []
2017-04-03 00:29:45,151 [Thread-2:17336] [django.request:256] [base:handle_uncaught_exception] [ERROR]- Internal Server Error: /admin/blog/user/add/
Traceback (most recent call last):
  File "e:\python27\lib\site-packages\django\core\handlers\base.py", line 132, in get_response
    response = wrapped_callback(request, *callback_args, **callback_kwargs)
  File "e:\python27\lib\site-packages\django\contrib\admin\options.py", line 616, in wrapper
    return self.admin_site.admin_view(view)(*args, **kwargs)
  File "e:\python27\lib\site-packages\django\utils\decorators.py", line 110, in _wrapped_view
    response = view_func(request, *args, **kwargs)
  File "e:\python27\lib\site-packages\django\views\decorators\cache.py", line 57, in _wrapped_view_func
    response = view_func(request, *args, **kwargs)
  File "e:\python27\lib\site-packages\django\contrib\admin\sites.py", line 222, in inner
    if not self.has_permission(request):
  File "e:\python27\lib\site-packages\django\contrib\admin\sites.py", line 162, in has_permission
    return request.user.is_active and request.user.is_staff
  File "e:\python27\lib\site-packages\django\utils\functional.py", line 226, in inner
    self._setup()
  File "e:\python27\lib\site-packages\django\utils\functional.py", line 359, in _setup
    self._wrapped = self._setupfunc()
  File "e:\python27\lib\site-packages\django\contrib\auth\middleware.py", line 22, in <lambda>
    request.user = SimpleLazyObject(lambda: get_user(request))
  File "e:\python27\lib\site-packages\django\contrib\auth\middleware.py", line 10, in get_user
    request._cached_user = auth.get_user(request)
  File "e:\python27\lib\site-packages\django\contrib\auth\__init__.py", line 174, in get_user
    user = backend.get_user(user_id)
  File "e:\python27\lib\site-packages\django\contrib\auth\backends.py", line 93, in get_user
    return UserModel._default_manager.get(pk=user_id)
  File "e:\python27\lib\site-packages\django\db\models\manager.py", line 127, in manager_method
    return getattr(self.get_queryset(), name)(*args, **kwargs)
  File "e:\python27\lib\site-packages\django\db\models\query.py", line 328, in get
    num = len(clone)
  File "e:\python27\lib\site-packages\django\db\models\query.py", line 144, in __len__
    self._fetch_all()
  File "e:\python27\lib\site-packages\django\db\models\query.py", line 965, in _fetch_all
    self._result_cache = list(self.iterator())
  File "e:\python27\lib\site-packages\django\db\models\query.py", line 238, in iterator
    results = compiler.execute_sql()
  File "e:\python27\lib\site-packages\django\db\models\sql\compiler.py", line 840, in execute_sql
    cursor.execute(sql, params)
  File "e:\python27\lib\site-packages\django\db\backends\utils.py", line 79, in execute
    return super(CursorDebugWrapper, self).execute(sql, params)
  File "e:\python27\lib\site-packages\django\db\backends\utils.py", line 64, in execute
    return self.cursor.execute(sql, params)
  File "e:\python27\lib\site-packages\django\db\utils.py", line 97, in __exit__
    six.reraise(dj_exc_type, dj_exc_value, traceback)
  File "e:\python27\lib\site-packages\django\db\backends\utils.py", line 64, in execute
    return self.cursor.execute(sql, params)
  File "e:\python27\lib\site-packages\django\db\backends\mysql\base.py", line 124, in execute
    return self.cursor.execute(query, args)
  File "e:\python27\lib\site-packages\MySQLdb\cursors.py", line 174, in execute
    self.errorhandler(self, exc, value)
  File "e:\python27\lib\site-packages\MySQLdb\connections.py", line 36, in defaulterrorhandler
    raise errorclass, errorvalue
OperationalError: (1054, "Unknown column 'blog_user.desc' in 'field list'")
2017-04-03 00:29:50,961 [Thread-3:17328] [django.request:256] [base:handle_uncaught_exception] [ERROR]- Internal Server Error: /admin/
Traceback (most recent call last):
  File "e:\python27\lib\site-packages\django\core\handlers\base.py", line 132, in get_response
    response = wrapped_callback(request, *callback_args, **callback_kwargs)
  File "e:\python27\lib\site-packages\django\contrib\admin\sites.py", line 254, in wrapper
    return self.admin_view(view, cacheable)(*args, **kwargs)
  File "e:\python27\lib\site-packages\django\utils\decorators.py", line 110, in _wrapped_view
    response = view_func(request, *args, **kwargs)
  File "e:\python27\lib\site-packages\django\views\decorators\cache.py", line 57, in _wrapped_view_func
    response = view_func(request, *args, **kwargs)
  File "e:\python27\lib\site-packages\django\contrib\admin\sites.py", line 222, in inner
    if not self.has_permission(request):
  File "e:\python27\lib\site-packages\django\contrib\admin\sites.py", line 162, in has_permission
    return request.user.is_active and request.user.is_staff
  File "e:\python27\lib\site-packages\django\utils\functional.py", line 226, in inner
    self._setup()
  File "e:\python27\lib\site-packages\django\utils\functional.py", line 359, in _setup
    self._wrapped = self._setupfunc()
  File "e:\python27\lib\site-packages\django\contrib\auth\middleware.py", line 22, in <lambda>
    request.user = SimpleLazyObject(lambda: get_user(request))
  File "e:\python27\lib\site-packages\django\contrib\auth\middleware.py", line 10, in get_user
    request._cached_user = auth.get_user(request)
  File "e:\python27\lib\site-packages\django\contrib\auth\__init__.py", line 174, in get_user
    user = backend.get_user(user_id)
  File "e:\python27\lib\site-packages\django\contrib\auth\backends.py", line 93, in get_user
    return UserModel._default_manager.get(pk=user_id)
  File "e:\python27\lib\site-packages\django\db\models\manager.py", line 127, in manager_method
    return getattr(self.get_queryset(), name)(*args, **kwargs)
  File "e:\python27\lib\site-packages\django\db\models\query.py", line 328, in get
    num = len(clone)
  File "e:\python27\lib\site-packages\django\db\models\query.py", line 144, in __len__
    self._fetch_all()
  File "e:\python27\lib\site-packages\django\db\models\query.py", line 965, in _fetch_all
    self._result_cache = list(self.iterator())
  File "e:\python27\lib\site-packages\django\db\models\query.py", line 238, in iterator
    results = compiler.execute_sql()
  File "e:\python27\lib\site-packages\django\db\models\sql\compiler.py", line 840, in execute_sql
    cursor.execute(sql, params)
  File "e:\python27\lib\site-packages\django\db\backends\utils.py", line 79, in execute
    return super(CursorDebugWrapper, self).execute(sql, params)
  File "e:\python27\lib\site-packages\django\db\backends\utils.py", line 64, in execute
    return self.cursor.execute(sql, params)
  File "e:\python27\lib\site-packages\django\db\utils.py", line 97, in __exit__
    six.reraise(dj_exc_type, dj_exc_value, traceback)
  File "e:\python27\lib\site-packages\django\db\backends\utils.py", line 64, in execute
    return self.cursor.execute(sql, params)
  File "e:\python27\lib\site-packages\django\db\backends\mysql\base.py", line 124, in execute
    return self.cursor.execute(query, args)
  File "e:\python27\lib\site-packages\MySQLdb\cursors.py", line 174, in execute
    self.errorhandler(self, exc, value)
  File "e:\python27\lib\site-packages\MySQLdb\connections.py", line 36, in defaulterrorhandler
    raise errorclass, errorvalue
OperationalError: (1054, "Unknown column 'blog_user.desc' in 'field list'")
2017-04-03 00:29:52,463 [Thread-4:16712] [django.request:256] [base:handle_uncaught_exception] [ERROR]- Internal Server Error: /admin/blog/links/add/
Traceback (most recent call last):
  File "e:\python27\lib\site-packages\django\core\handlers\base.py", line 132, in get_response
    response = wrapped_callback(request, *callback_args, **callback_kwargs)
  File "e:\python27\lib\site-packages\django\contrib\admin\options.py", line 616, in wrapper
    return self.admin_site.admin_view(view)(*args, **kwargs)
  File "e:\python27\lib\site-packages\django\utils\decorators.py", line 110, in _wrapped_view
    response = view_func(request, *args, **kwargs)
  File "e:\python27\lib\site-packages\django\views\decorators\cache.py", line 57, in _wrapped_view_func
    response = view_func(request, *args, **kwargs)
  File "e:\python27\lib\site-packages\django\contrib\admin\sites.py", line 222, in inner
    if not self.has_permission(request):
  File "e:\python27\lib\site-packages\django\contrib\admin\sites.py", line 162, in has_permission
    return request.user.is_active and request.user.is_staff
  File "e:\python27\lib\site-packages\django\utils\functional.py", line 226, in inner
    self._setup()
  File "e:\python27\lib\site-packages\django\utils\functional.py", line 359, in _setup
    self._wrapped = self._setupfunc()
  File "e:\python27\lib\site-packages\django\contrib\auth\middleware.py", line 22, in <lambda>
    request.user = SimpleLazyObject(lambda: get_user(request))
  File "e:\python27\lib\site-packages\django\contrib\auth\middleware.py", line 10, in get_user
    request._cached_user = auth.get_user(request)
  File "e:\python27\lib\site-packages\django\contrib\auth\__init__.py", line 174, in get_user
    user = backend.get_user(user_id)
  File "e:\python27\lib\site-packages\django\contrib\auth\backends.py", line 93, in get_user
    return UserModel._default_manager.get(pk=user_id)
  File "e:\python27\lib\site-packages\django\db\models\manager.py", line 127, in manager_method
    return getattr(self.get_queryset(), name)(*args, **kwargs)
  File "e:\python27\lib\site-packages\django\db\models\query.py", line 328, in get
    num = len(clone)
  File "e:\python27\lib\site-packages\django\db\models\query.py", line 144, in __len__
    self._fetch_all()
  File "e:\python27\lib\site-packages\django\db\models\query.py", line 965, in _fetch_all
    self._result_cache = list(self.iterator())
  File "e:\python27\lib\site-packages\django\db\models\query.py", line 238, in iterator
    results = compiler.execute_sql()
  File "e:\python27\lib\site-packages\django\db\models\sql\compiler.py", line 840, in execute_sql
    cursor.execute(sql, params)
  File "e:\python27\lib\site-packages\django\db\backends\utils.py", line 79, in execute
    return super(CursorDebugWrapper, self).execute(sql, params)
  File "e:\python27\lib\site-packages\django\db\backends\utils.py", line 64, in execute
    return self.cursor.execute(sql, params)
  File "e:\python27\lib\site-packages\django\db\utils.py", line 97, in __exit__
    six.reraise(dj_exc_type, dj_exc_value, traceback)
  File "e:\python27\lib\site-packages\django\db\backends\utils.py", line 64, in execute
    return self.cursor.execute(sql, params)
  File "e:\python27\lib\site-packages\django\db\backends\mysql\base.py", line 124, in execute
    return self.cursor.execute(query, args)
  File "e:\python27\lib\site-packages\MySQLdb\cursors.py", line 174, in execute
    self.errorhandler(self, exc, value)
  File "e:\python27\lib\site-packages\MySQLdb\connections.py", line 36, in defaulterrorhandler
    raise errorclass, errorvalue
OperationalError: (1054, "Unknown column 'blog_user.desc' in 'field list'")
2017-04-03 00:37:00,029 [Thread-2:16500] [django.request:256] [base:handle_uncaught_exception] [ERROR]- Internal Server Error: /
Traceback (most recent call last):
  File "e:\python27\lib\site-packages\django\core\handlers\base.py", line 132, in get_response
    response = wrapped_callback(request, *callback_args, **callback_kwargs)
  File "F:\workspaces\Linux_learn2\blog\views.py", line 68, in index
    return render(request, 'index.html', locals())
  File "e:\python27\lib\site-packages\django\shortcuts.py", line 67, in render
    template_name, context, request=request, using=using)
  File "e:\python27\lib\site-packages\django\template\loader.py", line 99, in render_to_string
    return template.render(context, request)
  File "e:\python27\lib\site-packages\django\template\backends\django.py", line 74, in render
    return self.template.render(context)
  File "e:\python27\lib\site-packages\django\template\base.py", line 209, in render
    return self._render(context)
  File "e:\python27\lib\site-packages\django\template\base.py", line 201, in _render
    return self.nodelist.render(context)
  File "e:\python27\lib\site-packages\django\template\base.py", line 903, in render
    bit = self.render_node(node, context)
  File "e:\python27\lib\site-packages\django\template\debug.py", line 79, in render_node
    return node.render(context)
  File "e:\python27\lib\site-packages\django\template\loader_tags.py", line 135, in render
    return compiled_parent._render(context)
  File "e:\python27\lib\site-packages\django\template\base.py", line 201, in _render
    return self.nodelist.render(context)
  File "e:\python27\lib\site-packages\django\template\base.py", line 903, in render
    bit = self.render_node(node, context)
  File "e:\python27\lib\site-packages\django\template\debug.py", line 79, in render_node
    return node.render(context)
  File "e:\python27\lib\site-packages\django\template\debug.py", line 89, in render
    output = self.filter_expression.resolve(context)
  File "e:\python27\lib\site-packages\django\template\base.py", line 647, in resolve
    obj = self.var.resolve(context)
  File "e:\python27\lib\site-packages\django\template\base.py", line 787, in resolve
    value = self._resolve_lookup(context)
  File "e:\python27\lib\site-packages\django\template\base.py", line 817, in _resolve_lookup
    current = current[bit]
  File "e:\python27\lib\site-packages\django\utils\functional.py", line 226, in inner
    self._setup()
  File "e:\python27\lib\site-packages\django\utils\functional.py", line 359, in _setup
    self._wrapped = self._setupfunc()
  File "e:\python27\lib\site-packages\django\contrib\auth\middleware.py", line 22, in <lambda>
    request.user = SimpleLazyObject(lambda: get_user(request))
  File "e:\python27\lib\site-packages\django\contrib\auth\middleware.py", line 10, in get_user
    request._cached_user = auth.get_user(request)
  File "e:\python27\lib\site-packages\django\contrib\auth\__init__.py", line 174, in get_user
    user = backend.get_user(user_id)
  File "e:\python27\lib\site-packages\django\contrib\auth\backends.py", line 93, in get_user
    return UserModel._default_manager.get(pk=user_id)
  File "e:\python27\lib\site-packages\django\db\models\manager.py", line 127, in manager_method
    return getattr(self.get_queryset(), name)(*args, **kwargs)
  File "e:\python27\lib\site-packages\django\db\models\query.py", line 328, in get
    num = len(clone)
  File "e:\python27\lib\site-packages\django\db\models\query.py", line 144, in __len__
    self._fetch_all()
  File "e:\python27\lib\site-packages\django\db\models\query.py", line 965, in _fetch_all
    self._result_cache = list(self.iterator())
  File "e:\python27\lib\site-packages\django\db\models\query.py", line 238, in iterator
    results = compiler.execute_sql()
  File "e:\python27\lib\site-packages\django\db\models\sql\compiler.py", line 840, in execute_sql
    cursor.execute(sql, params)
  File "e:\python27\lib\site-packages\django\db\backends\utils.py", line 79, in execute
    return super(CursorDebugWrapper, self).execute(sql, params)
  File "e:\python27\lib\site-packages\django\db\backends\utils.py", line 64, in execute
    return self.cursor.execute(sql, params)
  File "e:\python27\lib\site-packages\django\db\utils.py", line 97, in __exit__
    six.reraise(dj_exc_type, dj_exc_value, traceback)
  File "e:\python27\lib\site-packages\django\db\backends\utils.py", line 64, in execute
    return self.cursor.execute(sql, params)
  File "e:\python27\lib\site-packages\django\db\backends\mysql\base.py", line 124, in execute
    return self.cursor.execute(query, args)
  File "e:\python27\lib\site-packages\MySQLdb\cursors.py", line 174, in execute
    self.errorhandler(self, exc, value)
  File "e:\python27\lib\site-packages\MySQLdb\connections.py", line 36, in defaulterrorhandler
    raise errorclass, errorvalue
OperationalError: (1054, "Unknown column 'blog_user.desc' in 'field list'")
2017-04-03 00:37:20,698 [Thread-2:18280] [django.request:256] [base:handle_uncaught_exception] [ERROR]- Internal Server Error: /
Traceback (most recent call last):
  File "e:\python27\lib\site-packages\django\core\handlers\base.py", line 132, in get_response
    response = wrapped_callback(request, *callback_args, **callback_kwargs)
  File "F:\workspaces\Linux_learn2\blog\views.py", line 68, in index
    return render(request, 'index.html', locals())
  File "e:\python27\lib\site-packages\django\shortcuts.py", line 67, in render
    template_name, context, request=request, using=using)
  File "e:\python27\lib\site-packages\django\template\loader.py", line 99, in render_to_string
    return template.render(context, request)
  File "e:\python27\lib\site-packages\django\template\backends\django.py", line 74, in render
    return self.template.render(context)
  File "e:\python27\lib\site-packages\django\template\base.py", line 209, in render
    return self._render(context)
  File "e:\python27\lib\site-packages\django\template\base.py", line 201, in _render
    return self.nodelist.render(context)
  File "e:\python27\lib\site-packages\django\template\base.py", line 903, in render
    bit = self.render_node(node, context)
  File "e:\python27\lib\site-packages\django\template\debug.py", line 79, in render_node
    return node.render(context)
  File "e:\python27\lib\site-packages\django\template\loader_tags.py", line 135, in render
    return compiled_parent._render(context)
  File "e:\python27\lib\site-packages\django\template\base.py", line 201, in _render
    return self.nodelist.render(context)
  File "e:\python27\lib\site-packages\django\template\base.py", line 903, in render
    bit = self.render_node(node, context)
  File "e:\python27\lib\site-packages\django\template\debug.py", line 79, in render_node
    return node.render(context)
  File "e:\python27\lib\site-packages\django\template\debug.py", line 89, in render
    output = self.filter_expression.resolve(context)
  File "e:\python27\lib\site-packages\django\template\base.py", line 647, in resolve
    obj = self.var.resolve(context)
  File "e:\python27\lib\site-packages\django\template\base.py", line 787, in resolve
    value = self._resolve_lookup(context)
  File "e:\python27\lib\site-packages\django\template\base.py", line 817, in _resolve_lookup
    current = current[bit]
  File "e:\python27\lib\site-packages\django\utils\functional.py", line 226, in inner
    self._setup()
  File "e:\python27\lib\site-packages\django\utils\functional.py", line 359, in _setup
    self._wrapped = self._setupfunc()
  File "e:\python27\lib\site-packages\django\contrib\auth\middleware.py", line 22, in <lambda>
    request.user = SimpleLazyObject(lambda: get_user(request))
  File "e:\python27\lib\site-packages\django\contrib\auth\middleware.py", line 10, in get_user
    request._cached_user = auth.get_user(request)
  File "e:\python27\lib\site-packages\django\contrib\auth\__init__.py", line 174, in get_user
    user = backend.get_user(user_id)
  File "e:\python27\lib\site-packages\django\contrib\auth\backends.py", line 93, in get_user
    return UserModel._default_manager.get(pk=user_id)
  File "e:\python27\lib\site-packages\django\db\models\manager.py", line 127, in manager_method
    return getattr(self.get_queryset(), name)(*args, **kwargs)
  File "e:\python27\lib\site-packages\django\db\models\query.py", line 328, in get
    num = len(clone)
  File "e:\python27\lib\site-packages\django\db\models\query.py", line 144, in __len__
    self._fetch_all()
  File "e:\python27\lib\site-packages\django\db\models\query.py", line 965, in _fetch_all
    self._result_cache = list(self.iterator())
  File "e:\python27\lib\site-packages\django\db\models\query.py", line 238, in iterator
    results = compiler.execute_sql()
  File "e:\python27\lib\site-packages\django\db\models\sql\compiler.py", line 840, in execute_sql
    cursor.execute(sql, params)
  File "e:\python27\lib\site-packages\django\db\backends\utils.py", line 79, in execute
    return super(CursorDebugWrapper, self).execute(sql, params)
  File "e:\python27\lib\site-packages\django\db\backends\utils.py", line 64, in execute
    return self.cursor.execute(sql, params)
  File "e:\python27\lib\site-packages\django\db\utils.py", line 97, in __exit__
    six.reraise(dj_exc_type, dj_exc_value, traceback)
  File "e:\python27\lib\site-packages\django\db\backends\utils.py", line 64, in execute
    return self.cursor.execute(sql, params)
  File "e:\python27\lib\site-packages\django\db\backends\mysql\base.py", line 124, in execute
    return self.cursor.execute(query, args)
  File "e:\python27\lib\site-packages\MySQLdb\cursors.py", line 174, in execute
    self.errorhandler(self, exc, value)
  File "e:\python27\lib\site-packages\MySQLdb\connections.py", line 36, in defaulterrorhandler
    raise errorclass, errorvalue
OperationalError: (1054, "Unknown column 'blog_user.desc' in 'field list'")
2017-04-03 01:01:49,319 [Thread-2:7712] [django.request:256] [base:handle_uncaught_exception] [ERROR]- Internal Server Error: /
Traceback (most recent call last):
  File "e:\python27\lib\site-packages\django\core\handlers\base.py", line 132, in get_response
    response = wrapped_callback(request, *callback_args, **callback_kwargs)
  File "F:\workspaces\Linux_learn2\blog\views.py", line 68, in index
    return render(request, 'index.html', locals())
  File "e:\python27\lib\site-packages\django\shortcuts.py", line 67, in render
    template_name, context, request=request, using=using)
  File "e:\python27\lib\site-packages\django\template\loader.py", line 99, in render_to_string
    return template.render(context, request)
  File "e:\python27\lib\site-packages\django\template\backends\django.py", line 74, in render
    return self.template.render(context)
  File "e:\python27\lib\site-packages\django\template\base.py", line 209, in render
    return self._render(context)
  File "e:\python27\lib\site-packages\django\template\base.py", line 201, in _render
    return self.nodelist.render(context)
  File "e:\python27\lib\site-packages\django\template\base.py", line 903, in render
    bit = self.render_node(node, context)
  File "e:\python27\lib\site-packages\django\template\debug.py", line 79, in render_node
    return node.render(context)
  File "e:\python27\lib\site-packages\django\template\loader_tags.py", line 135, in render
    return compiled_parent._render(context)
  File "e:\python27\lib\site-packages\django\template\base.py", line 201, in _render
    return self.nodelist.render(context)
  File "e:\python27\lib\site-packages\django\template\base.py", line 903, in render
    bit = self.render_node(node, context)
  File "e:\python27\lib\site-packages\django\template\debug.py", line 79, in render_node
    return node.render(context)
  File "e:\python27\lib\site-packages\django\template\debug.py", line 89, in render
    output = self.filter_expression.resolve(context)
  File "e:\python27\lib\site-packages\django\template\base.py", line 647, in resolve
    obj = self.var.resolve(context)
  File "e:\python27\lib\site-packages\django\template\base.py", line 787, in resolve
    value = self._resolve_lookup(context)
  File "e:\python27\lib\site-packages\django\template\base.py", line 817, in _resolve_lookup
    current = current[bit]
  File "e:\python27\lib\site-packages\django\utils\functional.py", line 226, in inner
    self._setup()
  File "e:\python27\lib\site-packages\django\utils\functional.py", line 359, in _setup
    self._wrapped = self._setupfunc()
  File "e:\python27\lib\site-packages\django\contrib\auth\middleware.py", line 22, in <lambda>
    request.user = SimpleLazyObject(lambda: get_user(request))
  File "e:\python27\lib\site-packages\django\contrib\auth\middleware.py", line 10, in get_user
    request._cached_user = auth.get_user(request)
  File "e:\python27\lib\site-packages\django\contrib\auth\__init__.py", line 174, in get_user
    user = backend.get_user(user_id)
  File "e:\python27\lib\site-packages\django\contrib\auth\backends.py", line 93, in get_user
    return UserModel._default_manager.get(pk=user_id)
  File "e:\python27\lib\site-packages\django\db\models\manager.py", line 127, in manager_method
    return getattr(self.get_queryset(), name)(*args, **kwargs)
  File "e:\python27\lib\site-packages\django\db\models\query.py", line 328, in get
    num = len(clone)
  File "e:\python27\lib\site-packages\django\db\models\query.py", line 144, in __len__
    self._fetch_all()
  File "e:\python27\lib\site-packages\django\db\models\query.py", line 965, in _fetch_all
    self._result_cache = list(self.iterator())
  File "e:\python27\lib\site-packages\django\db\models\query.py", line 238, in iterator
    results = compiler.execute_sql()
  File "e:\python27\lib\site-packages\django\db\models\sql\compiler.py", line 840, in execute_sql
    cursor.execute(sql, params)
  File "e:\python27\lib\site-packages\django\db\backends\utils.py", line 79, in execute
    return super(CursorDebugWrapper, self).execute(sql, params)
  File "e:\python27\lib\site-packages\django\db\backends\utils.py", line 64, in execute
    return self.cursor.execute(sql, params)
  File "e:\python27\lib\site-packages\django\db\utils.py", line 97, in __exit__
    six.reraise(dj_exc_type, dj_exc_value, traceback)
  File "e:\python27\lib\site-packages\django\db\backends\utils.py", line 64, in execute
    return self.cursor.execute(sql, params)
  File "e:\python27\lib\site-packages\django\db\backends\mysql\base.py", line 124, in execute
    return self.cursor.execute(query, args)
  File "e:\python27\lib\site-packages\MySQLdb\cursors.py", line 174, in execute
    self.errorhandler(self, exc, value)
  File "e:\python27\lib\site-packages\MySQLdb\connections.py", line 36, in defaulterrorhandler
    raise errorclass, errorvalue
OperationalError: (1054, "Unknown column 'blog_user.desc' in 'field list'")
2017-04-03 01:01:50,496 [Thread-3:6924] [django.request:170] [base:get_response] [WARNING]- Not Found: /favicon.ico
2017-04-03 01:09:00,743 [Thread-2:6808] [django.request:256] [base:handle_uncaught_exception] [ERROR]- Internal Server Error: /
Traceback (most recent call last):
  File "e:\python27\lib\site-packages\django\core\handlers\base.py", line 132, in get_response
    response = wrapped_callback(request, *callback_args, **callback_kwargs)
  File "F:\workspaces\Linux_learn2\blog\views.py", line 68, in index
    return render(request, 'index.html', locals())
  File "e:\python27\lib\site-packages\django\shortcuts.py", line 67, in render
    template_name, context, request=request, using=using)
  File "e:\python27\lib\site-packages\django\template\loader.py", line 99, in render_to_string
    return template.render(context, request)
  File "e:\python27\lib\site-packages\django\template\backends\django.py", line 74, in render
    return self.template.render(context)
  File "e:\python27\lib\site-packages\django\template\base.py", line 208, in render
    with context.bind_template(self):
  File "e:\python27\Lib\contextlib.py", line 17, in __enter__
    return self.gen.next()
  File "e:\python27\lib\site-packages\django\template\context.py", line 235, in bind_template
    updates.update(processor(self.request))
  File "F:\workspaces\Linux_learn2\blog\views.py", line 24, in global_setting
    SITE_DESC = settings.SITE_DESC
  File "e:\python27\lib\site-packages\django\conf\__init__.py", line 49, in __getattr__
    return getattr(self._wrapped, name)
AttributeError: 'Settings' object has no attribute 'SITE_DESC'
2017-04-03 01:09:02,823 [Thread-3:7752] [django.request:256] [base:handle_uncaught_exception] [ERROR]- Internal Server Error: /
Traceback (most recent call last):
  File "e:\python27\lib\site-packages\django\core\handlers\base.py", line 132, in get_response
    response = wrapped_callback(request, *callback_args, **callback_kwargs)
  File "F:\workspaces\Linux_learn2\blog\views.py", line 68, in index
    return render(request, 'index.html', locals())
  File "e:\python27\lib\site-packages\django\shortcuts.py", line 67, in render
    template_name, context, request=request, using=using)
  File "e:\python27\lib\site-packages\django\template\loader.py", line 99, in render_to_string
    return template.render(context, request)
  File "e:\python27\lib\site-packages\django\template\backends\django.py", line 74, in render
    return self.template.render(context)
  File "e:\python27\lib\site-packages\django\template\base.py", line 208, in render
    with context.bind_template(self):
  File "e:\python27\Lib\contextlib.py", line 17, in __enter__
    return self.gen.next()
  File "e:\python27\lib\site-packages\django\template\context.py", line 235, in bind_template
    updates.update(processor(self.request))
  File "F:\workspaces\Linux_learn2\blog\views.py", line 24, in global_setting
    SITE_DESC = settings.SITE_DESC
  File "e:\python27\lib\site-packages\django\conf\__init__.py", line 49, in __getattr__
    return getattr(self._wrapped, name)
AttributeError: 'Settings' object has no attribute 'SITE_DESC'
2017-04-03 01:09:03,946 [Thread-4:6876] [django.request:256] [base:handle_uncaught_exception] [ERROR]- Internal Server Error: /
Traceback (most recent call last):
  File "e:\python27\lib\site-packages\django\core\handlers\base.py", line 132, in get_response
    response = wrapped_callback(request, *callback_args, **callback_kwargs)
  File "F:\workspaces\Linux_learn2\blog\views.py", line 68, in index
    return render(request, 'index.html', locals())
  File "e:\python27\lib\site-packages\django\shortcuts.py", line 67, in render
    template_name, context, request=request, using=using)
  File "e:\python27\lib\site-packages\django\template\loader.py", line 99, in render_to_string
    return template.render(context, request)
  File "e:\python27\lib\site-packages\django\template\backends\django.py", line 74, in render
    return self.template.render(context)
  File "e:\python27\lib\site-packages\django\template\base.py", line 208, in render
    with context.bind_template(self):
  File "e:\python27\Lib\contextlib.py", line 17, in __enter__
    return self.gen.next()
  File "e:\python27\lib\site-packages\django\template\context.py", line 235, in bind_template
    updates.update(processor(self.request))
  File "F:\workspaces\Linux_learn2\blog\views.py", line 24, in global_setting
    SITE_DESC = settings.SITE_DESC
  File "e:\python27\lib\site-packages\django\conf\__init__.py", line 49, in __getattr__
    return getattr(self._wrapped, name)
AttributeError: 'Settings' object has no attribute 'SITE_DESC'
2017-04-03 01:09:49,780 [Thread-9:3552] [django.request:256] [base:handle_uncaught_exception] [ERROR]- Internal Server Error: /
Traceback (most recent call last):
  File "e:\python27\lib\site-packages\django\core\handlers\base.py", line 132, in get_response
    response = wrapped_callback(request, *callback_args, **callback_kwargs)
  File "F:\workspaces\Linux_learn2\blog\views.py", line 68, in index
    return render(request, 'index.html', locals())
  File "e:\python27\lib\site-packages\django\shortcuts.py", line 67, in render
    template_name, context, request=request, using=using)
  File "e:\python27\lib\site-packages\django\template\loader.py", line 99, in render_to_string
    return template.render(context, request)
  File "e:\python27\lib\site-packages\django\template\backends\django.py", line 74, in render
    return self.template.render(context)
  File "e:\python27\lib\site-packages\django\template\base.py", line 208, in render
    with context.bind_template(self):
  File "e:\python27\Lib\contextlib.py", line 17, in __enter__
    return self.gen.next()
  File "e:\python27\lib\site-packages\django\template\context.py", line 235, in bind_template
    updates.update(processor(self.request))
  File "F:\workspaces\Linux_learn2\blog\views.py", line 24, in global_setting
    SITE_DESC = settings.SITE_DESC
  File "e:\python27\lib\site-packages\django\conf\__init__.py", line 49, in __getattr__
    return getattr(self._wrapped, name)
AttributeError: 'Settings' object has no attribute 'SITE_DESC'
2017-04-03 01:09:50,855 [Thread-10:7016] [django.request:256] [base:handle_uncaught_exception] [ERROR]- Internal Server Error: /
Traceback (most recent call last):
  File "e:\python27\lib\site-packages\django\core\handlers\base.py", line 132, in get_response
    response = wrapped_callback(request, *callback_args, **callback_kwargs)
  File "F:\workspaces\Linux_learn2\blog\views.py", line 68, in index
    return render(request, 'index.html', locals())
  File "e:\python27\lib\site-packages\django\shortcuts.py", line 67, in render
    template_name, context, request=request, using=using)
  File "e:\python27\lib\site-packages\django\template\loader.py", line 99, in render_to_string
    return template.render(context, request)
  File "e:\python27\lib\site-packages\django\template\backends\django.py", line 74, in render
    return self.template.render(context)
  File "e:\python27\lib\site-packages\django\template\base.py", line 208, in render
    with context.bind_template(self):
  File "e:\python27\Lib\contextlib.py", line 17, in __enter__
    return self.gen.next()
  File "e:\python27\lib\site-packages\django\template\context.py", line 235, in bind_template
    updates.update(processor(self.request))
  File "F:\workspaces\Linux_learn2\blog\views.py", line 24, in global_setting
    SITE_DESC = settings.SITE_DESC
  File "e:\python27\lib\site-packages\django\conf\__init__.py", line 49, in __getattr__
    return getattr(self._wrapped, name)
AttributeError: 'Settings' object has no attribute 'SITE_DESC'
2017-04-03 01:09:52,306 [Thread-11:8396] [django.request:256] [base:handle_uncaught_exception] [ERROR]- Internal Server Error: /
Traceback (most recent call last):
  File "e:\python27\lib\site-packages\django\core\handlers\base.py", line 132, in get_response
    response = wrapped_callback(request, *callback_args, **callback_kwargs)
  File "F:\workspaces\Linux_learn2\blog\views.py", line 68, in index
    return render(request, 'index.html', locals())
  File "e:\python27\lib\site-packages\django\shortcuts.py", line 67, in render
    template_name, context, request=request, using=using)
  File "e:\python27\lib\site-packages\django\template\loader.py", line 99, in render_to_string
    return template.render(context, request)
  File "e:\python27\lib\site-packages\django\template\backends\django.py", line 74, in render
    return self.template.render(context)
  File "e:\python27\lib\site-packages\django\template\base.py", line 208, in render
    with context.bind_template(self):
  File "e:\python27\Lib\contextlib.py", line 17, in __enter__
    return self.gen.next()
  File "e:\python27\lib\site-packages\django\template\context.py", line 235, in bind_template
    updates.update(processor(self.request))
  File "F:\workspaces\Linux_learn2\blog\views.py", line 24, in global_setting
    SITE_DESC = settings.SITE_DESC
  File "e:\python27\lib\site-packages\django\conf\__init__.py", line 49, in __getattr__
    return getattr(self._wrapped, name)
AttributeError: 'Settings' object has no attribute 'SITE_DESC'
2017-04-03 01:10:33,173 [Thread-14:6524] [django.request:256] [base:handle_uncaught_exception] [ERROR]- Internal Server Error: /
Traceback (most recent call last):
  File "e:\python27\lib\site-packages\django\core\handlers\base.py", line 132, in get_response
    response = wrapped_callback(request, *callback_args, **callback_kwargs)
  File "F:\workspaces\Linux_learn2\blog\views.py", line 68, in index
    return render(request, 'index.html', locals())
  File "e:\python27\lib\site-packages\django\shortcuts.py", line 67, in render
    template_name, context, request=request, using=using)
  File "e:\python27\lib\site-packages\django\template\loader.py", line 99, in render_to_string
    return template.render(context, request)
  File "e:\python27\lib\site-packages\django\template\backends\django.py", line 74, in render
    return self.template.render(context)
  File "e:\python27\lib\site-packages\django\template\base.py", line 208, in render
    with context.bind_template(self):
  File "e:\python27\Lib\contextlib.py", line 17, in __enter__
    return self.gen.next()
  File "e:\python27\lib\site-packages\django\template\context.py", line 235, in bind_template
    updates.update(processor(self.request))
  File "F:\workspaces\Linux_learn2\blog\views.py", line 24, in global_setting
    SITE_DESC = settings.SITE_DESC
  File "e:\python27\lib\site-packages\django\conf\__init__.py", line 49, in __getattr__
    return getattr(self._wrapped, name)
AttributeError: 'Settings' object has no attribute 'SITE_DESC'
2017-04-03 01:10:40,183 [Thread-15:7584] [django.request:256] [base:handle_uncaught_exception] [ERROR]- Internal Server Error: /
Traceback (most recent call last):
  File "e:\python27\lib\site-packages\django\core\handlers\base.py", line 132, in get_response
    response = wrapped_callback(request, *callback_args, **callback_kwargs)
  File "F:\workspaces\Linux_learn2\blog\views.py", line 68, in index
    return render(request, 'index.html', locals())
  File "e:\python27\lib\site-packages\django\shortcuts.py", line 67, in render
    template_name, context, request=request, using=using)
  File "e:\python27\lib\site-packages\django\template\loader.py", line 99, in render_to_string
    return template.render(context, request)
  File "e:\python27\lib\site-packages\django\template\backends\django.py", line 74, in render
    return self.template.render(context)
  File "e:\python27\lib\site-packages\django\template\base.py", line 208, in render
    with context.bind_template(self):
  File "e:\python27\Lib\contextlib.py", line 17, in __enter__
    return self.gen.next()
  File "e:\python27\lib\site-packages\django\template\context.py", line 235, in bind_template
    updates.update(processor(self.request))
  File "F:\workspaces\Linux_learn2\blog\views.py", line 24, in global_setting
    SITE_DESC = settings.SITE_DESC
  File "e:\python27\lib\site-packages\django\conf\__init__.py", line 49, in __getattr__
    return getattr(self._wrapped, name)
AttributeError: 'Settings' object has no attribute 'SITE_DESC'
2017-04-03 01:11:54,341 [Thread-2:6520] [django.request:256] [base:handle_uncaught_exception] [ERROR]- Internal Server Error: /
Traceback (most recent call last):
  File "e:\python27\lib\site-packages\django\core\handlers\base.py", line 132, in get_response
    response = wrapped_callback(request, *callback_args, **callback_kwargs)
  File "F:\workspaces\Linux_learn2\blog\views.py", line 68, in index
    return render(request, 'index.html', locals())
  File "e:\python27\lib\site-packages\django\shortcuts.py", line 67, in render
    template_name, context, request=request, using=using)
  File "e:\python27\lib\site-packages\django\template\loader.py", line 99, in render_to_string
    return template.render(context, request)
  File "e:\python27\lib\site-packages\django\template\backends\django.py", line 74, in render
    return self.template.render(context)
  File "e:\python27\lib\site-packages\django\template\base.py", line 208, in render
    with context.bind_template(self):
  File "e:\python27\Lib\contextlib.py", line 17, in __enter__
    return self.gen.next()
  File "e:\python27\lib\site-packages\django\template\context.py", line 235, in bind_template
    updates.update(processor(self.request))
  File "F:\workspaces\Linux_learn2\blog\views.py", line 24, in global_setting
    SITE_DESC = settings.SITE_DESC
  File "e:\python27\lib\site-packages\django\conf\__init__.py", line 49, in __getattr__
    return getattr(self._wrapped, name)
AttributeError: 'Settings' object has no attribute 'SITE_DESC'
2017-04-03 01:12:11,582 [Thread-3:7920] [django.request:256] [base:handle_uncaught_exception] [ERROR]- Internal Server Error: /
Traceback (most recent call last):
  File "e:\python27\lib\site-packages\django\core\handlers\base.py", line 132, in get_response
    response = wrapped_callback(request, *callback_args, **callback_kwargs)
  File "F:\workspaces\Linux_learn2\blog\views.py", line 68, in index
    return render(request, 'index.html', locals())
  File "e:\python27\lib\site-packages\django\shortcuts.py", line 67, in render
    template_name, context, request=request, using=using)
  File "e:\python27\lib\site-packages\django\template\loader.py", line 99, in render_to_string
    return template.render(context, request)
  File "e:\python27\lib\site-packages\django\template\backends\django.py", line 74, in render
    return self.template.render(context)
  File "e:\python27\lib\site-packages\django\template\base.py", line 208, in render
    with context.bind_template(self):
  File "e:\python27\Lib\contextlib.py", line 17, in __enter__
    return self.gen.next()
  File "e:\python27\lib\site-packages\django\template\context.py", line 235, in bind_template
    updates.update(processor(self.request))
  File "F:\workspaces\Linux_learn2\blog\views.py", line 24, in global_setting
    SITE_DESC = settings.SITE_DESC
  File "e:\python27\lib\site-packages\django\conf\__init__.py", line 49, in __getattr__
    return getattr(self._wrapped, name)
AttributeError: 'Settings' object has no attribute 'SITE_DESC'
2017-04-03 01:12:12,006 [Thread-4:8664] [django.request:256] [base:handle_uncaught_exception] [ERROR]- Internal Server Error: /
Traceback (most recent call last):
  File "e:\python27\lib\site-packages\django\core\handlers\base.py", line 132, in get_response
    response = wrapped_callback(request, *callback_args, **callback_kwargs)
  File "F:\workspaces\Linux_learn2\blog\views.py", line 68, in index
    return render(request, 'index.html', locals())
  File "e:\python27\lib\site-packages\django\shortcuts.py", line 67, in render
    template_name, context, request=request, using=using)
  File "e:\python27\lib\site-packages\django\template\loader.py", line 99, in render_to_string
    return template.render(context, request)
  File "e:\python27\lib\site-packages\django\template\backends\django.py", line 74, in render
    return self.template.render(context)
  File "e:\python27\lib\site-packages\django\template\base.py", line 208, in render
    with context.bind_template(self):
  File "e:\python27\Lib\contextlib.py", line 17, in __enter__
    return self.gen.next()
  File "e:\python27\lib\site-packages\django\template\context.py", line 235, in bind_template
    updates.update(processor(self.request))
  File "F:\workspaces\Linux_learn2\blog\views.py", line 24, in global_setting
    SITE_DESC = settings.SITE_DESC
  File "e:\python27\lib\site-packages\django\conf\__init__.py", line 49, in __getattr__
    return getattr(self._wrapped, name)
AttributeError: 'Settings' object has no attribute 'SITE_DESC'
2017-04-03 01:55:16,772 [Thread-2:11964] [django.request:256] [base:handle_uncaught_exception] [ERROR]- Internal Server Error: /home/
Traceback (most recent call last):
  File "e:\python27\lib\site-packages\django\core\handlers\base.py", line 132, in get_response
    response = wrapped_callback(request, *callback_args, **callback_kwargs)
  File "F:\workspaces\Linux_learn2\VideoHome\views.py", line 5, in videohome
    return render(request, 'vidoehome.html', locals())
  File "e:\python27\lib\site-packages\django\shortcuts.py", line 67, in render
    template_name, context, request=request, using=using)
  File "e:\python27\lib\site-packages\django\template\loader.py", line 98, in render_to_string
    template = get_template(template_name, using=using)
  File "e:\python27\lib\site-packages\django\template\loader.py", line 46, in get_template
    raise TemplateDoesNotExist(template_name)
TemplateDoesNotExist: vidoehome.html
2017-04-03 01:58:01,006 [Thread-2:11596] [django.request:256] [base:handle_uncaught_exception] [ERROR]- Internal Server Error: /home/
Traceback (most recent call last):
  File "e:\python27\lib\site-packages\django\core\handlers\base.py", line 119, in get_response
    resolver_match = resolver.resolve(request.path_info)
  File "e:\python27\lib\site-packages\django\core\urlresolvers.py", line 366, in resolve
    for pattern in self.url_patterns:
  File "e:\python27\lib\site-packages\django\core\urlresolvers.py", line 402, in url_patterns
    patterns = getattr(self.urlconf_module, "urlpatterns", self.urlconf_module)
  File "e:\python27\lib\site-packages\django\core\urlresolvers.py", line 396, in urlconf_module
    self._urlconf_module = import_module(self.urlconf_name)
  File "e:\python27\Lib\importlib\__init__.py", line 37, in import_module
    __import__(name)
  File "F:\workspaces\Linux_learn2\Linux_learn2\urls.py", line 28, in <module>
    url(r'^', include('VideoHome.urls')),
  File "e:\python27\lib\site-packages\django\conf\urls\__init__.py", line 33, in include
    urlconf_module = import_module(urlconf_module)
  File "e:\python27\Lib\importlib\__init__.py", line 37, in import_module
    __import__(name)
  File "F:\workspaces\Linux_learn2\VideoHome\urls.py", line 16, in <module>
    from forms import *
ImportError: No module named forms
2017-04-03 02:02:19,085 [Thread-6:5940] [django.request:256] [base:handle_uncaught_exception] [ERROR]- Internal Server Error: /home/
Traceback (most recent call last):
  File "e:\python27\lib\site-packages\django\core\handlers\base.py", line 119, in get_response
    resolver_match = resolver.resolve(request.path_info)
  File "e:\python27\lib\site-packages\django\core\urlresolvers.py", line 366, in resolve
    for pattern in self.url_patterns:
  File "e:\python27\lib\site-packages\django\core\urlresolvers.py", line 402, in url_patterns
    patterns = getattr(self.urlconf_module, "urlpatterns", self.urlconf_module)
  File "e:\python27\lib\site-packages\django\core\urlresolvers.py", line 396, in urlconf_module
    self._urlconf_module = import_module(self.urlconf_name)
  File "e:\python27\Lib\importlib\__init__.py", line 37, in import_module
    __import__(name)
  File "F:\workspaces\Linux_learn2\Linux_learn2\urls.py", line 28, in <module>
    url(r'^', include('VideoHome.urls')),
  File "e:\python27\lib\site-packages\django\conf\urls\__init__.py", line 33, in include
    urlconf_module = import_module(urlconf_module)
  File "e:\python27\Lib\importlib\__init__.py", line 37, in import_module
    __import__(name)
  File "F:\workspaces\Linux_learn2\VideoHome\urls.py", line 16, in <module>
    from forms import *
ImportError: No module named forms
2017-04-03 02:04:37,362 [Thread-2:12020] [django.request:256] [base:handle_uncaught_exception] [ERROR]- Internal Server Error: /
Traceback (most recent call last):
  File "e:\python27\lib\site-packages\django\core\handlers\base.py", line 119, in get_response
    resolver_match = resolver.resolve(request.path_info)
  File "e:\python27\lib\site-packages\django\core\urlresolvers.py", line 366, in resolve
    for pattern in self.url_patterns:
  File "e:\python27\lib\site-packages\django\core\urlresolvers.py", line 402, in url_patterns
    patterns = getattr(self.urlconf_module, "urlpatterns", self.urlconf_module)
  File "e:\python27\lib\site-packages\django\core\urlresolvers.py", line 396, in urlconf_module
    self._urlconf_module = import_module(self.urlconf_name)
  File "e:\python27\Lib\importlib\__init__.py", line 37, in import_module
    __import__(name)
  File "F:\workspaces\Linux_learn2\Linux_learn2\urls.py", line 28, in <module>
    url(r'^', include('VideoHome.urls')),
  File "e:\python27\lib\site-packages\django\conf\urls\__init__.py", line 33, in include
    urlconf_module = import_module(urlconf_module)
  File "e:\python27\Lib\importlib\__init__.py", line 37, in import_module
    __import__(name)
  File "F:\workspaces\Linux_learn2\VideoHome\urls.py", line 16, in <module>
    from forms import *
ImportError: No module named forms
2017-04-03 02:05:59,434 [Thread-4:12648] [django.request:256] [base:handle_uncaught_exception] [ERROR]- Internal Server Error: /
Traceback (most recent call last):
  File "e:\python27\lib\site-packages\django\core\handlers\base.py", line 119, in get_response
    resolver_match = resolver.resolve(request.path_info)
  File "e:\python27\lib\site-packages\django\core\urlresolvers.py", line 366, in resolve
    for pattern in self.url_patterns:
  File "e:\python27\lib\site-packages\django\core\urlresolvers.py", line 402, in url_patterns
    patterns = getattr(self.urlconf_module, "urlpatterns", self.urlconf_module)
  File "e:\python27\lib\site-packages\django\core\urlresolvers.py", line 396, in urlconf_module
    self._urlconf_module = import_module(self.urlconf_name)
  File "e:\python27\Lib\importlib\__init__.py", line 37, in import_module
    __import__(name)
  File "F:\workspaces\Linux_learn2\Linux_learn2\urls.py", line 28, in <module>
    url(r'^home', include('VideoHome.urls')),
  File "e:\python27\lib\site-packages\django\conf\urls\__init__.py", line 33, in include
    urlconf_module = import_module(urlconf_module)
  File "e:\python27\Lib\importlib\__init__.py", line 37, in import_module
    __import__(name)
  File "F:\workspaces\Linux_learn2\VideoHome\urls.py", line 16, in <module>
    from forms import *
ImportError: No module named forms
2017-04-03 02:06:09,490 [Thread-5:9764] [django.request:256] [base:handle_uncaught_exception] [ERROR]- Internal Server Error: /
Traceback (most recent call last):
  File "e:\python27\lib\site-packages\django\core\handlers\base.py", line 119, in get_response
    resolver_match = resolver.resolve(request.path_info)
  File "e:\python27\lib\site-packages\django\core\urlresolvers.py", line 366, in resolve
    for pattern in self.url_patterns:
  File "e:\python27\lib\site-packages\django\core\urlresolvers.py", line 402, in url_patterns
    patterns = getattr(self.urlconf_module, "urlpatterns", self.urlconf_module)
  File "e:\python27\lib\site-packages\django\core\urlresolvers.py", line 396, in urlconf_module
    self._urlconf_module = import_module(self.urlconf_name)
  File "e:\python27\Lib\importlib\__init__.py", line 37, in import_module
    __import__(name)
  File "F:\workspaces\Linux_learn2\Linux_learn2\urls.py", line 28, in <module>
    url(r'^home', include('VideoHome.urls')),
  File "e:\python27\lib\site-packages\django\conf\urls\__init__.py", line 33, in include
    urlconf_module = import_module(urlconf_module)
  File "e:\python27\Lib\importlib\__init__.py", line 37, in import_module
    __import__(name)
  File "F:\workspaces\Linux_learn2\VideoHome\urls.py", line 16, in <module>
    from forms import *
ImportError: No module named forms
2017-04-03 02:06:09,953 [Thread-6:11576] [django.request:256] [base:handle_uncaught_exception] [ERROR]- Internal Server Error: /
Traceback (most recent call last):
  File "e:\python27\lib\site-packages\django\core\handlers\base.py", line 119, in get_response
    resolver_match = resolver.resolve(request.path_info)
  File "e:\python27\lib\site-packages\django\core\urlresolvers.py", line 366, in resolve
    for pattern in self.url_patterns:
  File "e:\python27\lib\site-packages\django\core\urlresolvers.py", line 402, in url_patterns
    patterns = getattr(self.urlconf_module, "urlpatterns", self.urlconf_module)
  File "e:\python27\lib\site-packages\django\core\urlresolvers.py", line 396, in urlconf_module
    self._urlconf_module = import_module(self.urlconf_name)
  File "e:\python27\Lib\importlib\__init__.py", line 37, in import_module
    __import__(name)
  File "F:\workspaces\Linux_learn2\Linux_learn2\urls.py", line 28, in <module>
    url(r'^home', include('VideoHome.urls')),
  File "e:\python27\lib\site-packages\django\conf\urls\__init__.py", line 33, in include
    urlconf_module = import_module(urlconf_module)
  File "e:\python27\Lib\importlib\__init__.py", line 37, in import_module
    __import__(name)
  File "F:\workspaces\Linux_learn2\VideoHome\urls.py", line 16, in <module>
    from forms import *
ImportError: No module named forms
2017-04-03 02:06:28,566 [Thread-2:11808] [django.request:256] [base:handle_uncaught_exception] [ERROR]- Internal Server Error: /
Traceback (most recent call last):
  File "e:\python27\lib\site-packages\django\core\handlers\base.py", line 119, in get_response
    resolver_match = resolver.resolve(request.path_info)
  File "e:\python27\lib\site-packages\django\core\urlresolvers.py", line 366, in resolve
    for pattern in self.url_patterns:
  File "e:\python27\lib\site-packages\django\core\urlresolvers.py", line 402, in url_patterns
    patterns = getattr(self.urlconf_module, "urlpatterns", self.urlconf_module)
  File "e:\python27\lib\site-packages\django\core\urlresolvers.py", line 396, in urlconf_module
    self._urlconf_module = import_module(self.urlconf_name)
  File "e:\python27\Lib\importlib\__init__.py", line 37, in import_module
    __import__(name)
  File "F:\workspaces\Linux_learn2\Linux_learn2\urls.py", line 28, in <module>
    url(r'^home', include('VideoHome.urls')),
  File "e:\python27\lib\site-packages\django\conf\urls\__init__.py", line 33, in include
    urlconf_module = import_module(urlconf_module)
  File "e:\python27\Lib\importlib\__init__.py", line 37, in import_module
    __import__(name)
  File "F:\workspaces\Linux_learn2\VideoHome\urls.py", line 16, in <module>
    from forms import *
ImportError: No module named forms
2017-04-03 02:06:30,391 [Thread-3:13160] [django.request:256] [base:handle_uncaught_exception] [ERROR]- Internal Server Error: /
Traceback (most recent call last):
  File "e:\python27\lib\site-packages\django\core\handlers\base.py", line 119, in get_response
    resolver_match = resolver.resolve(request.path_info)
  File "e:\python27\lib\site-packages\django\core\urlresolvers.py", line 366, in resolve
    for pattern in self.url_patterns:
  File "e:\python27\lib\site-packages\django\core\urlresolvers.py", line 402, in url_patterns
    patterns = getattr(self.urlconf_module, "urlpatterns", self.urlconf_module)
  File "e:\python27\lib\site-packages\django\core\urlresolvers.py", line 396, in urlconf_module
    self._urlconf_module = import_module(self.urlconf_name)
  File "e:\python27\Lib\importlib\__init__.py", line 37, in import_module
    __import__(name)
  File "F:\workspaces\Linux_learn2\Linux_learn2\urls.py", line 28, in <module>
    url(r'^home', include('VideoHome.urls')),
  File "e:\python27\lib\site-packages\django\conf\urls\__init__.py", line 33, in include
    urlconf_module = import_module(urlconf_module)
  File "e:\python27\Lib\importlib\__init__.py", line 37, in import_module
    __import__(name)
  File "F:\workspaces\Linux_learn2\VideoHome\urls.py", line 16, in <module>
    from forms import *
ImportError: No module named forms
2017-04-03 02:06:31,244 [Thread-4:12080] [django.request:256] [base:handle_uncaught_exception] [ERROR]- Internal Server Error: /
Traceback (most recent call last):
  File "e:\python27\lib\site-packages\django\core\handlers\base.py", line 119, in get_response
    resolver_match = resolver.resolve(request.path_info)
  File "e:\python27\lib\site-packages\django\core\urlresolvers.py", line 366, in resolve
    for pattern in self.url_patterns:
  File "e:\python27\lib\site-packages\django\core\urlresolvers.py", line 402, in url_patterns
    patterns = getattr(self.urlconf_module, "urlpatterns", self.urlconf_module)
  File "e:\python27\lib\site-packages\django\core\urlresolvers.py", line 396, in urlconf_module
    self._urlconf_module = import_module(self.urlconf_name)
  File "e:\python27\Lib\importlib\__init__.py", line 37, in import_module
    __import__(name)
  File "F:\workspaces\Linux_learn2\Linux_learn2\urls.py", line 28, in <module>
    url(r'^home', include('VideoHome.urls')),
  File "e:\python27\lib\site-packages\django\conf\urls\__init__.py", line 33, in include
    urlconf_module = import_module(urlconf_module)
  File "e:\python27\Lib\importlib\__init__.py", line 37, in import_module
    __import__(name)
  File "F:\workspaces\Linux_learn2\VideoHome\urls.py", line 16, in <module>
    from forms import *
ImportError: No module named forms
2017-04-03 02:06:58,884 [Thread-5:8264] [django.request:170] [base:get_response] [WARNING]- Not Found: /
2017-04-03 02:07:36,145 [Thread-2:12940] [django.request:256] [base:handle_uncaught_exception] [ERROR]- Internal Server Error: /blog
Traceback (most recent call last):
  File "e:\python27\lib\site-packages\django\core\handlers\base.py", line 108, in get_response
    response = middleware_method(request)
  File "e:\python27\lib\site-packages\django\middleware\common.py", line 74, in process_request
    if (not urlresolvers.is_valid_path(request.path_info, urlconf) and
  File "e:\python27\lib\site-packages\django\core\urlresolvers.py", line 647, in is_valid_path
    resolve(path, urlconf)
  File "e:\python27\lib\site-packages\django\core\urlresolvers.py", line 522, in resolve
    return get_resolver(urlconf).resolve(path)
  File "e:\python27\lib\site-packages\django\core\urlresolvers.py", line 366, in resolve
    for pattern in self.url_patterns:
  File "e:\python27\lib\site-packages\django\core\urlresolvers.py", line 402, in url_patterns
    patterns = getattr(self.urlconf_module, "urlpatterns", self.urlconf_module)
  File "e:\python27\lib\site-packages\django\core\urlresolvers.py", line 396, in urlconf_module
    self._urlconf_module = import_module(self.urlconf_name)
  File "e:\python27\Lib\importlib\__init__.py", line 37, in import_module
    __import__(name)
  File "F:\workspaces\Linux_learn2\Linux_learn2\urls.py", line 28, in <module>
    url(r'^', include('VideoHome.urls')),
  File "e:\python27\lib\site-packages\django\conf\urls\__init__.py", line 33, in include
    urlconf_module = import_module(urlconf_module)
  File "e:\python27\Lib\importlib\__init__.py", line 37, in import_module
    __import__(name)
  File "F:\workspaces\Linux_learn2\VideoHome\urls.py", line 16, in <module>
    from forms import *
ImportError: No module named forms
2017-04-03 02:07:40,038 [Thread-3:12668] [django.request:256] [base:handle_uncaught_exception] [ERROR]- Internal Server Error: /
Traceback (most recent call last):
  File "e:\python27\lib\site-packages\django\core\handlers\base.py", line 119, in get_response
    resolver_match = resolver.resolve(request.path_info)
  File "e:\python27\lib\site-packages\django\core\urlresolvers.py", line 366, in resolve
    for pattern in self.url_patterns:
  File "e:\python27\lib\site-packages\django\core\urlresolvers.py", line 402, in url_patterns
    patterns = getattr(self.urlconf_module, "urlpatterns", self.urlconf_module)
  File "e:\python27\lib\site-packages\django\core\urlresolvers.py", line 396, in urlconf_module
    self._urlconf_module = import_module(self.urlconf_name)
  File "e:\python27\Lib\importlib\__init__.py", line 37, in import_module
    __import__(name)
  File "F:\workspaces\Linux_learn2\Linux_learn2\urls.py", line 28, in <module>
    url(r'^', include('VideoHome.urls')),
  File "e:\python27\lib\site-packages\django\conf\urls\__init__.py", line 33, in include
    urlconf_module = import_module(urlconf_module)
  File "e:\python27\Lib\importlib\__init__.py", line 37, in import_module
    __import__(name)
  File "F:\workspaces\Linux_learn2\VideoHome\urls.py", line 16, in <module>
    from forms import *
ImportError: No module named forms
2017-04-03 02:10:37,687 [Thread-9:12560] [django.request:256] [base:handle_uncaught_exception] [ERROR]- Internal Server Error: /
Traceback (most recent call last):
  File "e:\python27\lib\site-packages\django\core\handlers\base.py", line 119, in get_response
    resolver_match = resolver.resolve(request.path_info)
  File "e:\python27\lib\site-packages\django\core\urlresolvers.py", line 366, in resolve
    for pattern in self.url_patterns:
  File "e:\python27\lib\site-packages\django\core\urlresolvers.py", line 402, in url_patterns
    patterns = getattr(self.urlconf_module, "urlpatterns", self.urlconf_module)
  File "e:\python27\lib\site-packages\django\core\urlresolvers.py", line 396, in urlconf_module
    self._urlconf_module = import_module(self.urlconf_name)
  File "e:\python27\Lib\importlib\__init__.py", line 37, in import_module
    __import__(name)
  File "F:\workspaces\Linux_learn2\Linux_learn2\urls.py", line 28, in <module>
    url(r'^', include('VideoHome.urls')),
  File "e:\python27\lib\site-packages\django\conf\urls\__init__.py", line 33, in include
    urlconf_module = import_module(urlconf_module)
  File "e:\python27\Lib\importlib\__init__.py", line 37, in import_module
    __import__(name)
  File "F:\workspaces\Linux_learn2\VideoHome\urls.py", line 16, in <module>
    from forms import *
ImportError: No module named forms
2017-04-03 02:10:38,992 [Thread-10:11976] [django.request:256] [base:handle_uncaught_exception] [ERROR]- Internal Server Error: /
Traceback (most recent call last):
  File "e:\python27\lib\site-packages\django\core\handlers\base.py", line 132, in get_response
    response = wrapped_callback(request, *callback_args, **callback_kwargs)
  File "F:\workspaces\Linux_learn2\VideoHome\views.py", line 18, in videohome
    return render(request, 'videohome.html', locals())
  File "e:\python27\lib\site-packages\django\shortcuts.py", line 67, in render
    template_name, context, request=request, using=using)
  File "e:\python27\lib\site-packages\django\template\loader.py", line 98, in render_to_string
    template = get_template(template_name, using=using)
  File "e:\python27\lib\site-packages\django\template\loader.py", line 35, in get_template
    return engine.get_template(template_name, dirs)
  File "e:\python27\lib\site-packages\django\template\backends\django.py", line 30, in get_template
    return Template(self.engine.get_template(template_name, dirs))
  File "e:\python27\lib\site-packages\django\template\engine.py", line 167, in get_template
    template, origin = self.find_template(template_name, dirs)
  File "e:\python27\lib\site-packages\django\template\engine.py", line 141, in find_template
    source, display_name = loader(name, dirs)
  File "e:\python27\lib\site-packages\django\template\loaders\base.py", line 13, in __call__
    return self.load_template(template_name, template_dirs)
  File "e:\python27\lib\site-packages\django\template\loaders\base.py", line 23, in load_template
    template = Template(source, origin, template_name, self.engine)
  File "e:\python27\lib\site-packages\django\template\base.py", line 190, in __init__
    self.nodelist = engine.compile_string(template_string, origin)
  File "e:\python27\lib\site-packages\django\template\engine.py", line 261, in compile_string
    return parser.parse()
  File "e:\python27\lib\site-packages\django\template\base.py", line 339, in parse
    self.invalid_block_tag(token, command, parse_until)
  File "e:\python27\lib\site-packages\django\template\base.py", line 395, in invalid_block_tag
    raise self.error(token, "Invalid block tag: '%s'" % command)
TemplateSyntaxError: Invalid block tag: 'static'
2017-04-03 02:10:40,005 [Thread-11:13028] [django.request:256] [base:handle_uncaught_exception] [ERROR]- Internal Server Error: /
Traceback (most recent call last):
  File "e:\python27\lib\site-packages\django\core\handlers\base.py", line 132, in get_response
    response = wrapped_callback(request, *callback_args, **callback_kwargs)
  File "F:\workspaces\Linux_learn2\VideoHome\views.py", line 18, in videohome
    return render(request, 'videohome.html', locals())
  File "e:\python27\lib\site-packages\django\shortcuts.py", line 67, in render
    template_name, context, request=request, using=using)
  File "e:\python27\lib\site-packages\django\template\loader.py", line 98, in render_to_string
    template = get_template(template_name, using=using)
  File "e:\python27\lib\site-packages\django\template\loader.py", line 35, in get_template
    return engine.get_template(template_name, dirs)
  File "e:\python27\lib\site-packages\django\template\backends\django.py", line 30, in get_template
    return Template(self.engine.get_template(template_name, dirs))
  File "e:\python27\lib\site-packages\django\template\engine.py", line 167, in get_template
    template, origin = self.find_template(template_name, dirs)
  File "e:\python27\lib\site-packages\django\template\engine.py", line 141, in find_template
    source, display_name = loader(name, dirs)
  File "e:\python27\lib\site-packages\django\template\loaders\base.py", line 13, in __call__
    return self.load_template(template_name, template_dirs)
  File "e:\python27\lib\site-packages\django\template\loaders\base.py", line 23, in load_template
    template = Template(source, origin, template_name, self.engine)
  File "e:\python27\lib\site-packages\django\template\base.py", line 190, in __init__
    self.nodelist = engine.compile_string(template_string, origin)
  File "e:\python27\lib\site-packages\django\template\engine.py", line 261, in compile_string
    return parser.parse()
  File "e:\python27\lib\site-packages\django\template\base.py", line 339, in parse
    self.invalid_block_tag(token, command, parse_until)
  File "e:\python27\lib\site-packages\django\template\base.py", line 395, in invalid_block_tag
    raise self.error(token, "Invalid block tag: '%s'" % command)
TemplateSyntaxError: Invalid block tag: 'static'
2017-04-03 02:10:54,049 [Thread-14:13628] [django.request:256] [base:handle_uncaught_exception] [ERROR]- Internal Server Error: /
Traceback (most recent call last):
  File "e:\python27\lib\site-packages\django\core\handlers\base.py", line 132, in get_response
    response = wrapped_callback(request, *callback_args, **callback_kwargs)
  File "F:\workspaces\Linux_learn2\VideoHome\views.py", line 18, in videohome
    return render(request, 'videohome.html', locals())
  File "e:\python27\lib\site-packages\django\shortcuts.py", line 67, in render
    template_name, context, request=request, using=using)
  File "e:\python27\lib\site-packages\django\template\loader.py", line 98, in render_to_string
    template = get_template(template_name, using=using)
  File "e:\python27\lib\site-packages\django\template\loader.py", line 35, in get_template
    return engine.get_template(template_name, dirs)
  File "e:\python27\lib\site-packages\django\template\backends\django.py", line 30, in get_template
    return Template(self.engine.get_template(template_name, dirs))
  File "e:\python27\lib\site-packages\django\template\engine.py", line 167, in get_template
    template, origin = self.find_template(template_name, dirs)
  File "e:\python27\lib\site-packages\django\template\engine.py", line 141, in find_template
    source, display_name = loader(name, dirs)
  File "e:\python27\lib\site-packages\django\template\loaders\base.py", line 13, in __call__
    return self.load_template(template_name, template_dirs)
  File "e:\python27\lib\site-packages\django\template\loaders\base.py", line 23, in load_template
    template = Template(source, origin, template_name, self.engine)
  File "e:\python27\lib\site-packages\django\template\base.py", line 190, in __init__
    self.nodelist = engine.compile_string(template_string, origin)
  File "e:\python27\lib\site-packages\django\template\engine.py", line 261, in compile_string
    return parser.parse()
  File "e:\python27\lib\site-packages\django\template\base.py", line 339, in parse
    self.invalid_block_tag(token, command, parse_until)
  File "e:\python27\lib\site-packages\django\template\base.py", line 395, in invalid_block_tag
    raise self.error(token, "Invalid block tag: '%s'" % command)
TemplateSyntaxError: Invalid block tag: 'static'
2017-04-03 02:10:55,892 [Thread-2:13700] [django.request:170] [base:get_response] [WARNING]- Not Found: /
2017-04-03 06:16:55,855 [Thread-2:2876] [django.request:170] [base:get_response] [WARNING]- Not Found: /
2017-04-03 06:16:55,950 [Thread-3:1504] [django.request:170] [base:get_response] [WARNING]- Not Found: /favicon.ico
