2017-03-28 03:24:00,927 [Thread-2:20300] [django.request:256] [base:handle_uncaught_exception] [ERROR]- Internal Server Error: /
Traceback (most recent call last):
  File "e:\python27\lib\site-packages\django\core\handlers\base.py", line 132, in get_response
    response = wrapped_callback(request, *callback_args, **callback_kwargs)
  File "F:\workspaces\Linux_learn2\blog\views.py", line 58, in index
    return render(request, 'index.html', locals())
  File "e:\python27\lib\site-packages\django\shortcuts.py", line 67, in render
    template_name, context, request=request, using=using)
  File "e:\python27\lib\site-packages\django\template\loader.py", line 99, in render_to_string
    return template.render(context, request)
  File "e:\python27\lib\site-packages\django\template\backends\django.py", line 74, in render
    return self.template.render(context)
  File "e:\python27\lib\site-packages\django\template\base.py", line 208, in render
    with context.bind_template(self):
  File "e:\python27\Lib\contextlib.py", line 17, in __enter__
    return self.gen.next()
  File "e:\python27\lib\site-packages\django\template\context.py", line 235, in bind_template
    updates.update(processor(self.request))
  File "F:\workspaces\Linux_learn2\blog\views.py", line 26, in global_setting
    archive_list = Article.objects.distinct_date()
  File "F:\workspaces\Linux_learn2\blog\models.py", line 58, in distinct_date
    date = date['date_publish'].strftime('%Y/%m鏂囩珷瀛樻。')
UnicodeEncodeError: 'ascii' codec can't encode characters in position 5-8: ordinal not in range(128)
2017-03-28 03:24:01,526 [Thread-3:20236] [django.request:170] [base:get_response] [WARNING]- Not Found: /favicon.ico
2017-03-28 03:25:27,661 [Thread-2:19284] [django.request:256] [base:handle_uncaught_exception] [ERROR]- Internal Server Error: /
Traceback (most recent call last):
  File "e:\python27\lib\site-packages\django\core\handlers\base.py", line 132, in get_response
    response = wrapped_callback(request, *callback_args, **callback_kwargs)
  File "F:\workspaces\Linux_learn2\blog\views.py", line 58, in index
    return render(request, 'index.html', locals())
  File "e:\python27\lib\site-packages\django\shortcuts.py", line 67, in render
    template_name, context, request=request, using=using)
  File "e:\python27\lib\site-packages\django\template\loader.py", line 99, in render_to_string
    return template.render(context, request)
  File "e:\python27\lib\site-packages\django\template\backends\django.py", line 74, in render
    return self.template.render(context)
  File "e:\python27\lib\site-packages\django\template\base.py", line 208, in render
    with context.bind_template(self):
  File "e:\python27\Lib\contextlib.py", line 17, in __enter__
    return self.gen.next()
  File "e:\python27\lib\site-packages\django\template\context.py", line 235, in bind_template
    updates.update(processor(self.request))
  File "F:\workspaces\Linux_learn2\blog\views.py", line 26, in global_setting
    archive_list = Article.objects.distinct_date()
  File "F:\workspaces\Linux_learn2\blog\models.py", line 58, in distinct_date
    date = date['date_publish'].strftime('%Y/%m鏂囩珷瀛樻。')
UnicodeEncodeError: 'ascii' codec can't encode characters in position 5-8: ordinal not in range(128)
2017-03-28 03:27:44,500 [Thread-2:21448] [django.request:256] [base:handle_uncaught_exception] [ERROR]- Internal Server Error: /
Traceback (most recent call last):
  File "e:\python27\lib\site-packages\django\core\handlers\base.py", line 132, in get_response
    response = wrapped_callback(request, *callback_args, **callback_kwargs)
  File "F:\workspaces\Linux_learn2\blog\views.py", line 58, in index
    return render(request, 'index.html', locals())
  File "e:\python27\lib\site-packages\django\shortcuts.py", line 67, in render
    template_name, context, request=request, using=using)
  File "e:\python27\lib\site-packages\django\template\loader.py", line 99, in render_to_string
    return template.render(context, request)
  File "e:\python27\lib\site-packages\django\template\backends\django.py", line 74, in render
    return self.template.render(context)
  File "e:\python27\lib\site-packages\django\template\base.py", line 208, in render
    with context.bind_template(self):
  File "e:\python27\Lib\contextlib.py", line 17, in __enter__
    return self.gen.next()
  File "e:\python27\lib\site-packages\django\template\context.py", line 235, in bind_template
    updates.update(processor(self.request))
  File "F:\workspaces\Linux_learn2\blog\views.py", line 26, in global_setting
    archive_list = Article.objects.distinct_date()
  File "F:\workspaces\Linux_learn2\blog\models.py", line 58, in distinct_date
    date = date['date_publish'].strftime('%Y/%m鏂囩珷瀛樻。')
UnicodeEncodeError: 'ascii' codec can't encode characters in position 5-8: ordinal not in range(128)
2017-03-28 03:28:17,415 [Thread-2:21388] [django.request:256] [base:handle_uncaught_exception] [ERROR]- Internal Server Error: /
Traceback (most recent call last):
  File "e:\python27\lib\site-packages\django\core\handlers\base.py", line 132, in get_response
    response = wrapped_callback(request, *callback_args, **callback_kwargs)
  File "F:\workspaces\Linux_learn2\blog\views.py", line 58, in index
    return render(request, 'index.html', locals())
  File "e:\python27\lib\site-packages\django\shortcuts.py", line 67, in render
    template_name, context, request=request, using=using)
  File "e:\python27\lib\site-packages\django\template\loader.py", line 99, in render_to_string
    return template.render(context, request)
  File "e:\python27\lib\site-packages\django\template\backends\django.py", line 74, in render
    return self.template.render(context)
  File "e:\python27\lib\site-packages\django\template\base.py", line 208, in render
    with context.bind_template(self):
  File "e:\python27\Lib\contextlib.py", line 17, in __enter__
    return self.gen.next()
  File "e:\python27\lib\site-packages\django\template\context.py", line 235, in bind_template
    updates.update(processor(self.request))
  File "F:\workspaces\Linux_learn2\blog\views.py", line 26, in global_setting
    archive_list = Article.objects.distinct_date()
  File "F:\workspaces\Linux_learn2\blog\models.py", line 57, in distinct_date
    date = date['date_publish'].strftime('%Y/%m鏂囩珷瀛?)
UnicodeEncodeError: 'ascii' codec can't encode characters in position 5-7: ordinal not in range(128)
2017-03-28 03:28:46,092 [Thread-2:20860] [django.request:256] [base:handle_uncaught_exception] [ERROR]- Internal Server Error: /
Traceback (most recent call last):
  File "e:\python27\lib\site-packages\django\core\handlers\base.py", line 132, in get_response
    response = wrapped_callback(request, *callback_args, **callback_kwargs)
  File "F:\workspaces\Linux_learn2\blog\views.py", line 58, in index
    return render(request, 'index.html', locals())
  File "e:\python27\lib\site-packages\django\shortcuts.py", line 67, in render
    template_name, context, request=request, using=using)
  File "e:\python27\lib\site-packages\django\template\loader.py", line 99, in render_to_string
    return template.render(context, request)
  File "e:\python27\lib\site-packages\django\template\backends\django.py", line 74, in render
    return self.template.render(context)
  File "e:\python27\lib\site-packages\django\template\base.py", line 208, in render
    with context.bind_template(self):
  File "e:\python27\Lib\contextlib.py", line 17, in __enter__
    return self.gen.next()
  File "e:\python27\lib\site-packages\django\template\context.py", line 235, in bind_template
    updates.update(processor(self.request))
  File "F:\workspaces\Linux_learn2\blog\views.py", line 26, in global_setting
    archive_list = Article.objects.distinct_date()
  File "F:\workspaces\Linux_learn2\blog\models.py", line 57, in distinct_date
    date = date['date_publish'].strftime('%Y/%m鏂囩珷瀛樻。')
UnicodeEncodeError: 'ascii' codec can't encode characters in position 5-8: ordinal not in range(128)
2017-03-28 03:29:24,821 [Thread-2:21700] [django.request:256] [base:handle_uncaught_exception] [ERROR]- Internal Server Error: /
Traceback (most recent call last):
  File "e:\python27\lib\site-packages\django\core\handlers\base.py", line 132, in get_response
    response = wrapped_callback(request, *callback_args, **callback_kwargs)
  File "F:\workspaces\Linux_learn2\blog\views.py", line 58, in index
    return render(request, 'index.html', locals())
  File "e:\python27\lib\site-packages\django\shortcuts.py", line 67, in render
    template_name, context, request=request, using=using)
  File "e:\python27\lib\site-packages\django\template\loader.py", line 99, in render_to_string
    return template.render(context, request)
  File "e:\python27\lib\site-packages\django\template\backends\django.py", line 74, in render
    return self.template.render(context)
  File "e:\python27\lib\site-packages\django\template\base.py", line 208, in render
    with context.bind_template(self):
  File "e:\python27\Lib\contextlib.py", line 17, in __enter__
    return self.gen.next()
  File "e:\python27\lib\site-packages\django\template\context.py", line 235, in bind_template
    updates.update(processor(self.request))
  File "F:\workspaces\Linux_learn2\blog\views.py", line 26, in global_setting
    archive_list = Article.objects.distinct_date
  File "F:\workspaces\Linux_learn2\blog\models.py", line 58, in distinct_date
    date = date['date_publish'].strftime('%Y/%m鏂囩珷瀛樻。')
UnicodeEncodeError: 'ascii' codec can't encode characters in position 5-8: ordinal not in range(128)
2017-03-28 03:30:38,016 [Thread-2:18860] [django.request:256] [base:handle_uncaught_exception] [ERROR]- Internal Server Error: /
Traceback (most recent call last):
  File "e:\python27\lib\site-packages\django\core\handlers\base.py", line 132, in get_response
    response = wrapped_callback(request, *callback_args, **callback_kwargs)
  File "F:\workspaces\Linux_learn2\blog\views.py", line 58, in index
    return render(request, 'index.html', locals())
  File "e:\python27\lib\site-packages\django\shortcuts.py", line 67, in render
    template_name, context, request=request, using=using)
  File "e:\python27\lib\site-packages\django\template\loader.py", line 99, in render_to_string
    return template.render(context, request)
  File "e:\python27\lib\site-packages\django\template\backends\django.py", line 74, in render
    return self.template.render(context)
  File "e:\python27\lib\site-packages\django\template\base.py", line 208, in render
    with context.bind_template(self):
  File "e:\python27\Lib\contextlib.py", line 17, in __enter__
    return self.gen.next()
  File "e:\python27\lib\site-packages\django\template\context.py", line 235, in bind_template
    updates.update(processor(self.request))
  File "F:\workspaces\Linux_learn2\blog\views.py", line 26, in global_setting
    archive_list = Article.objects.distinct_date()
  File "F:\workspaces\Linux_learn2\blog\models.py", line 57, in distinct_date
    date = date['date_publish'].strftime('%Y/%m'&"鏂囩珷瀛樻。")
TypeError: unsupported operand type(s) for &: 'unicode' and 'unicode'
2017-03-28 13:53:10,082 [Thread-25:10832] [django.request:170] [base:get_response] [WARNING]- Not Found: /favicon.ico
2017-03-28 14:07:07,487 [Thread-24:13184] [django.request:170] [base:get_response] [WARNING]- Not Found: /portal.php
2017-03-30 05:17:54,134 [Thread-25:15552] [django.request:170] [base:get_response] [WARNING]- Not Found: /favicon.ico
2017-03-30 05:18:13,973 [Thread-38:17072] [django.request:170] [base:get_response] [WARNING]- Not Found: /re
2017-04-02 22:44:03,492 [Thread-25:11000] [django.request:170] [base:get_response] [WARNING]- Not Found: /favicon.ico
2017-04-02 23:26:28,214 [Thread-41:12052] [django.request:256] [base:handle_uncaught_exception] [ERROR]- Internal Server Error: /
Traceback (most recent call last):
  File "e:\python27\lib\site-packages\django\core\handlers\base.py", line 132, in get_response
    response = wrapped_callback(request, *callback_args, **callback_kwargs)
  File "F:\workspaces\Linux_learn2\blog\views.py", line 61, in index
    return render(request, 'index.html', locals())
  File "e:\python27\lib\site-packages\django\shortcuts.py", line 67, in render
    template_name, context, request=request, using=using)
  File "e:\python27\lib\site-packages\django\template\loader.py", line 99, in render_to_string
    return template.render(context, request)
  File "e:\python27\lib\site-packages\django\template\backends\django.py", line 74, in render
    return self.template.render(context)
  File "e:\python27\lib\site-packages\django\template\base.py", line 209, in render
    return self._render(context)
  File "e:\python27\lib\site-packages\django\template\base.py", line 201, in _render
    return self.nodelist.render(context)
  File "e:\python27\lib\site-packages\django\template\base.py", line 903, in render
    bit = self.render_node(node, context)
  File "e:\python27\lib\site-packages\django\template\debug.py", line 79, in render_node
    return node.render(context)
  File "e:\python27\lib\site-packages\django\template\loader_tags.py", line 113, in render
    compiled_parent = self.get_parent(context)
  File "e:\python27\lib\site-packages\django\template\loader_tags.py", line 110, in get_parent
    return context.template.engine.get_template(parent)
  File "e:\python27\lib\site-packages\django\template\engine.py", line 167, in get_template
    template, origin = self.find_template(template_name, dirs)
  File "e:\python27\lib\site-packages\django\template\engine.py", line 141, in find_template
    source, display_name = loader(name, dirs)
  File "e:\python27\lib\site-packages\django\template\loaders\base.py", line 13, in __call__
    return self.load_template(template_name, template_dirs)
  File "e:\python27\lib\site-packages\django\template\loaders\base.py", line 23, in load_template
    template = Template(source, origin, template_name, self.engine)
  File "e:\python27\lib\site-packages\django\template\base.py", line 190, in __init__
    self.nodelist = engine.compile_string(template_string, origin)
  File "e:\python27\lib\site-packages\django\template\engine.py", line 261, in compile_string
    return parser.parse()
  File "e:\python27\lib\site-packages\django\template\base.py", line 341, in parse
    compiled_result = compile_func(self, token)
  File "e:\python27\lib\site-packages\django\template\defaulttags.py", line 872, in do_for
    nodelist_loop = parser.parse(('empty', 'endfor',))
  File "e:\python27\lib\site-packages\django\template\base.py", line 317, in parse
    filter_expression = self.compile_filter(token.contents)
  File "e:\python27\lib\site-packages\django\template\base.py", line 423, in compile_filter
    return FilterExpression(token, self)
  File "e:\python27\lib\site-packages\django\template\base.py", line 639, in __init__
    "from '%s'" % (token[upto:], token))
TemplateSyntaxError: Could not parse the remainder: '% endfor %' from '% endfor %'
2017-04-02 23:39:51,163 [Thread-2:12968] [django.request:170] [base:get_response] [WARNING]- Not Found: /admin]
2017-04-03 00:01:32,553 [Thread-12:11904] [django.request:256] [base:handle_uncaught_exception] [ERROR]- Internal Server Error: /article/
Traceback (most recent call last):
  File "e:\python27\lib\site-packages\django\core\handlers\base.py", line 132, in get_response
    response = wrapped_callback(request, *callback_args, **callback_kwargs)
  File "F:\workspaces\Linux_learn2\blog\views.py", line 128, in article
    return render(request, 'article.html', locals())
  File "e:\python27\lib\site-packages\django\shortcuts.py", line 67, in render
    template_name, context, request=request, using=using)
  File "e:\python27\lib\site-packages\django\template\loader.py", line 99, in render_to_string
    return template.render(context, request)
  File "e:\python27\lib\site-packages\django\template\backends\django.py", line 74, in render
    return self.template.render(context)
  File "e:\python27\lib\site-packages\django\template\base.py", line 209, in render
    return self._render(context)
  File "e:\python27\lib\site-packages\django\template\base.py", line 201, in _render
    return self.nodelist.render(context)
  File "e:\python27\lib\site-packages\django\template\base.py", line 903, in render
    bit = self.render_node(node, context)
  File "e:\python27\lib\site-packages\django\template\debug.py", line 79, in render_node
    return node.render(context)
  File "e:\python27\lib\site-packages\django\template\loader_tags.py", line 113, in render
    compiled_parent = self.get_parent(context)
  File "e:\python27\lib\site-packages\django\template\loader_tags.py", line 110, in get_parent
    return context.template.engine.get_template(parent)
  File "e:\python27\lib\site-packages\django\template\engine.py", line 167, in get_template
    template, origin = self.find_template(template_name, dirs)
  File "e:\python27\lib\site-packages\django\template\engine.py", line 141, in find_template
    source, display_name = loader(name, dirs)
  File "e:\python27\lib\site-packages\django\template\loaders\base.py", line 13, in __call__
    return self.load_template(template_name, template_dirs)
  File "e:\python27\lib\site-packages\django\template\loaders\base.py", line 23, in load_template
    template = Template(source, origin, template_name, self.engine)
  File "e:\python27\lib\site-packages\django\template\base.py", line 190, in __init__
    self.nodelist = engine.compile_string(template_string, origin)
  File "e:\python27\lib\site-packages\django\template\engine.py", line 261, in compile_string
    return parser.parse()
  File "e:\python27\lib\site-packages\django\template\base.py", line 341, in parse
    compiled_result = compile_func(self, token)
  File "e:\python27\lib\site-packages\django\template\defaulttags.py", line 872, in do_for
    nodelist_loop = parser.parse(('empty', 'endfor',))
  File "e:\python27\lib\site-packages\django\template\base.py", line 317, in parse
    filter_expression = self.compile_filter(token.contents)
  File "e:\python27\lib\site-packages\django\template\base.py", line 423, in compile_filter
    return FilterExpression(token, self)
  File "e:\python27\lib\site-packages\django\template\base.py", line 639, in __init__
    "from '%s'" % (token[upto:], token))
TemplateSyntaxError: Could not parse the remainder: '/article/?id=article_click_count.id' from '/article/?id=article_click_count.id'
2017-04-03 00:02:45,361 [Thread-15:14848] [django.request:256] [base:handle_uncaught_exception] [ERROR]- Internal Server Error: /
Traceback (most recent call last):
  File "e:\python27\lib\site-packages\django\core\handlers\base.py", line 132, in get_response
    response = wrapped_callback(request, *callback_args, **callback_kwargs)
  File "F:\workspaces\Linux_learn2\blog\views.py", line 64, in index
    return render(request, 'index.html', locals())
  File "e:\python27\lib\site-packages\django\shortcuts.py", line 67, in render
    template_name, context, request=request, using=using)
  File "e:\python27\lib\site-packages\django\template\loader.py", line 99, in render_to_string
    return template.render(context, request)
  File "e:\python27\lib\site-packages\django\template\backends\django.py", line 74, in render
    return self.template.render(context)
  File "e:\python27\lib\site-packages\django\template\base.py", line 209, in render
    return self._render(context)
  File "e:\python27\lib\site-packages\django\template\base.py", line 201, in _render
    return self.nodelist.render(context)
  File "e:\python27\lib\site-packages\django\template\base.py", line 903, in render
    bit = self.render_node(node, context)
  File "e:\python27\lib\site-packages\django\template\debug.py", line 79, in render_node
    return node.render(context)
  File "e:\python27\lib\site-packages\django\template\loader_tags.py", line 113, in render
    compiled_parent = self.get_parent(context)
  File "e:\python27\lib\site-packages\django\template\loader_tags.py", line 110, in get_parent
    return context.template.engine.get_template(parent)
  File "e:\python27\lib\site-packages\django\template\engine.py", line 167, in get_template
    template, origin = self.find_template(template_name, dirs)
  File "e:\python27\lib\site-packages\django\template\engine.py", line 141, in find_template
    source, display_name = loader(name, dirs)
  File "e:\python27\lib\site-packages\django\template\loaders\base.py", line 13, in __call__
    return self.load_template(template_name, template_dirs)
  File "e:\python27\lib\site-packages\django\template\loaders\base.py", line 23, in load_template
    template = Template(source, origin, template_name, self.engine)
  File "e:\python27\lib\site-packages\django\template\base.py", line 190, in __init__
    self.nodelist = engine.compile_string(template_string, origin)
  File "e:\python27\lib\site-packages\django\template\engine.py", line 261, in compile_string
    return parser.parse()
  File "e:\python27\lib\site-packages\django\template\base.py", line 341, in parse
    compiled_result = compile_func(self, token)
  File "e:\python27\lib\site-packages\django\template\defaulttags.py", line 872, in do_for
    nodelist_loop = parser.parse(('empty', 'endfor',))
  File "e:\python27\lib\site-packages\django\template\base.py", line 317, in parse
    filter_expression = self.compile_filter(token.contents)
  File "e:\python27\lib\site-packages\django\template\base.py", line 423, in compile_filter
    return FilterExpression(token, self)
  File "e:\python27\lib\site-packages\django\template\base.py", line 639, in __init__
    "from '%s'" % (token[upto:], token))
TemplateSyntaxError: Could not parse the remainder: '/article/?id=article_click_count.id' from '/article/?id=article_click_count.id'
2017-04-03 00:11:12,974 [Thread-54:14796] [django.request:256] [base:handle_uncaught_exception] [ERROR]- Internal Server Error: /
Traceback (most recent call last):
  File "e:\python27\lib\site-packages\django\core\handlers\base.py", line 132, in get_response
    response = wrapped_callback(request, *callback_args, **callback_kwargs)
  File "F:\workspaces\Linux_learn2\blog\views.py", line 64, in index
    return render(request, 'index.html', locals())
  File "e:\python27\lib\site-packages\django\shortcuts.py", line 67, in render
    template_name, context, request=request, using=using)
  File "e:\python27\lib\site-packages\django\template\loader.py", line 99, in render_to_string
    return template.render(context, request)
  File "e:\python27\lib\site-packages\django\template\backends\django.py", line 74, in render
    return self.template.render(context)
  File "e:\python27\lib\site-packages\django\template\base.py", line 209, in render
    return self._render(context)
  File "e:\python27\lib\site-packages\django\template\base.py", line 201, in _render
    return self.nodelist.render(context)
  File "e:\python27\lib\site-packages\django\template\base.py", line 903, in render
    bit = self.render_node(node, context)
  File "e:\python27\lib\site-packages\django\template\debug.py", line 79, in render_node
    return node.render(context)
  File "e:\python27\lib\site-packages\django\template\loader_tags.py", line 135, in render
    return compiled_parent._render(context)
  File "e:\python27\lib\site-packages\django\template\base.py", line 201, in _render
    return self.nodelist.render(context)
  File "e:\python27\lib\site-packages\django\template\base.py", line 903, in render
    bit = self.render_node(node, context)
  File "e:\python27\lib\site-packages\django\template\debug.py", line 79, in render_node
    return node.render(context)
  File "e:\python27\lib\site-packages\django\template\defaulttags.py", line 507, in render
    six.reraise(*exc_info)
  File "e:\python27\lib\site-packages\django\template\defaulttags.py", line 493, in render
    url = reverse(view_name, args=args, kwargs=kwargs, current_app=current_app)
  File "e:\python27\lib\site-packages\django\core\urlresolvers.py", line 579, in reverse
    return force_text(iri_to_uri(resolver._reverse_with_prefix(view, prefix, *args, **kwargs)))
  File "e:\python27\lib\site-packages\django\core\urlresolvers.py", line 496, in _reverse_with_prefix
    (lookup_view_s, args, kwargs, len(patterns), patterns))
NoReverseMatch: Reverse for 'regdit' with arguments '()' and keyword arguments '{}' not found. 0 pattern(s) tried: []
2017-04-03 00:11:23,875 [Thread-3:14864] [django.request:256] [base:handle_uncaught_exception] [ERROR]- Internal Server Error: /reg
Traceback (most recent call last):
  File "e:\python27\lib\site-packages\django\core\handlers\base.py", line 132, in get_response
    response = wrapped_callback(request, *callback_args, **callback_kwargs)
  File "F:\workspaces\Linux_learn2\blog\views.py", line 181, in do_reg
    return render(request, 'regdit.html', locals())
  File "e:\python27\lib\site-packages\django\shortcuts.py", line 67, in render
    template_name, context, request=request, using=using)
  File "e:\python27\lib\site-packages\django\template\loader.py", line 99, in render_to_string
    return template.render(context, request)
  File "e:\python27\lib\site-packages\django\template\backends\django.py", line 74, in render
    return self.template.render(context)
  File "e:\python27\lib\site-packages\django\template\base.py", line 209, in render
    return self._render(context)
  File "e:\python27\lib\site-packages\django\template\base.py", line 201, in _render
    return self.nodelist.render(context)
  File "e:\python27\lib\site-packages\django\template\base.py", line 903, in render
    bit = self.render_node(node, context)
  File "e:\python27\lib\site-packages\django\template\debug.py", line 79, in render_node
    return node.render(context)
  File "e:\python27\lib\site-packages\django\template\defaulttags.py", line 507, in render
    six.reraise(*exc_info)
  File "e:\python27\lib\site-packages\django\template\defaulttags.py", line 493, in render
    url = reverse(view_name, args=args, kwargs=kwargs, current_app=current_app)
  File "e:\python27\lib\site-packages\django\core\urlresolvers.py", line 579, in reverse
    return force_text(iri_to_uri(resolver._reverse_with_prefix(view, prefix, *args, **kwargs)))
  File "e:\python27\lib\site-packages\django\core\urlresolvers.py", line 496, in _reverse_with_prefix
    (lookup_view_s, args, kwargs, len(patterns), patterns))
NoReverseMatch: Reverse for 'reg' with arguments '()' and keyword arguments '{}' not found. 0 pattern(s) tried: []
2017-04-03 00:11:28,173 [Thread-5:14452] [django.request:256] [base:handle_uncaught_exception] [ERROR]- Internal Server Error: /reg
Traceback (most recent call last):
  File "e:\python27\lib\site-packages\django\core\handlers\base.py", line 132, in get_response
    response = wrapped_callback(request, *callback_args, **callback_kwargs)
  File "F:\workspaces\Linux_learn2\blog\views.py", line 181, in do_reg
    return render(request, 'regdit.html', locals())
  File "e:\python27\lib\site-packages\django\shortcuts.py", line 67, in render
    template_name, context, request=request, using=using)
  File "e:\python27\lib\site-packages\django\template\loader.py", line 99, in render_to_string
    return template.render(context, request)
  File "e:\python27\lib\site-packages\django\template\backends\django.py", line 74, in render
    return self.template.render(context)
  File "e:\python27\lib\site-packages\django\template\base.py", line 209, in render
    return self._render(context)
  File "e:\python27\lib\site-packages\django\template\base.py", line 201, in _render
    return self.nodelist.render(context)
  File "e:\python27\lib\site-packages\django\template\base.py", line 903, in render
    bit = self.render_node(node, context)
  File "e:\python27\lib\site-packages\django\template\debug.py", line 79, in render_node
    return node.render(context)
  File "e:\python27\lib\site-packages\django\template\defaulttags.py", line 507, in render
    six.reraise(*exc_info)
  File "e:\python27\lib\site-packages\django\template\defaulttags.py", line 493, in render
    url = reverse(view_name, args=args, kwargs=kwargs, current_app=current_app)
  File "e:\python27\lib\site-packages\django\core\urlresolvers.py", line 579, in reverse
    return force_text(iri_to_uri(resolver._reverse_with_prefix(view, prefix, *args, **kwargs)))
  File "e:\python27\lib\site-packages\django\core\urlresolvers.py", line 496, in _reverse_with_prefix
    (lookup_view_s, args, kwargs, len(patterns), patterns))
NoReverseMatch: Reverse for 'reg' with arguments '()' and keyword arguments '{}' not found. 0 pattern(s) tried: []
2017-04-03 00:29:45,151 [Thread-2:17336] [django.request:256] [base:handle_uncaught_exception] [ERROR]- Internal Server Error: /admin/blog/user/add/
Traceback (most recent call last):
  File "e:\python27\lib\site-packages\django\core\handlers\base.py", line 132, in get_response
    response = wrapped_callback(request, *callback_args, **callback_kwargs)
  File "e:\python27\lib\site-packages\django\contrib\admin\options.py", line 616, in wrapper
    return self.admin_site.admin_view(view)(*args, **kwargs)
  File "e:\python27\lib\site-packages\django\utils\decorators.py", line 110, in _wrapped_view
    response = view_func(request, *args, **kwargs)
  File "e:\python27\lib\site-packages\django\views\decorators\cache.py", line 57, in _wrapped_view_func
    response = view_func(request, *args, **kwargs)
  File "e:\python27\lib\site-packages\django\contrib\admin\sites.py", line 222, in inner
    if not self.has_permission(request):
  File "e:\python27\lib\site-packages\django\contrib\admin\sites.py", line 162, in has_permission
    return request.user.is_active and request.user.is_staff
  File "e:\python27\lib\site-packages\django\utils\functional.py", line 226, in inner
    self._setup()
  File "e:\python27\lib\site-packages\django\utils\functional.py", line 359, in _setup
    self._wrapped = self._setupfunc()
  File "e:\python27\lib\site-packages\django\contrib\auth\middleware.py", line 22, in <lambda>
    request.user = SimpleLazyObject(lambda: get_user(request))
  File "e:\python27\lib\site-packages\django\contrib\auth\middleware.py", line 10, in get_user
    request._cached_user = auth.get_user(request)
  File "e:\python27\lib\site-packages\django\contrib\auth\__init__.py", line 174, in get_user
    user = backend.get_user(user_id)
  File "e:\python27\lib\site-packages\django\contrib\auth\backends.py", line 93, in get_user
    return UserModel._default_manager.get(pk=user_id)
  File "e:\python27\lib\site-packages\django\db\models\manager.py", line 127, in manager_method
    return getattr(self.get_queryset(), name)(*args, **kwargs)
  File "e:\python27\lib\site-packages\django\db\models\query.py", line 328, in get
    num = len(clone)
  File "e:\python27\lib\site-packages\django\db\models\query.py", line 144, in __len__
    self._fetch_all()
  File "e:\python27\lib\site-packages\django\db\models\query.py", line 965, in _fetch_all
    self._result_cache = list(self.iterator())
  File "e:\python27\lib\site-packages\django\db\models\query.py", line 238, in iterator
    results = compiler.execute_sql()
  File "e:\python27\lib\site-packages\django\db\models\sql\compiler.py", line 840, in execute_sql
    cursor.execute(sql, params)
  File "e:\python27\lib\site-packages\django\db\backends\utils.py", line 79, in execute
    return super(CursorDebugWrapper, self).execute(sql, params)
  File "e:\python27\lib\site-packages\django\db\backends\utils.py", line 64, in execute
    return self.cursor.execute(sql, params)
  File "e:\python27\lib\site-packages\django\db\utils.py", line 97, in __exit__
    six.reraise(dj_exc_type, dj_exc_value, traceback)
  File "e:\python27\lib\site-packages\django\db\backends\utils.py", line 64, in execute
    return self.cursor.execute(sql, params)
  File "e:\python27\lib\site-packages\django\db\backends\mysql\base.py", line 124, in execute
    return self.cursor.execute(query, args)
  File "e:\python27\lib\site-packages\MySQLdb\cursors.py", line 174, in execute
    self.errorhandler(self, exc, value)
  File "e:\python27\lib\site-packages\MySQLdb\connections.py", line 36, in defaulterrorhandler
    raise errorclass, errorvalue
OperationalError: (1054, "Unknown column 'blog_user.desc' in 'field list'")
2017-04-03 00:29:50,961 [Thread-3:17328] [django.request:256] [base:handle_uncaught_exception] [ERROR]- Internal Server Error: /admin/
Traceback (most recent call last):
  File "e:\python27\lib\site-packages\django\core\handlers\base.py", line 132, in get_response
    response = wrapped_callback(request, *callback_args, **callback_kwargs)
  File "e:\python27\lib\site-packages\django\contrib\admin\sites.py", line 254, in wrapper
    return self.admin_view(view, cacheable)(*args, **kwargs)
  File "e:\python27\lib\site-packages\django\utils\decorators.py", line 110, in _wrapped_view
    response = view_func(request, *args, **kwargs)
  File "e:\python27\lib\site-packages\django\views\decorators\cache.py", line 57, in _wrapped_view_func
    response = view_func(request, *args, **kwargs)
  File "e:\python27\lib\site-packages\django\contrib\admin\sites.py", line 222, in inner
    if not self.has_permission(request):
  File "e:\python27\lib\site-packages\django\contrib\admin\sites.py", line 162, in has_permission
    return request.user.is_active and request.user.is_staff
  File "e:\python27\lib\site-packages\django\utils\functional.py", line 226, in inner
    self._setup()
  File "e:\python27\lib\site-packages\django\utils\functional.py", line 359, in _setup
    self._wrapped = self._setupfunc()
  File "e:\python27\lib\site-packages\django\contrib\auth\middleware.py", line 22, in <lambda>
    request.user = SimpleLazyObject(lambda: get_user(request))
  File "e:\python27\lib\site-packages\django\contrib\auth\middleware.py", line 10, in get_user
    request._cached_user = auth.get_user(request)
  File "e:\python27\lib\site-packages\django\contrib\auth\__init__.py", line 174, in get_user
    user = backend.get_user(user_id)
  File "e:\python27\lib\site-packages\django\contrib\auth\backends.py", line 93, in get_user
    return UserModel._default_manager.get(pk=user_id)
  File "e:\python27\lib\site-packages\django\db\models\manager.py", line 127, in manager_method
    return getattr(self.get_queryset(), name)(*args, **kwargs)
  File "e:\python27\lib\site-packages\django\db\models\query.py", line 328, in get
    num = len(clone)
  File "e:\python27\lib\site-packages\django\db\models\query.py", line 144, in __len__
    self._fetch_all()
  File "e:\python27\lib\site-packages\django\db\models\query.py", line 965, in _fetch_all
    self._result_cache = list(self.iterator())
  File "e:\python27\lib\site-packages\django\db\models\query.py", line 238, in iterator
    results = compiler.execute_sql()
  File "e:\python27\lib\site-packages\django\db\models\sql\compiler.py", line 840, in execute_sql
    cursor.execute(sql, params)
  File "e:\python27\lib\site-packages\django\db\backends\utils.py", line 79, in execute
    return super(CursorDebugWrapper, self).execute(sql, params)
  File "e:\python27\lib\site-packages\django\db\backends\utils.py", line 64, in execute
    return self.cursor.execute(sql, params)
  File "e:\python27\lib\site-packages\django\db\utils.py", line 97, in __exit__
    six.reraise(dj_exc_type, dj_exc_value, traceback)
  File "e:\python27\lib\site-packages\django\db\backends\utils.py", line 64, in execute
    return self.cursor.execute(sql, params)
  File "e:\python27\lib\site-packages\django\db\backends\mysql\base.py", line 124, in execute
    return self.cursor.execute(query, args)
  File "e:\python27\lib\site-packages\MySQLdb\cursors.py", line 174, in execute
    self.errorhandler(self, exc, value)
  File "e:\python27\lib\site-packages\MySQLdb\connections.py", line 36, in defaulterrorhandler
    raise errorclass, errorvalue
OperationalError: (1054, "Unknown column 'blog_user.desc' in 'field list'")
2017-04-03 00:29:52,463 [Thread-4:16712] [django.request:256] [base:handle_uncaught_exception] [ERROR]- Internal Server Error: /admin/blog/links/add/
Traceback (most recent call last):
  File "e:\python27\lib\site-packages\django\core\handlers\base.py", line 132, in get_response
    response = wrapped_callback(request, *callback_args, **callback_kwargs)
  File "e:\python27\lib\site-packages\django\contrib\admin\options.py", line 616, in wrapper
    return self.admin_site.admin_view(view)(*args, **kwargs)
  File "e:\python27\lib\site-packages\django\utils\decorators.py", line 110, in _wrapped_view
    response = view_func(request, *args, **kwargs)
  File "e:\python27\lib\site-packages\django\views\decorators\cache.py", line 57, in _wrapped_view_func
    response = view_func(request, *args, **kwargs)
  File "e:\python27\lib\site-packages\django\contrib\admin\sites.py", line 222, in inner
    if not self.has_permission(request):
  File "e:\python27\lib\site-packages\django\contrib\admin\sites.py", line 162, in has_permission
    return request.user.is_active and request.user.is_staff
  File "e:\python27\lib\site-packages\django\utils\functional.py", line 226, in inner
    self._setup()
  File "e:\python27\lib\site-packages\django\utils\functional.py", line 359, in _setup
    self._wrapped = self._setupfunc()
  File "e:\python27\lib\site-packages\django\contrib\auth\middleware.py", line 22, in <lambda>
    request.user = SimpleLazyObject(lambda: get_user(request))
  File "e:\python27\lib\site-packages\django\contrib\auth\middleware.py", line 10, in get_user
    request._cached_user = auth.get_user(request)
  File "e:\python27\lib\site-packages\django\contrib\auth\__init__.py", line 174, in get_user
    user = backend.get_user(user_id)
  File "e:\python27\lib\site-packages\django\contrib\auth\backends.py", line 93, in get_user
    return UserModel._default_manager.get(pk=user_id)
  File "e:\python27\lib\site-packages\django\db\models\manager.py", line 127, in manager_method
    return getattr(self.get_queryset(), name)(*args, **kwargs)
  File "e:\python27\lib\site-packages\django\db\models\query.py", line 328, in get
    num = len(clone)
  File "e:\python27\lib\site-packages\django\db\models\query.py", line 144, in __len__
    self._fetch_all()
  File "e:\python27\lib\site-packages\django\db\models\query.py", line 965, in _fetch_all
    self._result_cache = list(self.iterator())
  File "e:\python27\lib\site-packages\django\db\models\query.py", line 238, in iterator
    results = compiler.execute_sql()
  File "e:\python27\lib\site-packages\django\db\models\sql\compiler.py", line 840, in execute_sql
    cursor.execute(sql, params)
  File "e:\python27\lib\site-packages\django\db\backends\utils.py", line 79, in execute
    return super(CursorDebugWrapper, self).execute(sql, params)
  File "e:\python27\lib\site-packages\django\db\backends\utils.py", line 64, in execute
    return self.cursor.execute(sql, params)
  File "e:\python27\lib\site-packages\django\db\utils.py", line 97, in __exit__
    six.reraise(dj_exc_type, dj_exc_value, traceback)
  File "e:\python27\lib\site-packages\django\db\backends\utils.py", line 64, in execute
    return self.cursor.execute(sql, params)
  File "e:\python27\lib\site-packages\django\db\backends\mysql\base.py", line 124, in execute
    return self.cursor.execute(query, args)
  File "e:\python27\lib\site-packages\MySQLdb\cursors.py", line 174, in execute
    self.errorhandler(self, exc, value)
  File "e:\python27\lib\site-packages\MySQLdb\connections.py", line 36, in defaulterrorhandler
    raise errorclass, errorvalue
OperationalError: (1054, "Unknown column 'blog_user.desc' in 'field list'")
2017-04-03 00:37:00,029 [Thread-2:16500] [django.request:256] [base:handle_uncaught_exception] [ERROR]- Internal Server Error: /
Traceback (most recent call last):
  File "e:\python27\lib\site-packages\django\core\handlers\base.py", line 132, in get_response
    response = wrapped_callback(request, *callback_args, **callback_kwargs)
  File "F:\workspaces\Linux_learn2\blog\views.py", line 68, in index
    return render(request, 'index.html', locals())
  File "e:\python27\lib\site-packages\django\shortcuts.py", line 67, in render
    template_name, context, request=request, using=using)
  File "e:\python27\lib\site-packages\django\template\loader.py", line 99, in render_to_string
    return template.render(context, request)
  File "e:\python27\lib\site-packages\django\template\backends\django.py", line 74, in render
    return self.template.render(context)
  File "e:\python27\lib\site-packages\django\template\base.py", line 209, in render
    return self._render(context)
  File "e:\python27\lib\site-packages\django\template\base.py", line 201, in _render
    return self.nodelist.render(context)
  File "e:\python27\lib\site-packages\django\template\base.py", line 903, in render
    bit = self.render_node(node, context)
  File "e:\python27\lib\site-packages\django\template\debug.py", line 79, in render_node
    return node.render(context)
  File "e:\python27\lib\site-packages\django\template\loader_tags.py", line 135, in render
    return compiled_parent._render(context)
  File "e:\python27\lib\site-packages\django\template\base.py", line 201, in _render
    return self.nodelist.render(context)
  File "e:\python27\lib\site-packages\django\template\base.py", line 903, in render
    bit = self.render_node(node, context)
  File "e:\python27\lib\site-packages\django\template\debug.py", line 79, in render_node
    return node.render(context)
  File "e:\python27\lib\site-packages\django\template\debug.py", line 89, in render
    output = self.filter_expression.resolve(context)
  File "e:\python27\lib\site-packages\django\template\base.py", line 647, in resolve
    obj = self.var.resolve(context)
  File "e:\python27\lib\site-packages\django\template\base.py", line 787, in resolve
    value = self._resolve_lookup(context)
  File "e:\python27\lib\site-packages\django\template\base.py", line 817, in _resolve_lookup
    current = current[bit]
  File "e:\python27\lib\site-packages\django\utils\functional.py", line 226, in inner
    self._setup()
  File "e:\python27\lib\site-packages\django\utils\functional.py", line 359, in _setup
    self._wrapped = self._setupfunc()
  File "e:\python27\lib\site-packages\django\contrib\auth\middleware.py", line 22, in <lambda>
    request.user = SimpleLazyObject(lambda: get_user(request))
  File "e:\python27\lib\site-packages\django\contrib\auth\middleware.py", line 10, in get_user
    request._cached_user = auth.get_user(request)
  File "e:\python27\lib\site-packages\django\contrib\auth\__init__.py", line 174, in get_user
    user = backend.get_user(user_id)
  File "e:\python27\lib\site-packages\django\contrib\auth\backends.py", line 93, in get_user
    return UserModel._default_manager.get(pk=user_id)
  File "e:\python27\lib\site-packages\django\db\models\manager.py", line 127, in manager_method
    return getattr(self.get_queryset(), name)(*args, **kwargs)
  File "e:\python27\lib\site-packages\django\db\models\query.py", line 328, in get
    num = len(clone)
  File "e:\python27\lib\site-packages\django\db\models\query.py", line 144, in __len__
    self._fetch_all()
  File "e:\python27\lib\site-packages\django\db\models\query.py", line 965, in _fetch_all
    self._result_cache = list(self.iterator())
  File "e:\python27\lib\site-packages\django\db\models\query.py", line 238, in iterator
    results = compiler.execute_sql()
  File "e:\python27\lib\site-packages\django\db\models\sql\compiler.py", line 840, in execute_sql
    cursor.execute(sql, params)
  File "e:\python27\lib\site-packages\django\db\backends\utils.py", line 79, in execute
    return super(CursorDebugWrapper, self).execute(sql, params)
  File "e:\python27\lib\site-packages\django\db\backends\utils.py", line 64, in execute
    return self.cursor.execute(sql, params)
  File "e:\python27\lib\site-packages\django\db\utils.py", line 97, in __exit__
    six.reraise(dj_exc_type, dj_exc_value, traceback)
  File "e:\python27\lib\site-packages\django\db\backends\utils.py", line 64, in execute
    return self.cursor.execute(sql, params)
  File "e:\python27\lib\site-packages\django\db\backends\mysql\base.py", line 124, in execute
    return self.cursor.execute(query, args)
  File "e:\python27\lib\site-packages\MySQLdb\cursors.py", line 174, in execute
    self.errorhandler(self, exc, value)
  File "e:\python27\lib\site-packages\MySQLdb\connections.py", line 36, in defaulterrorhandler
    raise errorclass, errorvalue
OperationalError: (1054, "Unknown column 'blog_user.desc' in 'field list'")
2017-04-03 00:37:20,698 [Thread-2:18280] [django.request:256] [base:handle_uncaught_exception] [ERROR]- Internal Server Error: /
Traceback (most recent call last):
  File "e:\python27\lib\site-packages\django\core\handlers\base.py", line 132, in get_response
    response = wrapped_callback(request, *callback_args, **callback_kwargs)
  File "F:\workspaces\Linux_learn2\blog\views.py", line 68, in index
    return render(request, 'index.html', locals())
  File "e:\python27\lib\site-packages\django\shortcuts.py", line 67, in render
    template_name, context, request=request, using=using)
  File "e:\python27\lib\site-packages\django\template\loader.py", line 99, in render_to_string
    return template.render(context, request)
  File "e:\python27\lib\site-packages\django\template\backends\django.py", line 74, in render
    return self.template.render(context)
  File "e:\python27\lib\site-packages\django\template\base.py", line 209, in render
    return self._render(context)
  File "e:\python27\lib\site-packages\django\template\base.py", line 201, in _render
    return self.nodelist.render(context)
  File "e:\python27\lib\site-packages\django\template\base.py", line 903, in render
    bit = self.render_node(node, context)
  File "e:\python27\lib\site-packages\django\template\debug.py", line 79, in render_node
    return node.render(context)
  File "e:\python27\lib\site-packages\django\template\loader_tags.py", line 135, in render
    return compiled_parent._render(context)
  File "e:\python27\lib\site-packages\django\template\base.py", line 201, in _render
    return self.nodelist.render(context)
  File "e:\python27\lib\site-packages\django\template\base.py", line 903, in render
    bit = self.render_node(node, context)
  File "e:\python27\lib\site-packages\django\template\debug.py", line 79, in render_node
    return node.render(context)
  File "e:\python27\lib\site-packages\django\template\debug.py", line 89, in render
    output = self.filter_expression.resolve(context)
  File "e:\python27\lib\site-packages\django\template\base.py", line 647, in resolve
    obj = self.var.resolve(context)
  File "e:\python27\lib\site-packages\django\template\base.py", line 787, in resolve
    value = self._resolve_lookup(context)
  File "e:\python27\lib\site-packages\django\template\base.py", line 817, in _resolve_lookup
    current = current[bit]
  File "e:\python27\lib\site-packages\django\utils\functional.py", line 226, in inner
    self._setup()
  File "e:\python27\lib\site-packages\django\utils\functional.py", line 359, in _setup
    self._wrapped = self._setupfunc()
  File "e:\python27\lib\site-packages\django\contrib\auth\middleware.py", line 22, in <lambda>
    request.user = SimpleLazyObject(lambda: get_user(request))
  File "e:\python27\lib\site-packages\django\contrib\auth\middleware.py", line 10, in get_user
    request._cached_user = auth.get_user(request)
  File "e:\python27\lib\site-packages\django\contrib\auth\__init__.py", line 174, in get_user
    user = backend.get_user(user_id)
  File "e:\python27\lib\site-packages\django\contrib\auth\backends.py", line 93, in get_user
    return UserModel._default_manager.get(pk=user_id)
  File "e:\python27\lib\site-packages\django\db\models\manager.py", line 127, in manager_method
    return getattr(self.get_queryset(), name)(*args, **kwargs)
  File "e:\python27\lib\site-packages\django\db\models\query.py", line 328, in get
    num = len(clone)
  File "e:\python27\lib\site-packages\django\db\models\query.py", line 144, in __len__
    self._fetch_all()
  File "e:\python27\lib\site-packages\django\db\models\query.py", line 965, in _fetch_all
    self._result_cache = list(self.iterator())
  File "e:\python27\lib\site-packages\django\db\models\query.py", line 238, in iterator
    results = compiler.execute_sql()
  File "e:\python27\lib\site-packages\django\db\models\sql\compiler.py", line 840, in execute_sql
    cursor.execute(sql, params)
  File "e:\python27\lib\site-packages\django\db\backends\utils.py", line 79, in execute
    return super(CursorDebugWrapper, self).execute(sql, params)
  File "e:\python27\lib\site-packages\django\db\backends\utils.py", line 64, in execute
    return self.cursor.execute(sql, params)
  File "e:\python27\lib\site-packages\django\db\utils.py", line 97, in __exit__
    six.reraise(dj_exc_type, dj_exc_value, traceback)
  File "e:\python27\lib\site-packages\django\db\backends\utils.py", line 64, in execute
    return self.cursor.execute(sql, params)
  File "e:\python27\lib\site-packages\django\db\backends\mysql\base.py", line 124, in execute
    return self.cursor.execute(query, args)
  File "e:\python27\lib\site-packages\MySQLdb\cursors.py", line 174, in execute
    self.errorhandler(self, exc, value)
  File "e:\python27\lib\site-packages\MySQLdb\connections.py", line 36, in defaulterrorhandler
    raise errorclass, errorvalue
OperationalError: (1054, "Unknown column 'blog_user.desc' in 'field list'")
2017-04-03 01:01:49,319 [Thread-2:7712] [django.request:256] [base:handle_uncaught_exception] [ERROR]- Internal Server Error: /
Traceback (most recent call last):
  File "e:\python27\lib\site-packages\django\core\handlers\base.py", line 132, in get_response
    response = wrapped_callback(request, *callback_args, **callback_kwargs)
  File "F:\workspaces\Linux_learn2\blog\views.py", line 68, in index
    return render(request, 'index.html', locals())
  File "e:\python27\lib\site-packages\django\shortcuts.py", line 67, in render
    template_name, context, request=request, using=using)
  File "e:\python27\lib\site-packages\django\template\loader.py", line 99, in render_to_string
    return template.render(context, request)
  File "e:\python27\lib\site-packages\django\template\backends\django.py", line 74, in render
    return self.template.render(context)
  File "e:\python27\lib\site-packages\django\template\base.py", line 209, in render
    return self._render(context)
  File "e:\python27\lib\site-packages\django\template\base.py", line 201, in _render
    return self.nodelist.render(context)
  File "e:\python27\lib\site-packages\django\template\base.py", line 903, in render
    bit = self.render_node(node, context)
  File "e:\python27\lib\site-packages\django\template\debug.py", line 79, in render_node
    return node.render(context)
  File "e:\python27\lib\site-packages\django\template\loader_tags.py", line 135, in render
    return compiled_parent._render(context)
  File "e:\python27\lib\site-packages\django\template\base.py", line 201, in _render
    return self.nodelist.render(context)
  File "e:\python27\lib\site-packages\django\template\base.py", line 903, in render
    bit = self.render_node(node, context)
  File "e:\python27\lib\site-packages\django\template\debug.py", line 79, in render_node
    return node.render(context)
  File "e:\python27\lib\site-packages\django\template\debug.py", line 89, in render
    output = self.filter_expression.resolve(context)
  File "e:\python27\lib\site-packages\django\template\base.py", line 647, in resolve
    obj = self.var.resolve(context)
  File "e:\python27\lib\site-packages\django\template\base.py", line 787, in resolve
    value = self._resolve_lookup(context)
  File "e:\python27\lib\site-packages\django\template\base.py", line 817, in _resolve_lookup
    current = current[bit]
  File "e:\python27\lib\site-packages\django\utils\functional.py", line 226, in inner
    self._setup()
  File "e:\python27\lib\site-packages\django\utils\functional.py", line 359, in _setup
    self._wrapped = self._setupfunc()
  File "e:\python27\lib\site-packages\django\contrib\auth\middleware.py", line 22, in <lambda>
    request.user = SimpleLazyObject(lambda: get_user(request))
  File "e:\python27\lib\site-packages\django\contrib\auth\middleware.py", line 10, in get_user
    request._cached_user = auth.get_user(request)
  File "e:\python27\lib\site-packages\django\contrib\auth\__init__.py", line 174, in get_user
    user = backend.get_user(user_id)
  File "e:\python27\lib\site-packages\django\contrib\auth\backends.py", line 93, in get_user
    return UserModel._default_manager.get(pk=user_id)
  File "e:\python27\lib\site-packages\django\db\models\manager.py", line 127, in manager_method
    return getattr(self.get_queryset(), name)(*args, **kwargs)
  File "e:\python27\lib\site-packages\django\db\models\query.py", line 328, in get
    num = len(clone)
  File "e:\python27\lib\site-packages\django\db\models\query.py", line 144, in __len__
    self._fetch_all()
  File "e:\python27\lib\site-packages\django\db\models\query.py", line 965, in _fetch_all
    self._result_cache = list(self.iterator())
  File "e:\python27\lib\site-packages\django\db\models\query.py", line 238, in iterator
    results = compiler.execute_sql()
  File "e:\python27\lib\site-packages\django\db\models\sql\compiler.py", line 840, in execute_sql
    cursor.execute(sql, params)
  File "e:\python27\lib\site-packages\django\db\backends\utils.py", line 79, in execute
    return super(CursorDebugWrapper, self).execute(sql, params)
  File "e:\python27\lib\site-packages\django\db\backends\utils.py", line 64, in execute
    return self.cursor.execute(sql, params)
  File "e:\python27\lib\site-packages\django\db\utils.py", line 97, in __exit__
    six.reraise(dj_exc_type, dj_exc_value, traceback)
  File "e:\python27\lib\site-packages\django\db\backends\utils.py", line 64, in execute
    return self.cursor.execute(sql, params)
  File "e:\python27\lib\site-packages\django\db\backends\mysql\base.py", line 124, in execute
    return self.cursor.execute(query, args)
  File "e:\python27\lib\site-packages\MySQLdb\cursors.py", line 174, in execute
    self.errorhandler(self, exc, value)
  File "e:\python27\lib\site-packages\MySQLdb\connections.py", line 36, in defaulterrorhandler
    raise errorclass, errorvalue
OperationalError: (1054, "Unknown column 'blog_user.desc' in 'field list'")
2017-04-03 01:01:50,496 [Thread-3:6924] [django.request:170] [base:get_response] [WARNING]- Not Found: /favicon.ico
2017-04-03 01:09:00,743 [Thread-2:6808] [django.request:256] [base:handle_uncaught_exception] [ERROR]- Internal Server Error: /
Traceback (most recent call last):
  File "e:\python27\lib\site-packages\django\core\handlers\base.py", line 132, in get_response
    response = wrapped_callback(request, *callback_args, **callback_kwargs)
  File "F:\workspaces\Linux_learn2\blog\views.py", line 68, in index
    return render(request, 'index.html', locals())
  File "e:\python27\lib\site-packages\django\shortcuts.py", line 67, in render
    template_name, context, request=request, using=using)
  File "e:\python27\lib\site-packages\django\template\loader.py", line 99, in render_to_string
    return template.render(context, request)
  File "e:\python27\lib\site-packages\django\template\backends\django.py", line 74, in render
    return self.template.render(context)
  File "e:\python27\lib\site-packages\django\template\base.py", line 208, in render
    with context.bind_template(self):
  File "e:\python27\Lib\contextlib.py", line 17, in __enter__
    return self.gen.next()
  File "e:\python27\lib\site-packages\django\template\context.py", line 235, in bind_template
    updates.update(processor(self.request))
  File "F:\workspaces\Linux_learn2\blog\views.py", line 24, in global_setting
    SITE_DESC = settings.SITE_DESC
  File "e:\python27\lib\site-packages\django\conf\__init__.py", line 49, in __getattr__
    return getattr(self._wrapped, name)
AttributeError: 'Settings' object has no attribute 'SITE_DESC'
2017-04-03 01:09:02,823 [Thread-3:7752] [django.request:256] [base:handle_uncaught_exception] [ERROR]- Internal Server Error: /
Traceback (most recent call last):
  File "e:\python27\lib\site-packages\django\core\handlers\base.py", line 132, in get_response
    response = wrapped_callback(request, *callback_args, **callback_kwargs)
  File "F:\workspaces\Linux_learn2\blog\views.py", line 68, in index
    return render(request, 'index.html', locals())
  File "e:\python27\lib\site-packages\django\shortcuts.py", line 67, in render
    template_name, context, request=request, using=using)
  File "e:\python27\lib\site-packages\django\template\loader.py", line 99, in render_to_string
    return template.render(context, request)
  File "e:\python27\lib\site-packages\django\template\backends\django.py", line 74, in render
    return self.template.render(context)
  File "e:\python27\lib\site-packages\django\template\base.py", line 208, in render
    with context.bind_template(self):
  File "e:\python27\Lib\contextlib.py", line 17, in __enter__
    return self.gen.next()
  File "e:\python27\lib\site-packages\django\template\context.py", line 235, in bind_template
    updates.update(processor(self.request))
  File "F:\workspaces\Linux_learn2\blog\views.py", line 24, in global_setting
    SITE_DESC = settings.SITE_DESC
  File "e:\python27\lib\site-packages\django\conf\__init__.py", line 49, in __getattr__
    return getattr(self._wrapped, name)
AttributeError: 'Settings' object has no attribute 'SITE_DESC'
2017-04-03 01:09:03,946 [Thread-4:6876] [django.request:256] [base:handle_uncaught_exception] [ERROR]- Internal Server Error: /
Traceback (most recent call last):
  File "e:\python27\lib\site-packages\django\core\handlers\base.py", line 132, in get_response
    response = wrapped_callback(request, *callback_args, **callback_kwargs)
  File "F:\workspaces\Linux_learn2\blog\views.py", line 68, in index
    return render(request, 'index.html', locals())
  File "e:\python27\lib\site-packages\django\shortcuts.py", line 67, in render
    template_name, context, request=request, using=using)
  File "e:\python27\lib\site-packages\django\template\loader.py", line 99, in render_to_string
    return template.render(context, request)
  File "e:\python27\lib\site-packages\django\template\backends\django.py", line 74, in render
    return self.template.render(context)
  File "e:\python27\lib\site-packages\django\template\base.py", line 208, in render
    with context.bind_template(self):
  File "e:\python27\Lib\contextlib.py", line 17, in __enter__
    return self.gen.next()
  File "e:\python27\lib\site-packages\django\template\context.py", line 235, in bind_template
    updates.update(processor(self.request))
  File "F:\workspaces\Linux_learn2\blog\views.py", line 24, in global_setting
    SITE_DESC = settings.SITE_DESC
  File "e:\python27\lib\site-packages\django\conf\__init__.py", line 49, in __getattr__
    return getattr(self._wrapped, name)
AttributeError: 'Settings' object has no attribute 'SITE_DESC'
2017-04-03 01:09:49,780 [Thread-9:3552] [django.request:256] [base:handle_uncaught_exception] [ERROR]- Internal Server Error: /
Traceback (most recent call last):
  File "e:\python27\lib\site-packages\django\core\handlers\base.py", line 132, in get_response
    response = wrapped_callback(request, *callback_args, **callback_kwargs)
  File "F:\workspaces\Linux_learn2\blog\views.py", line 68, in index
    return render(request, 'index.html', locals())
  File "e:\python27\lib\site-packages\django\shortcuts.py", line 67, in render
    template_name, context, request=request, using=using)
  File "e:\python27\lib\site-packages\django\template\loader.py", line 99, in render_to_string
    return template.render(context, request)
  File "e:\python27\lib\site-packages\django\template\backends\django.py", line 74, in render
    return self.template.render(context)
  File "e:\python27\lib\site-packages\django\template\base.py", line 208, in render
    with context.bind_template(self):
  File "e:\python27\Lib\contextlib.py", line 17, in __enter__
    return self.gen.next()
  File "e:\python27\lib\site-packages\django\template\context.py", line 235, in bind_template
    updates.update(processor(self.request))
  File "F:\workspaces\Linux_learn2\blog\views.py", line 24, in global_setting
    SITE_DESC = settings.SITE_DESC
  File "e:\python27\lib\site-packages\django\conf\__init__.py", line 49, in __getattr__
    return getattr(self._wrapped, name)
AttributeError: 'Settings' object has no attribute 'SITE_DESC'
2017-04-03 01:09:50,855 [Thread-10:7016] [django.request:256] [base:handle_uncaught_exception] [ERROR]- Internal Server Error: /
Traceback (most recent call last):
  File "e:\python27\lib\site-packages\django\core\handlers\base.py", line 132, in get_response
    response = wrapped_callback(request, *callback_args, **callback_kwargs)
  File "F:\workspaces\Linux_learn2\blog\views.py", line 68, in index
    return render(request, 'index.html', locals())
  File "e:\python27\lib\site-packages\django\shortcuts.py", line 67, in render
    template_name, context, request=request, using=using)
  File "e:\python27\lib\site-packages\django\template\loader.py", line 99, in render_to_string
    return template.render(context, request)
  File "e:\python27\lib\site-packages\django\template\backends\django.py", line 74, in render
    return self.template.render(context)
  File "e:\python27\lib\site-packages\django\template\base.py", line 208, in render
    with context.bind_template(self):
  File "e:\python27\Lib\contextlib.py", line 17, in __enter__
    return self.gen.next()
  File "e:\python27\lib\site-packages\django\template\context.py", line 235, in bind_template
    updates.update(processor(self.request))
  File "F:\workspaces\Linux_learn2\blog\views.py", line 24, in global_setting
    SITE_DESC = settings.SITE_DESC
  File "e:\python27\lib\site-packages\django\conf\__init__.py", line 49, in __getattr__
    return getattr(self._wrapped, name)
AttributeError: 'Settings' object has no attribute 'SITE_DESC'
2017-04-03 01:09:52,306 [Thread-11:8396] [django.request:256] [base:handle_uncaught_exception] [ERROR]- Internal Server Error: /
Traceback (most recent call last):
  File "e:\python27\lib\site-packages\django\core\handlers\base.py", line 132, in get_response
    response = wrapped_callback(request, *callback_args, **callback_kwargs)
  File "F:\workspaces\Linux_learn2\blog\views.py", line 68, in index
    return render(request, 'index.html', locals())
  File "e:\python27\lib\site-packages\django\shortcuts.py", line 67, in render
    template_name, context, request=request, using=using)
  File "e:\python27\lib\site-packages\django\template\loader.py", line 99, in render_to_string
    return template.render(context, request)
  File "e:\python27\lib\site-packages\django\template\backends\django.py", line 74, in render
    return self.template.render(context)
  File "e:\python27\lib\site-packages\django\template\base.py", line 208, in render
    with context.bind_template(self):
  File "e:\python27\Lib\contextlib.py", line 17, in __enter__
    return self.gen.next()
  File "e:\python27\lib\site-packages\django\template\context.py", line 235, in bind_template
    updates.update(processor(self.request))
  File "F:\workspaces\Linux_learn2\blog\views.py", line 24, in global_setting
    SITE_DESC = settings.SITE_DESC
  File "e:\python27\lib\site-packages\django\conf\__init__.py", line 49, in __getattr__
    return getattr(self._wrapped, name)
AttributeError: 'Settings' object has no attribute 'SITE_DESC'
2017-04-03 01:10:33,173 [Thread-14:6524] [django.request:256] [base:handle_uncaught_exception] [ERROR]- Internal Server Error: /
Traceback (most recent call last):
  File "e:\python27\lib\site-packages\django\core\handlers\base.py", line 132, in get_response
    response = wrapped_callback(request, *callback_args, **callback_kwargs)
  File "F:\workspaces\Linux_learn2\blog\views.py", line 68, in index
    return render(request, 'index.html', locals())
  File "e:\python27\lib\site-packages\django\shortcuts.py", line 67, in render
    template_name, context, request=request, using=using)
  File "e:\python27\lib\site-packages\django\template\loader.py", line 99, in render_to_string
    return template.render(context, request)
  File "e:\python27\lib\site-packages\django\template\backends\django.py", line 74, in render
    return self.template.render(context)
  File "e:\python27\lib\site-packages\django\template\base.py", line 208, in render
    with context.bind_template(self):
  File "e:\python27\Lib\contextlib.py", line 17, in __enter__
    return self.gen.next()
  File "e:\python27\lib\site-packages\django\template\context.py", line 235, in bind_template
    updates.update(processor(self.request))
  File "F:\workspaces\Linux_learn2\blog\views.py", line 24, in global_setting
    SITE_DESC = settings.SITE_DESC
  File "e:\python27\lib\site-packages\django\conf\__init__.py", line 49, in __getattr__
    return getattr(self._wrapped, name)
AttributeError: 'Settings' object has no attribute 'SITE_DESC'
2017-04-03 01:10:40,183 [Thread-15:7584] [django.request:256] [base:handle_uncaught_exception] [ERROR]- Internal Server Error: /
Traceback (most recent call last):
  File "e:\python27\lib\site-packages\django\core\handlers\base.py", line 132, in get_response
    response = wrapped_callback(request, *callback_args, **callback_kwargs)
  File "F:\workspaces\Linux_learn2\blog\views.py", line 68, in index
    return render(request, 'index.html', locals())
  File "e:\python27\lib\site-packages\django\shortcuts.py", line 67, in render
    template_name, context, request=request, using=using)
  File "e:\python27\lib\site-packages\django\template\loader.py", line 99, in render_to_string
    return template.render(context, request)
  File "e:\python27\lib\site-packages\django\template\backends\django.py", line 74, in render
    return self.template.render(context)
  File "e:\python27\lib\site-packages\django\template\base.py", line 208, in render
    with context.bind_template(self):
  File "e:\python27\Lib\contextlib.py", line 17, in __enter__
    return self.gen.next()
  File "e:\python27\lib\site-packages\django\template\context.py", line 235, in bind_template
    updates.update(processor(self.request))
  File "F:\workspaces\Linux_learn2\blog\views.py", line 24, in global_setting
    SITE_DESC = settings.SITE_DESC
  File "e:\python27\lib\site-packages\django\conf\__init__.py", line 49, in __getattr__
    return getattr(self._wrapped, name)
AttributeError: 'Settings' object has no attribute 'SITE_DESC'
2017-04-03 01:11:54,341 [Thread-2:6520] [django.request:256] [base:handle_uncaught_exception] [ERROR]- Internal Server Error: /
Traceback (most recent call last):
  File "e:\python27\lib\site-packages\django\core\handlers\base.py", line 132, in get_response
    response = wrapped_callback(request, *callback_args, **callback_kwargs)
  File "F:\workspaces\Linux_learn2\blog\views.py", line 68, in index
    return render(request, 'index.html', locals())
  File "e:\python27\lib\site-packages\django\shortcuts.py", line 67, in render
    template_name, context, request=request, using=using)
  File "e:\python27\lib\site-packages\django\template\loader.py", line 99, in render_to_string
    return template.render(context, request)
  File "e:\python27\lib\site-packages\django\template\backends\django.py", line 74, in render
    return self.template.render(context)
  File "e:\python27\lib\site-packages\django\template\base.py", line 208, in render
    with context.bind_template(self):
  File "e:\python27\Lib\contextlib.py", line 17, in __enter__
    return self.gen.next()
  File "e:\python27\lib\site-packages\django\template\context.py", line 235, in bind_template
    updates.update(processor(self.request))
  File "F:\workspaces\Linux_learn2\blog\views.py", line 24, in global_setting
    SITE_DESC = settings.SITE_DESC
  File "e:\python27\lib\site-packages\django\conf\__init__.py", line 49, in __getattr__
    return getattr(self._wrapped, name)
AttributeError: 'Settings' object has no attribute 'SITE_DESC'
2017-04-03 01:12:11,582 [Thread-3:7920] [django.request:256] [base:handle_uncaught_exception] [ERROR]- Internal Server Error: /
Traceback (most recent call last):
  File "e:\python27\lib\site-packages\django\core\handlers\base.py", line 132, in get_response
    response = wrapped_callback(request, *callback_args, **callback_kwargs)
  File "F:\workspaces\Linux_learn2\blog\views.py", line 68, in index
    return render(request, 'index.html', locals())
  File "e:\python27\lib\site-packages\django\shortcuts.py", line 67, in render
    template_name, context, request=request, using=using)
  File "e:\python27\lib\site-packages\django\template\loader.py", line 99, in render_to_string
    return template.render(context, request)
  File "e:\python27\lib\site-packages\django\template\backends\django.py", line 74, in render
    return self.template.render(context)
  File "e:\python27\lib\site-packages\django\template\base.py", line 208, in render
    with context.bind_template(self):
  File "e:\python27\Lib\contextlib.py", line 17, in __enter__
    return self.gen.next()
  File "e:\python27\lib\site-packages\django\template\context.py", line 235, in bind_template
    updates.update(processor(self.request))
  File "F:\workspaces\Linux_learn2\blog\views.py", line 24, in global_setting
    SITE_DESC = settings.SITE_DESC
  File "e:\python27\lib\site-packages\django\conf\__init__.py", line 49, in __getattr__
    return getattr(self._wrapped, name)
AttributeError: 'Settings' object has no attribute 'SITE_DESC'
2017-04-03 01:12:12,006 [Thread-4:8664] [django.request:256] [base:handle_uncaught_exception] [ERROR]- Internal Server Error: /
Traceback (most recent call last):
  File "e:\python27\lib\site-packages\django\core\handlers\base.py", line 132, in get_response
    response = wrapped_callback(request, *callback_args, **callback_kwargs)
  File "F:\workspaces\Linux_learn2\blog\views.py", line 68, in index
    return render(request, 'index.html', locals())
  File "e:\python27\lib\site-packages\django\shortcuts.py", line 67, in render
    template_name, context, request=request, using=using)
  File "e:\python27\lib\site-packages\django\template\loader.py", line 99, in render_to_string
    return template.render(context, request)
  File "e:\python27\lib\site-packages\django\template\backends\django.py", line 74, in render
    return self.template.render(context)
  File "e:\python27\lib\site-packages\django\template\base.py", line 208, in render
    with context.bind_template(self):
  File "e:\python27\Lib\contextlib.py", line 17, in __enter__
    return self.gen.next()
  File "e:\python27\lib\site-packages\django\template\context.py", line 235, in bind_template
    updates.update(processor(self.request))
  File "F:\workspaces\Linux_learn2\blog\views.py", line 24, in global_setting
    SITE_DESC = settings.SITE_DESC
  File "e:\python27\lib\site-packages\django\conf\__init__.py", line 49, in __getattr__
    return getattr(self._wrapped, name)
AttributeError: 'Settings' object has no attribute 'SITE_DESC'
2017-04-03 01:55:16,772 [Thread-2:11964] [django.request:256] [base:handle_uncaught_exception] [ERROR]- Internal Server Error: /home/
Traceback (most recent call last):
  File "e:\python27\lib\site-packages\django\core\handlers\base.py", line 132, in get_response
    response = wrapped_callback(request, *callback_args, **callback_kwargs)
  File "F:\workspaces\Linux_learn2\VideoHome\views.py", line 5, in videohome
    return render(request, 'vidoehome.html', locals())
  File "e:\python27\lib\site-packages\django\shortcuts.py", line 67, in render
    template_name, context, request=request, using=using)
  File "e:\python27\lib\site-packages\django\template\loader.py", line 98, in render_to_string
    template = get_template(template_name, using=using)
  File "e:\python27\lib\site-packages\django\template\loader.py", line 46, in get_template
    raise TemplateDoesNotExist(template_name)
TemplateDoesNotExist: vidoehome.html
2017-04-03 01:58:01,006 [Thread-2:11596] [django.request:256] [base:handle_uncaught_exception] [ERROR]- Internal Server Error: /home/
Traceback (most recent call last):
  File "e:\python27\lib\site-packages\django\core\handlers\base.py", line 119, in get_response
    resolver_match = resolver.resolve(request.path_info)
  File "e:\python27\lib\site-packages\django\core\urlresolvers.py", line 366, in resolve
    for pattern in self.url_patterns:
  File "e:\python27\lib\site-packages\django\core\urlresolvers.py", line 402, in url_patterns
    patterns = getattr(self.urlconf_module, "urlpatterns", self.urlconf_module)
  File "e:\python27\lib\site-packages\django\core\urlresolvers.py", line 396, in urlconf_module
    self._urlconf_module = import_module(self.urlconf_name)
  File "e:\python27\Lib\importlib\__init__.py", line 37, in import_module
    __import__(name)
  File "F:\workspaces\Linux_learn2\Linux_learn2\urls.py", line 28, in <module>
    url(r'^', include('VideoHome.urls')),
  File "e:\python27\lib\site-packages\django\conf\urls\__init__.py", line 33, in include
    urlconf_module = import_module(urlconf_module)
  File "e:\python27\Lib\importlib\__init__.py", line 37, in import_module
    __import__(name)
  File "F:\workspaces\Linux_learn2\VideoHome\urls.py", line 16, in <module>
    from forms import *
ImportError: No module named forms
2017-04-03 02:02:19,085 [Thread-6:5940] [django.request:256] [base:handle_uncaught_exception] [ERROR]- Internal Server Error: /home/
Traceback (most recent call last):
  File "e:\python27\lib\site-packages\django\core\handlers\base.py", line 119, in get_response
    resolver_match = resolver.resolve(request.path_info)
  File "e:\python27\lib\site-packages\django\core\urlresolvers.py", line 366, in resolve
    for pattern in self.url_patterns:
  File "e:\python27\lib\site-packages\django\core\urlresolvers.py", line 402, in url_patterns
    patterns = getattr(self.urlconf_module, "urlpatterns", self.urlconf_module)
  File "e:\python27\lib\site-packages\django\core\urlresolvers.py", line 396, in urlconf_module
    self._urlconf_module = import_module(self.urlconf_name)
  File "e:\python27\Lib\importlib\__init__.py", line 37, in import_module
    __import__(name)
  File "F:\workspaces\Linux_learn2\Linux_learn2\urls.py", line 28, in <module>
    url(r'^', include('VideoHome.urls')),
  File "e:\python27\lib\site-packages\django\conf\urls\__init__.py", line 33, in include
    urlconf_module = import_module(urlconf_module)
  File "e:\python27\Lib\importlib\__init__.py", line 37, in import_module
    __import__(name)
  File "F:\workspaces\Linux_learn2\VideoHome\urls.py", line 16, in <module>
    from forms import *
ImportError: No module named forms
2017-04-03 02:04:37,362 [Thread-2:12020] [django.request:256] [base:handle_uncaught_exception] [ERROR]- Internal Server Error: /
Traceback (most recent call last):
  File "e:\python27\lib\site-packages\django\core\handlers\base.py", line 119, in get_response
    resolver_match = resolver.resolve(request.path_info)
  File "e:\python27\lib\site-packages\django\core\urlresolvers.py", line 366, in resolve
    for pattern in self.url_patterns:
  File "e:\python27\lib\site-packages\django\core\urlresolvers.py", line 402, in url_patterns
    patterns = getattr(self.urlconf_module, "urlpatterns", self.urlconf_module)
  File "e:\python27\lib\site-packages\django\core\urlresolvers.py", line 396, in urlconf_module
    self._urlconf_module = import_module(self.urlconf_name)
  File "e:\python27\Lib\importlib\__init__.py", line 37, in import_module
    __import__(name)
  File "F:\workspaces\Linux_learn2\Linux_learn2\urls.py", line 28, in <module>
    url(r'^', include('VideoHome.urls')),
  File "e:\python27\lib\site-packages\django\conf\urls\__init__.py", line 33, in include
    urlconf_module = import_module(urlconf_module)
  File "e:\python27\Lib\importlib\__init__.py", line 37, in import_module
    __import__(name)
  File "F:\workspaces\Linux_learn2\VideoHome\urls.py", line 16, in <module>
    from forms import *
ImportError: No module named forms
2017-04-03 02:05:59,434 [Thread-4:12648] [django.request:256] [base:handle_uncaught_exception] [ERROR]- Internal Server Error: /
Traceback (most recent call last):
  File "e:\python27\lib\site-packages\django\core\handlers\base.py", line 119, in get_response
    resolver_match = resolver.resolve(request.path_info)
  File "e:\python27\lib\site-packages\django\core\urlresolvers.py", line 366, in resolve
    for pattern in self.url_patterns:
  File "e:\python27\lib\site-packages\django\core\urlresolvers.py", line 402, in url_patterns
    patterns = getattr(self.urlconf_module, "urlpatterns", self.urlconf_module)
  File "e:\python27\lib\site-packages\django\core\urlresolvers.py", line 396, in urlconf_module
    self._urlconf_module = import_module(self.urlconf_name)
  File "e:\python27\Lib\importlib\__init__.py", line 37, in import_module
    __import__(name)
  File "F:\workspaces\Linux_learn2\Linux_learn2\urls.py", line 28, in <module>
    url(r'^home', include('VideoHome.urls')),
  File "e:\python27\lib\site-packages\django\conf\urls\__init__.py", line 33, in include
    urlconf_module = import_module(urlconf_module)
  File "e:\python27\Lib\importlib\__init__.py", line 37, in import_module
    __import__(name)
  File "F:\workspaces\Linux_learn2\VideoHome\urls.py", line 16, in <module>
    from forms import *
ImportError: No module named forms
2017-04-03 02:06:09,490 [Thread-5:9764] [django.request:256] [base:handle_uncaught_exception] [ERROR]- Internal Server Error: /
Traceback (most recent call last):
  File "e:\python27\lib\site-packages\django\core\handlers\base.py", line 119, in get_response
    resolver_match = resolver.resolve(request.path_info)
  File "e:\python27\lib\site-packages\django\core\urlresolvers.py", line 366, in resolve
    for pattern in self.url_patterns:
  File "e:\python27\lib\site-packages\django\core\urlresolvers.py", line 402, in url_patterns
    patterns = getattr(self.urlconf_module, "urlpatterns", self.urlconf_module)
  File "e:\python27\lib\site-packages\django\core\urlresolvers.py", line 396, in urlconf_module
    self._urlconf_module = import_module(self.urlconf_name)
  File "e:\python27\Lib\importlib\__init__.py", line 37, in import_module
    __import__(name)
  File "F:\workspaces\Linux_learn2\Linux_learn2\urls.py", line 28, in <module>
    url(r'^home', include('VideoHome.urls')),
  File "e:\python27\lib\site-packages\django\conf\urls\__init__.py", line 33, in include
    urlconf_module = import_module(urlconf_module)
  File "e:\python27\Lib\importlib\__init__.py", line 37, in import_module
    __import__(name)
  File "F:\workspaces\Linux_learn2\VideoHome\urls.py", line 16, in <module>
    from forms import *
ImportError: No module named forms
2017-04-03 02:06:09,953 [Thread-6:11576] [django.request:256] [base:handle_uncaught_exception] [ERROR]- Internal Server Error: /
Traceback (most recent call last):
  File "e:\python27\lib\site-packages\django\core\handlers\base.py", line 119, in get_response
    resolver_match = resolver.resolve(request.path_info)
  File "e:\python27\lib\site-packages\django\core\urlresolvers.py", line 366, in resolve
    for pattern in self.url_patterns:
  File "e:\python27\lib\site-packages\django\core\urlresolvers.py", line 402, in url_patterns
    patterns = getattr(self.urlconf_module, "urlpatterns", self.urlconf_module)
  File "e:\python27\lib\site-packages\django\core\urlresolvers.py", line 396, in urlconf_module
    self._urlconf_module = import_module(self.urlconf_name)
  File "e:\python27\Lib\importlib\__init__.py", line 37, in import_module
    __import__(name)
  File "F:\workspaces\Linux_learn2\Linux_learn2\urls.py", line 28, in <module>
    url(r'^home', include('VideoHome.urls')),
  File "e:\python27\lib\site-packages\django\conf\urls\__init__.py", line 33, in include
    urlconf_module = import_module(urlconf_module)
  File "e:\python27\Lib\importlib\__init__.py", line 37, in import_module
    __import__(name)
  File "F:\workspaces\Linux_learn2\VideoHome\urls.py", line 16, in <module>
    from forms import *
ImportError: No module named forms
2017-04-03 02:06:28,566 [Thread-2:11808] [django.request:256] [base:handle_uncaught_exception] [ERROR]- Internal Server Error: /
Traceback (most recent call last):
  File "e:\python27\lib\site-packages\django\core\handlers\base.py", line 119, in get_response
    resolver_match = resolver.resolve(request.path_info)
  File "e:\python27\lib\site-packages\django\core\urlresolvers.py", line 366, in resolve
    for pattern in self.url_patterns:
  File "e:\python27\lib\site-packages\django\core\urlresolvers.py", line 402, in url_patterns
    patterns = getattr(self.urlconf_module, "urlpatterns", self.urlconf_module)
  File "e:\python27\lib\site-packages\django\core\urlresolvers.py", line 396, in urlconf_module
    self._urlconf_module = import_module(self.urlconf_name)
  File "e:\python27\Lib\importlib\__init__.py", line 37, in import_module
    __import__(name)
  File "F:\workspaces\Linux_learn2\Linux_learn2\urls.py", line 28, in <module>
    url(r'^home', include('VideoHome.urls')),
  File "e:\python27\lib\site-packages\django\conf\urls\__init__.py", line 33, in include
    urlconf_module = import_module(urlconf_module)
  File "e:\python27\Lib\importlib\__init__.py", line 37, in import_module
    __import__(name)
  File "F:\workspaces\Linux_learn2\VideoHome\urls.py", line 16, in <module>
    from forms import *
ImportError: No module named forms
2017-04-03 02:06:30,391 [Thread-3:13160] [django.request:256] [base:handle_uncaught_exception] [ERROR]- Internal Server Error: /
Traceback (most recent call last):
  File "e:\python27\lib\site-packages\django\core\handlers\base.py", line 119, in get_response
    resolver_match = resolver.resolve(request.path_info)
  File "e:\python27\lib\site-packages\django\core\urlresolvers.py", line 366, in resolve
    for pattern in self.url_patterns:
  File "e:\python27\lib\site-packages\django\core\urlresolvers.py", line 402, in url_patterns
    patterns = getattr(self.urlconf_module, "urlpatterns", self.urlconf_module)
  File "e:\python27\lib\site-packages\django\core\urlresolvers.py", line 396, in urlconf_module
    self._urlconf_module = import_module(self.urlconf_name)
  File "e:\python27\Lib\importlib\__init__.py", line 37, in import_module
    __import__(name)
  File "F:\workspaces\Linux_learn2\Linux_learn2\urls.py", line 28, in <module>
    url(r'^home', include('VideoHome.urls')),
  File "e:\python27\lib\site-packages\django\conf\urls\__init__.py", line 33, in include
    urlconf_module = import_module(urlconf_module)
  File "e:\python27\Lib\importlib\__init__.py", line 37, in import_module
    __import__(name)
  File "F:\workspaces\Linux_learn2\VideoHome\urls.py", line 16, in <module>
    from forms import *
ImportError: No module named forms
2017-04-03 02:06:31,244 [Thread-4:12080] [django.request:256] [base:handle_uncaught_exception] [ERROR]- Internal Server Error: /
Traceback (most recent call last):
  File "e:\python27\lib\site-packages\django\core\handlers\base.py", line 119, in get_response
    resolver_match = resolver.resolve(request.path_info)
  File "e:\python27\lib\site-packages\django\core\urlresolvers.py", line 366, in resolve
    for pattern in self.url_patterns:
  File "e:\python27\lib\site-packages\django\core\urlresolvers.py", line 402, in url_patterns
    patterns = getattr(self.urlconf_module, "urlpatterns", self.urlconf_module)
  File "e:\python27\lib\site-packages\django\core\urlresolvers.py", line 396, in urlconf_module
    self._urlconf_module = import_module(self.urlconf_name)
  File "e:\python27\Lib\importlib\__init__.py", line 37, in import_module
    __import__(name)
  File "F:\workspaces\Linux_learn2\Linux_learn2\urls.py", line 28, in <module>
    url(r'^home', include('VideoHome.urls')),
  File "e:\python27\lib\site-packages\django\conf\urls\__init__.py", line 33, in include
    urlconf_module = import_module(urlconf_module)
  File "e:\python27\Lib\importlib\__init__.py", line 37, in import_module
    __import__(name)
  File "F:\workspaces\Linux_learn2\VideoHome\urls.py", line 16, in <module>
    from forms import *
ImportError: No module named forms
2017-04-03 02:06:58,884 [Thread-5:8264] [django.request:170] [base:get_response] [WARNING]- Not Found: /
2017-04-03 02:07:36,145 [Thread-2:12940] [django.request:256] [base:handle_uncaught_exception] [ERROR]- Internal Server Error: /blog
Traceback (most recent call last):
  File "e:\python27\lib\site-packages\django\core\handlers\base.py", line 108, in get_response
    response = middleware_method(request)
  File "e:\python27\lib\site-packages\django\middleware\common.py", line 74, in process_request
    if (not urlresolvers.is_valid_path(request.path_info, urlconf) and
  File "e:\python27\lib\site-packages\django\core\urlresolvers.py", line 647, in is_valid_path
    resolve(path, urlconf)
  File "e:\python27\lib\site-packages\django\core\urlresolvers.py", line 522, in resolve
    return get_resolver(urlconf).resolve(path)
  File "e:\python27\lib\site-packages\django\core\urlresolvers.py", line 366, in resolve
    for pattern in self.url_patterns:
  File "e:\python27\lib\site-packages\django\core\urlresolvers.py", line 402, in url_patterns
    patterns = getattr(self.urlconf_module, "urlpatterns", self.urlconf_module)
  File "e:\python27\lib\site-packages\django\core\urlresolvers.py", line 396, in urlconf_module
    self._urlconf_module = import_module(self.urlconf_name)
  File "e:\python27\Lib\importlib\__init__.py", line 37, in import_module
    __import__(name)
  File "F:\workspaces\Linux_learn2\Linux_learn2\urls.py", line 28, in <module>
    url(r'^', include('VideoHome.urls')),
  File "e:\python27\lib\site-packages\django\conf\urls\__init__.py", line 33, in include
    urlconf_module = import_module(urlconf_module)
  File "e:\python27\Lib\importlib\__init__.py", line 37, in import_module
    __import__(name)
  File "F:\workspaces\Linux_learn2\VideoHome\urls.py", line 16, in <module>
    from forms import *
ImportError: No module named forms
2017-04-03 02:07:40,038 [Thread-3:12668] [django.request:256] [base:handle_uncaught_exception] [ERROR]- Internal Server Error: /
Traceback (most recent call last):
  File "e:\python27\lib\site-packages\django\core\handlers\base.py", line 119, in get_response
    resolver_match = resolver.resolve(request.path_info)
  File "e:\python27\lib\site-packages\django\core\urlresolvers.py", line 366, in resolve
    for pattern in self.url_patterns:
  File "e:\python27\lib\site-packages\django\core\urlresolvers.py", line 402, in url_patterns
    patterns = getattr(self.urlconf_module, "urlpatterns", self.urlconf_module)
  File "e:\python27\lib\site-packages\django\core\urlresolvers.py", line 396, in urlconf_module
    self._urlconf_module = import_module(self.urlconf_name)
  File "e:\python27\Lib\importlib\__init__.py", line 37, in import_module
    __import__(name)
  File "F:\workspaces\Linux_learn2\Linux_learn2\urls.py", line 28, in <module>
    url(r'^', include('VideoHome.urls')),
  File "e:\python27\lib\site-packages\django\conf\urls\__init__.py", line 33, in include
    urlconf_module = import_module(urlconf_module)
  File "e:\python27\Lib\importlib\__init__.py", line 37, in import_module
    __import__(name)
  File "F:\workspaces\Linux_learn2\VideoHome\urls.py", line 16, in <module>
    from forms import *
ImportError: No module named forms
2017-04-03 02:10:37,687 [Thread-9:12560] [django.request:256] [base:handle_uncaught_exception] [ERROR]- Internal Server Error: /
Traceback (most recent call last):
  File "e:\python27\lib\site-packages\django\core\handlers\base.py", line 119, in get_response
    resolver_match = resolver.resolve(request.path_info)
  File "e:\python27\lib\site-packages\django\core\urlresolvers.py", line 366, in resolve
    for pattern in self.url_patterns:
  File "e:\python27\lib\site-packages\django\core\urlresolvers.py", line 402, in url_patterns
    patterns = getattr(self.urlconf_module, "urlpatterns", self.urlconf_module)
  File "e:\python27\lib\site-packages\django\core\urlresolvers.py", line 396, in urlconf_module
    self._urlconf_module = import_module(self.urlconf_name)
  File "e:\python27\Lib\importlib\__init__.py", line 37, in import_module
    __import__(name)
  File "F:\workspaces\Linux_learn2\Linux_learn2\urls.py", line 28, in <module>
    url(r'^', include('VideoHome.urls')),
  File "e:\python27\lib\site-packages\django\conf\urls\__init__.py", line 33, in include
    urlconf_module = import_module(urlconf_module)
  File "e:\python27\Lib\importlib\__init__.py", line 37, in import_module
    __import__(name)
  File "F:\workspaces\Linux_learn2\VideoHome\urls.py", line 16, in <module>
    from forms import *
ImportError: No module named forms
2017-04-03 02:10:38,992 [Thread-10:11976] [django.request:256] [base:handle_uncaught_exception] [ERROR]- Internal Server Error: /
Traceback (most recent call last):
  File "e:\python27\lib\site-packages\django\core\handlers\base.py", line 132, in get_response
    response = wrapped_callback(request, *callback_args, **callback_kwargs)
  File "F:\workspaces\Linux_learn2\VideoHome\views.py", line 18, in videohome
    return render(request, 'videohome.html', locals())
  File "e:\python27\lib\site-packages\django\shortcuts.py", line 67, in render
    template_name, context, request=request, using=using)
  File "e:\python27\lib\site-packages\django\template\loader.py", line 98, in render_to_string
    template = get_template(template_name, using=using)
  File "e:\python27\lib\site-packages\django\template\loader.py", line 35, in get_template
    return engine.get_template(template_name, dirs)
  File "e:\python27\lib\site-packages\django\template\backends\django.py", line 30, in get_template
    return Template(self.engine.get_template(template_name, dirs))
  File "e:\python27\lib\site-packages\django\template\engine.py", line 167, in get_template
    template, origin = self.find_template(template_name, dirs)
  File "e:\python27\lib\site-packages\django\template\engine.py", line 141, in find_template
    source, display_name = loader(name, dirs)
  File "e:\python27\lib\site-packages\django\template\loaders\base.py", line 13, in __call__
    return self.load_template(template_name, template_dirs)
  File "e:\python27\lib\site-packages\django\template\loaders\base.py", line 23, in load_template
    template = Template(source, origin, template_name, self.engine)
  File "e:\python27\lib\site-packages\django\template\base.py", line 190, in __init__
    self.nodelist = engine.compile_string(template_string, origin)
  File "e:\python27\lib\site-packages\django\template\engine.py", line 261, in compile_string
    return parser.parse()
  File "e:\python27\lib\site-packages\django\template\base.py", line 339, in parse
    self.invalid_block_tag(token, command, parse_until)
  File "e:\python27\lib\site-packages\django\template\base.py", line 395, in invalid_block_tag
    raise self.error(token, "Invalid block tag: '%s'" % command)
TemplateSyntaxError: Invalid block tag: 'static'
2017-04-03 02:10:40,005 [Thread-11:13028] [django.request:256] [base:handle_uncaught_exception] [ERROR]- Internal Server Error: /
Traceback (most recent call last):
  File "e:\python27\lib\site-packages\django\core\handlers\base.py", line 132, in get_response
    response = wrapped_callback(request, *callback_args, **callback_kwargs)
  File "F:\workspaces\Linux_learn2\VideoHome\views.py", line 18, in videohome
    return render(request, 'videohome.html', locals())
  File "e:\python27\lib\site-packages\django\shortcuts.py", line 67, in render
    template_name, context, request=request, using=using)
  File "e:\python27\lib\site-packages\django\template\loader.py", line 98, in render_to_string
    template = get_template(template_name, using=using)
  File "e:\python27\lib\site-packages\django\template\loader.py", line 35, in get_template
    return engine.get_template(template_name, dirs)
  File "e:\python27\lib\site-packages\django\template\backends\django.py", line 30, in get_template
    return Template(self.engine.get_template(template_name, dirs))
  File "e:\python27\lib\site-packages\django\template\engine.py", line 167, in get_template
    template, origin = self.find_template(template_name, dirs)
  File "e:\python27\lib\site-packages\django\template\engine.py", line 141, in find_template
    source, display_name = loader(name, dirs)
  File "e:\python27\lib\site-packages\django\template\loaders\base.py", line 13, in __call__
    return self.load_template(template_name, template_dirs)
  File "e:\python27\lib\site-packages\django\template\loaders\base.py", line 23, in load_template
    template = Template(source, origin, template_name, self.engine)
  File "e:\python27\lib\site-packages\django\template\base.py", line 190, in __init__
    self.nodelist = engine.compile_string(template_string, origin)
  File "e:\python27\lib\site-packages\django\template\engine.py", line 261, in compile_string
    return parser.parse()
  File "e:\python27\lib\site-packages\django\template\base.py", line 339, in parse
    self.invalid_block_tag(token, command, parse_until)
  File "e:\python27\lib\site-packages\django\template\base.py", line 395, in invalid_block_tag
    raise self.error(token, "Invalid block tag: '%s'" % command)
TemplateSyntaxError: Invalid block tag: 'static'
2017-04-03 02:10:54,049 [Thread-14:13628] [django.request:256] [base:handle_uncaught_exception] [ERROR]- Internal Server Error: /
Traceback (most recent call last):
  File "e:\python27\lib\site-packages\django\core\handlers\base.py", line 132, in get_response
    response = wrapped_callback(request, *callback_args, **callback_kwargs)
  File "F:\workspaces\Linux_learn2\VideoHome\views.py", line 18, in videohome
    return render(request, 'videohome.html', locals())
  File "e:\python27\lib\site-packages\django\shortcuts.py", line 67, in render
    template_name, context, request=request, using=using)
  File "e:\python27\lib\site-packages\django\template\loader.py", line 98, in render_to_string
    template = get_template(template_name, using=using)
  File "e:\python27\lib\site-packages\django\template\loader.py", line 35, in get_template
    return engine.get_template(template_name, dirs)
  File "e:\python27\lib\site-packages\django\template\backends\django.py", line 30, in get_template
    return Template(self.engine.get_template(template_name, dirs))
  File "e:\python27\lib\site-packages\django\template\engine.py", line 167, in get_template
    template, origin = self.find_template(template_name, dirs)
  File "e:\python27\lib\site-packages\django\template\engine.py", line 141, in find_template
    source, display_name = loader(name, dirs)
  File "e:\python27\lib\site-packages\django\template\loaders\base.py", line 13, in __call__
    return self.load_template(template_name, template_dirs)
  File "e:\python27\lib\site-packages\django\template\loaders\base.py", line 23, in load_template
    template = Template(source, origin, template_name, self.engine)
  File "e:\python27\lib\site-packages\django\template\base.py", line 190, in __init__
    self.nodelist = engine.compile_string(template_string, origin)
  File "e:\python27\lib\site-packages\django\template\engine.py", line 261, in compile_string
    return parser.parse()
  File "e:\python27\lib\site-packages\django\template\base.py", line 339, in parse
    self.invalid_block_tag(token, command, parse_until)
  File "e:\python27\lib\site-packages\django\template\base.py", line 395, in invalid_block_tag
    raise self.error(token, "Invalid block tag: '%s'" % command)
TemplateSyntaxError: Invalid block tag: 'static'
2017-04-03 02:10:55,892 [Thread-2:13700] [django.request:170] [base:get_response] [WARNING]- Not Found: /
2017-04-03 06:16:55,855 [Thread-2:2876] [django.request:170] [base:get_response] [WARNING]- Not Found: /
2017-04-03 06:16:55,950 [Thread-3:1504] [django.request:170] [base:get_response] [WARNING]- Not Found: /favicon.ico
2017-04-03 19:54:04,390 [Thread-20:10116] [django.request:170] [base:get_response] [WARNING]- Not Found: /favicon.ico
2017-04-04 04:29:34,834 [Thread-20:18660] [django.request:170] [base:get_response] [WARNING]- Not Found: /favicon.ico
2017-04-04 04:29:41,178 [Thread-21:5964] [django.request:170] [base:get_response] [WARNING]- Not Found: /home
2017-04-04 04:29:45,900 [Thread-22:4180] [django.request:170] [base:get_response] [WARNING]- Not Found: /home/home
2017-04-04 04:30:05,009 [Thread-28:19592] [django.request:170] [base:get_response] [WARNING]- Not Found: /home
2017-04-04 04:30:19,071 [Thread-3:15856] [django.request:256] [base:handle_uncaught_exception] [ERROR]- Internal Server Error: /home/
Traceback (most recent call last):
  File "c:\python27\lib\site-packages\django\core\handlers\base.py", line 132, in get_response
    response = wrapped_callback(request, *callback_args, **callback_kwargs)
  File "F:\workspaces\Linux_learn2\VideoHome\views.py", line 17, in videohome
    return render(request, 'videohome.html', locals())
  File "c:\python27\lib\site-packages\django\shortcuts.py", line 67, in render
    template_name, context, request=request, using=using)
  File "c:\python27\lib\site-packages\django\template\loader.py", line 98, in render_to_string
    template = get_template(template_name, using=using)
  File "c:\python27\lib\site-packages\django\template\loader.py", line 35, in get_template
    return engine.get_template(template_name, dirs)
  File "c:\python27\lib\site-packages\django\template\backends\django.py", line 30, in get_template
    return Template(self.engine.get_template(template_name, dirs))
  File "c:\python27\lib\site-packages\django\template\engine.py", line 167, in get_template
    template, origin = self.find_template(template_name, dirs)
  File "c:\python27\lib\site-packages\django\template\engine.py", line 141, in find_template
    source, display_name = loader(name, dirs)
  File "c:\python27\lib\site-packages\django\template\loaders\base.py", line 13, in __call__
    return self.load_template(template_name, template_dirs)
  File "c:\python27\lib\site-packages\django\template\loaders\base.py", line 23, in load_template
    template = Template(source, origin, template_name, self.engine)
  File "c:\python27\lib\site-packages\django\template\base.py", line 190, in __init__
    self.nodelist = engine.compile_string(template_string, origin)
  File "c:\python27\lib\site-packages\django\template\engine.py", line 261, in compile_string
    return parser.parse()
  File "c:\python27\lib\site-packages\django\template\base.py", line 339, in parse
    self.invalid_block_tag(token, command, parse_until)
  File "c:\python27\lib\site-packages\django\template\base.py", line 395, in invalid_block_tag
    raise self.error(token, "Invalid block tag: '%s'" % command)
TemplateSyntaxError: Invalid block tag: 'static'
2017-04-04 04:31:28,234 [Thread-7:11804] [django.request:256] [base:handle_uncaught_exception] [ERROR]- Internal Server Error: /home/
Traceback (most recent call last):
  File "c:\python27\lib\site-packages\django\core\handlers\base.py", line 132, in get_response
    response = wrapped_callback(request, *callback_args, **callback_kwargs)
  File "F:\workspaces\Linux_learn2\VideoHome\views.py", line 17, in videohome
    return render(request, 'videohome.html', locals())
  File "c:\python27\lib\site-packages\django\shortcuts.py", line 67, in render
    template_name, context, request=request, using=using)
  File "c:\python27\lib\site-packages\django\template\loader.py", line 98, in render_to_string
    template = get_template(template_name, using=using)
  File "c:\python27\lib\site-packages\django\template\loader.py", line 35, in get_template
    return engine.get_template(template_name, dirs)
  File "c:\python27\lib\site-packages\django\template\backends\django.py", line 30, in get_template
    return Template(self.engine.get_template(template_name, dirs))
  File "c:\python27\lib\site-packages\django\template\engine.py", line 167, in get_template
    template, origin = self.find_template(template_name, dirs)
  File "c:\python27\lib\site-packages\django\template\engine.py", line 141, in find_template
    source, display_name = loader(name, dirs)
  File "c:\python27\lib\site-packages\django\template\loaders\base.py", line 13, in __call__
    return self.load_template(template_name, template_dirs)
  File "c:\python27\lib\site-packages\django\template\loaders\base.py", line 23, in load_template
    template = Template(source, origin, template_name, self.engine)
  File "c:\python27\lib\site-packages\django\template\base.py", line 190, in __init__
    self.nodelist = engine.compile_string(template_string, origin)
  File "c:\python27\lib\site-packages\django\template\engine.py", line 261, in compile_string
    return parser.parse()
  File "c:\python27\lib\site-packages\django\template\base.py", line 339, in parse
    self.invalid_block_tag(token, command, parse_until)
  File "c:\python27\lib\site-packages\django\template\base.py", line 395, in invalid_block_tag
    raise self.error(token, "Invalid block tag: '%s'" % command)
TemplateSyntaxError: Invalid block tag: 'static'
2017-04-04 04:32:21,385 [Thread-2:15380] [django.request:256] [base:handle_uncaught_exception] [ERROR]- Internal Server Error: /home/
Traceback (most recent call last):
  File "c:\python27\lib\site-packages\django\core\handlers\base.py", line 119, in get_response
    resolver_match = resolver.resolve(request.path_info)
  File "c:\python27\lib\site-packages\django\core\urlresolvers.py", line 366, in resolve
    for pattern in self.url_patterns:
  File "c:\python27\lib\site-packages\django\core\urlresolvers.py", line 402, in url_patterns
    patterns = getattr(self.urlconf_module, "urlpatterns", self.urlconf_module)
  File "c:\python27\lib\site-packages\django\core\urlresolvers.py", line 396, in urlconf_module
    self._urlconf_module = import_module(self.urlconf_name)
  File "c:\python27\Lib\importlib\__init__.py", line 37, in import_module
    __import__(name)
  File "F:\workspaces\Linux_learn2\Linux_learn2\urls.py", line 28, in <module>
    url(r'^home', include('VideoHome.urls')),
  File "c:\python27\lib\site-packages\django\conf\urls\__init__.py", line 33, in include
    urlconf_module = import_module(urlconf_module)
  File "c:\python27\Lib\importlib\__init__.py", line 37, in import_module
    __import__(name)
  File "F:\workspaces\Linux_learn2\VideoHome\urls.py", line 3, in <module>
    from VideoHome.views import *
  File "F:\workspaces\Linux_learn2\VideoHome\views.py", line 18
    return return HttpResponse("web")
                ^
SyntaxError: invalid syntax
2017-04-04 04:32:22,581 [Thread-3:18308] [django.request:256] [base:handle_uncaught_exception] [ERROR]- Internal Server Error: /home/
Traceback (most recent call last):
  File "c:\python27\lib\site-packages\django\core\handlers\base.py", line 119, in get_response
    resolver_match = resolver.resolve(request.path_info)
  File "c:\python27\lib\site-packages\django\core\urlresolvers.py", line 366, in resolve
    for pattern in self.url_patterns:
  File "c:\python27\lib\site-packages\django\core\urlresolvers.py", line 402, in url_patterns
    patterns = getattr(self.urlconf_module, "urlpatterns", self.urlconf_module)
  File "c:\python27\lib\site-packages\django\core\urlresolvers.py", line 396, in urlconf_module
    self._urlconf_module = import_module(self.urlconf_name)
  File "c:\python27\Lib\importlib\__init__.py", line 37, in import_module
    __import__(name)
  File "F:\workspaces\Linux_learn2\Linux_learn2\urls.py", line 28, in <module>
    url(r'^home', include('VideoHome.urls')),
  File "c:\python27\lib\site-packages\django\conf\urls\__init__.py", line 33, in include
    urlconf_module = import_module(urlconf_module)
  File "c:\python27\Lib\importlib\__init__.py", line 37, in import_module
    __import__(name)
  File "F:\workspaces\Linux_learn2\VideoHome\urls.py", line 3, in <module>
    from VideoHome.views import *
  File "F:\workspaces\Linux_learn2\VideoHome\views.py", line 18
    return return HttpResponse("web")
                ^
SyntaxError: invalid syntax
2017-04-04 04:32:24,073 [Thread-4:18996] [django.request:256] [base:handle_uncaught_exception] [ERROR]- Internal Server Error: /home/
Traceback (most recent call last):
  File "c:\python27\lib\site-packages\django\core\handlers\base.py", line 119, in get_response
    resolver_match = resolver.resolve(request.path_info)
  File "c:\python27\lib\site-packages\django\core\urlresolvers.py", line 366, in resolve
    for pattern in self.url_patterns:
  File "c:\python27\lib\site-packages\django\core\urlresolvers.py", line 402, in url_patterns
    patterns = getattr(self.urlconf_module, "urlpatterns", self.urlconf_module)
  File "c:\python27\lib\site-packages\django\core\urlresolvers.py", line 396, in urlconf_module
    self._urlconf_module = import_module(self.urlconf_name)
  File "c:\python27\Lib\importlib\__init__.py", line 37, in import_module
    __import__(name)
  File "F:\workspaces\Linux_learn2\Linux_learn2\urls.py", line 28, in <module>
    url(r'^home', include('VideoHome.urls')),
  File "c:\python27\lib\site-packages\django\conf\urls\__init__.py", line 33, in include
    urlconf_module = import_module(urlconf_module)
  File "c:\python27\Lib\importlib\__init__.py", line 37, in import_module
    __import__(name)
  File "F:\workspaces\Linux_learn2\VideoHome\urls.py", line 3, in <module>
    from VideoHome.views import *
  File "F:\workspaces\Linux_learn2\VideoHome\views.py", line 18
    return return HttpResponse("web")
                ^
SyntaxError: invalid syntax
2017-04-04 04:33:06,756 [Thread-2:19432] [django.request:256] [base:handle_uncaught_exception] [ERROR]- Internal Server Error: /home/
Traceback (most recent call last):
  File "c:\python27\lib\site-packages\django\core\handlers\base.py", line 132, in get_response
    response = wrapped_callback(request, *callback_args, **callback_kwargs)
  File "F:\workspaces\Linux_learn2\VideoHome\views.py", line 18, in videohome
    return render(request, 'videohome.html', locals())
  File "c:\python27\lib\site-packages\django\shortcuts.py", line 67, in render
    template_name, context, request=request, using=using)
  File "c:\python27\lib\site-packages\django\template\loader.py", line 98, in render_to_string
    template = get_template(template_name, using=using)
  File "c:\python27\lib\site-packages\django\template\loader.py", line 35, in get_template
    return engine.get_template(template_name, dirs)
  File "c:\python27\lib\site-packages\django\template\backends\django.py", line 30, in get_template
    return Template(self.engine.get_template(template_name, dirs))
  File "c:\python27\lib\site-packages\django\template\engine.py", line 167, in get_template
    template, origin = self.find_template(template_name, dirs)
  File "c:\python27\lib\site-packages\django\template\engine.py", line 141, in find_template
    source, display_name = loader(name, dirs)
  File "c:\python27\lib\site-packages\django\template\loaders\base.py", line 13, in __call__
    return self.load_template(template_name, template_dirs)
  File "c:\python27\lib\site-packages\django\template\loaders\base.py", line 23, in load_template
    template = Template(source, origin, template_name, self.engine)
  File "c:\python27\lib\site-packages\django\template\base.py", line 190, in __init__
    self.nodelist = engine.compile_string(template_string, origin)
  File "c:\python27\lib\site-packages\django\template\engine.py", line 261, in compile_string
    return parser.parse()
  File "c:\python27\lib\site-packages\django\template\base.py", line 339, in parse
    self.invalid_block_tag(token, command, parse_until)
  File "c:\python27\lib\site-packages\django\template\base.py", line 395, in invalid_block_tag
    raise self.error(token, "Invalid block tag: '%s'" % command)
TemplateSyntaxError: Invalid block tag: 'static'
2017-04-04 04:33:26,099 [Thread-5:3000] [django.request:256] [base:handle_uncaught_exception] [ERROR]- Internal Server Error: /home/
Traceback (most recent call last):
  File "c:\python27\lib\site-packages\django\core\handlers\base.py", line 132, in get_response
    response = wrapped_callback(request, *callback_args, **callback_kwargs)
  File "F:\workspaces\Linux_learn2\VideoHome\views.py", line 18, in videohome
    return render(request, 'base.html', locals())
  File "c:\python27\lib\site-packages\django\shortcuts.py", line 67, in render
    template_name, context, request=request, using=using)
  File "c:\python27\lib\site-packages\django\template\loader.py", line 98, in render_to_string
    template = get_template(template_name, using=using)
  File "c:\python27\lib\site-packages\django\template\loader.py", line 35, in get_template
    return engine.get_template(template_name, dirs)
  File "c:\python27\lib\site-packages\django\template\backends\django.py", line 30, in get_template
    return Template(self.engine.get_template(template_name, dirs))
  File "c:\python27\lib\site-packages\django\template\engine.py", line 167, in get_template
    template, origin = self.find_template(template_name, dirs)
  File "c:\python27\lib\site-packages\django\template\engine.py", line 141, in find_template
    source, display_name = loader(name, dirs)
  File "c:\python27\lib\site-packages\django\template\loaders\base.py", line 13, in __call__
    return self.load_template(template_name, template_dirs)
  File "c:\python27\lib\site-packages\django\template\loaders\base.py", line 23, in load_template
    template = Template(source, origin, template_name, self.engine)
  File "c:\python27\lib\site-packages\django\template\base.py", line 190, in __init__
    self.nodelist = engine.compile_string(template_string, origin)
  File "c:\python27\lib\site-packages\django\template\engine.py", line 261, in compile_string
    return parser.parse()
  File "c:\python27\lib\site-packages\django\template\base.py", line 339, in parse
    self.invalid_block_tag(token, command, parse_until)
  File "c:\python27\lib\site-packages\django\template\base.py", line 395, in invalid_block_tag
    raise self.error(token, "Invalid block tag: '%s'" % command)
TemplateSyntaxError: Invalid block tag: 'static'
2017-04-04 04:33:49,302 [Thread-2:16624] [django.request:256] [base:handle_uncaught_exception] [ERROR]- Internal Server Error: /home/
Traceback (most recent call last):
  File "c:\python27\lib\site-packages\django\core\handlers\base.py", line 132, in get_response
    response = wrapped_callback(request, *callback_args, **callback_kwargs)
  File "F:\workspaces\Linux_learn2\VideoHome\views.py", line 18, in videohome
    return render(request, 'videohome.html', locals())
  File "c:\python27\lib\site-packages\django\shortcuts.py", line 67, in render
    template_name, context, request=request, using=using)
  File "c:\python27\lib\site-packages\django\template\loader.py", line 98, in render_to_string
    template = get_template(template_name, using=using)
  File "c:\python27\lib\site-packages\django\template\loader.py", line 35, in get_template
    return engine.get_template(template_name, dirs)
  File "c:\python27\lib\site-packages\django\template\backends\django.py", line 30, in get_template
    return Template(self.engine.get_template(template_name, dirs))
  File "c:\python27\lib\site-packages\django\template\engine.py", line 167, in get_template
    template, origin = self.find_template(template_name, dirs)
  File "c:\python27\lib\site-packages\django\template\engine.py", line 141, in find_template
    source, display_name = loader(name, dirs)
  File "c:\python27\lib\site-packages\django\template\loaders\base.py", line 13, in __call__
    return self.load_template(template_name, template_dirs)
  File "c:\python27\lib\site-packages\django\template\loaders\base.py", line 23, in load_template
    template = Template(source, origin, template_name, self.engine)
  File "c:\python27\lib\site-packages\django\template\base.py", line 190, in __init__
    self.nodelist = engine.compile_string(template_string, origin)
  File "c:\python27\lib\site-packages\django\template\engine.py", line 261, in compile_string
    return parser.parse()
  File "c:\python27\lib\site-packages\django\template\base.py", line 339, in parse
    self.invalid_block_tag(token, command, parse_until)
  File "c:\python27\lib\site-packages\django\template\base.py", line 395, in invalid_block_tag
    raise self.error(token, "Invalid block tag: '%s'" % command)
TemplateSyntaxError: Invalid block tag: 'static'
2017-04-04 04:35:12,755 [Thread-6:20312] [django.request:256] [base:handle_uncaught_exception] [ERROR]- Internal Server Error: /home/
Traceback (most recent call last):
  File "c:\python27\lib\site-packages\django\core\handlers\base.py", line 132, in get_response
    response = wrapped_callback(request, *callback_args, **callback_kwargs)
  File "F:\workspaces\Linux_learn2\VideoHome\views.py", line 18, in videohome
    return render(request, 'videohome.html', locals())
  File "c:\python27\lib\site-packages\django\shortcuts.py", line 67, in render
    template_name, context, request=request, using=using)
  File "c:\python27\lib\site-packages\django\template\loader.py", line 98, in render_to_string
    template = get_template(template_name, using=using)
  File "c:\python27\lib\site-packages\django\template\loader.py", line 35, in get_template
    return engine.get_template(template_name, dirs)
  File "c:\python27\lib\site-packages\django\template\backends\django.py", line 30, in get_template
    return Template(self.engine.get_template(template_name, dirs))
  File "c:\python27\lib\site-packages\django\template\engine.py", line 167, in get_template
    template, origin = self.find_template(template_name, dirs)
  File "c:\python27\lib\site-packages\django\template\engine.py", line 141, in find_template
    source, display_name = loader(name, dirs)
  File "c:\python27\lib\site-packages\django\template\loaders\base.py", line 13, in __call__
    return self.load_template(template_name, template_dirs)
  File "c:\python27\lib\site-packages\django\template\loaders\base.py", line 23, in load_template
    template = Template(source, origin, template_name, self.engine)
  File "c:\python27\lib\site-packages\django\template\base.py", line 190, in __init__
    self.nodelist = engine.compile_string(template_string, origin)
  File "c:\python27\lib\site-packages\django\template\engine.py", line 261, in compile_string
    return parser.parse()
  File "c:\python27\lib\site-packages\django\template\base.py", line 339, in parse
    self.invalid_block_tag(token, command, parse_until)
  File "c:\python27\lib\site-packages\django\template\base.py", line 395, in invalid_block_tag
    raise self.error(token, "Invalid block tag: '%s'" % command)
TemplateSyntaxError: Invalid block tag: 'static'
2017-04-04 04:35:15,835 [Thread-7:19500] [django.request:256] [base:handle_uncaught_exception] [ERROR]- Internal Server Error: /home/
Traceback (most recent call last):
  File "c:\python27\lib\site-packages\django\core\handlers\base.py", line 132, in get_response
    response = wrapped_callback(request, *callback_args, **callback_kwargs)
  File "F:\workspaces\Linux_learn2\VideoHome\views.py", line 18, in videohome
    return render(request, 'videohome.html', locals())
  File "c:\python27\lib\site-packages\django\shortcuts.py", line 67, in render
    template_name, context, request=request, using=using)
  File "c:\python27\lib\site-packages\django\template\loader.py", line 98, in render_to_string
    template = get_template(template_name, using=using)
  File "c:\python27\lib\site-packages\django\template\loader.py", line 35, in get_template
    return engine.get_template(template_name, dirs)
  File "c:\python27\lib\site-packages\django\template\backends\django.py", line 30, in get_template
    return Template(self.engine.get_template(template_name, dirs))
  File "c:\python27\lib\site-packages\django\template\engine.py", line 167, in get_template
    template, origin = self.find_template(template_name, dirs)
  File "c:\python27\lib\site-packages\django\template\engine.py", line 141, in find_template
    source, display_name = loader(name, dirs)
  File "c:\python27\lib\site-packages\django\template\loaders\base.py", line 13, in __call__
    return self.load_template(template_name, template_dirs)
  File "c:\python27\lib\site-packages\django\template\loaders\base.py", line 23, in load_template
    template = Template(source, origin, template_name, self.engine)
  File "c:\python27\lib\site-packages\django\template\base.py", line 190, in __init__
    self.nodelist = engine.compile_string(template_string, origin)
  File "c:\python27\lib\site-packages\django\template\engine.py", line 261, in compile_string
    return parser.parse()
  File "c:\python27\lib\site-packages\django\template\base.py", line 339, in parse
    self.invalid_block_tag(token, command, parse_until)
  File "c:\python27\lib\site-packages\django\template\base.py", line 395, in invalid_block_tag
    raise self.error(token, "Invalid block tag: '%s'" % command)
TemplateSyntaxError: Invalid block tag: 'static'
2017-04-04 04:36:54,976 [Thread-14:20204] [django.request:170] [base:get_response] [WARNING]- Not Found: /home/img/linux.png
2017-04-04 04:36:54,996 [Thread-15:11096] [django.request:170] [base:get_response] [WARNING]- Not Found: /home/img/Python.png
2017-04-04 04:36:55,025 [Thread-16:4972] [django.request:170] [base:get_response] [WARNING]- Not Found: /home/img/HTML.png
2017-04-04 04:36:55,063 [Thread-18:19464] [django.request:170] [base:get_response] [WARNING]- Not Found: /home/img/default (1).jpg
2017-04-04 04:36:55,065 [Thread-19:19764] [django.request:170] [base:get_response] [WARNING]- Not Found: /home/img/default.jpg
2017-04-04 04:36:55,066 [Thread-20:10780] [django.request:170] [base:get_response] [WARNING]- Not Found: /home/img/sports.jpg
2017-04-04 04:41:17,677 [Thread-21:14836] [django.request:256] [base:handle_uncaught_exception] [ERROR]- Internal Server Error: /home/
Traceback (most recent call last):
  File "c:\python27\lib\site-packages\django\core\handlers\base.py", line 132, in get_response
    response = wrapped_callback(request, *callback_args, **callback_kwargs)
  File "F:\workspaces\Linux_learn2\VideoHome\views.py", line 18, in videohome
    return render(request, 'videohome.html', locals())
  File "c:\python27\lib\site-packages\django\shortcuts.py", line 67, in render
    template_name, context, request=request, using=using)
  File "c:\python27\lib\site-packages\django\template\loader.py", line 98, in render_to_string
    template = get_template(template_name, using=using)
  File "c:\python27\lib\site-packages\django\template\loader.py", line 35, in get_template
    return engine.get_template(template_name, dirs)
  File "c:\python27\lib\site-packages\django\template\backends\django.py", line 30, in get_template
    return Template(self.engine.get_template(template_name, dirs))
  File "c:\python27\lib\site-packages\django\template\engine.py", line 167, in get_template
    template, origin = self.find_template(template_name, dirs)
  File "c:\python27\lib\site-packages\django\template\engine.py", line 141, in find_template
    source, display_name = loader(name, dirs)
  File "c:\python27\lib\site-packages\django\template\loaders\base.py", line 13, in __call__
    return self.load_template(template_name, template_dirs)
  File "c:\python27\lib\site-packages\django\template\loaders\base.py", line 23, in load_template
    template = Template(source, origin, template_name, self.engine)
  File "c:\python27\lib\site-packages\django\template\base.py", line 190, in __init__
    self.nodelist = engine.compile_string(template_string, origin)
  File "c:\python27\lib\site-packages\django\template\engine.py", line 261, in compile_string
    return parser.parse()
  File "c:\python27\lib\site-packages\django\template\base.py", line 339, in parse
    self.invalid_block_tag(token, command, parse_until)
  File "c:\python27\lib\site-packages\django\template\base.py", line 395, in invalid_block_tag
    raise self.error(token, "Invalid block tag: '%s'" % command)
TemplateSyntaxError: Invalid block tag: 'static"imgHome/linux.png"'
2017-04-04 04:41:35,032 [Thread-30:13012] [django.request:170] [base:get_response] [WARNING]- Not Found: /home/img/default (1).jpg
2017-04-04 04:41:35,036 [Thread-31:18348] [django.request:170] [base:get_response] [WARNING]- Not Found: /home/img/default.jpg
2017-04-04 04:41:35,051 [Thread-32:17948] [django.request:170] [base:get_response] [WARNING]- Not Found: /home/img/sports.jpg
2017-04-04 04:42:29,924 [Thread-35:18120] [django.request:170] [base:get_response] [WARNING]- Not Found: /home/img/default.jpg
2017-04-04 04:42:29,946 [Thread-36:14204] [django.request:170] [base:get_response] [WARNING]- Not Found: /home/img/sports.jpg
2017-04-04 04:42:30,045 [Thread-37:3012] [django.request:170] [base:get_response] [WARNING]- Not Found: /home/img/default.jpg
2017-04-04 04:42:30,052 [Thread-38:5052] [django.request:170] [base:get_response] [WARNING]- Not Found: /home/img/sports.jpg
2017-04-04 16:17:17,461 [Thread-20:14364] [django.request:170] [base:get_response] [WARNING]- Not Found: /favicon.ico
2017-04-04 16:17:22,555 [Thread-21:10900] [django.request:170] [base:get_response] [WARNING]- Not Found: /hoime
2017-04-04 16:18:02,611 [Thread-4:15192] [django.request:170] [base:get_response] [WARNING]- Not Found: /home/
2017-04-04 16:18:03,786 [Thread-5:14172] [django.request:170] [base:get_response] [WARNING]- Not Found: /
2017-04-04 16:18:08,302 [Thread-6:15144] [django.request:170] [base:get_response] [WARNING]- Not Found: /
2017-04-04 16:19:12,107 [Thread-9:11416] [django.request:170] [base:get_response] [WARNING]- Not Found: /cat
2017-04-05 18:06:20,553 [Thread-13:12984] [django.request:170] [base:get_response] [WARNING]- Not Found: /favicon.ico
2017-04-05 18:15:15,875 [Thread-66:13836] [django.request:256] [base:handle_uncaught_exception] [ERROR]- Internal Server Error: /
Traceback (most recent call last):
  File "c:\python27\lib\site-packages\django\core\handlers\base.py", line 132, in get_response
    response = wrapped_callback(request, *callback_args, **callback_kwargs)
  File "F:\workspaces\Linux_learn2\VideoHome\views.py", line 18, in videohome
    return render(request, 'videohome.html', locals())
  File "c:\python27\lib\site-packages\django\shortcuts.py", line 67, in render
    template_name, context, request=request, using=using)
  File "c:\python27\lib\site-packages\django\template\loader.py", line 99, in render_to_string
    return template.render(context, request)
  File "c:\python27\lib\site-packages\django\template\backends\django.py", line 74, in render
    return self.template.render(context)
  File "c:\python27\lib\site-packages\django\template\base.py", line 209, in render
    return self._render(context)
  File "c:\python27\lib\site-packages\django\template\base.py", line 201, in _render
    return self.nodelist.render(context)
  File "c:\python27\lib\site-packages\django\template\base.py", line 903, in render
    bit = self.render_node(node, context)
  File "c:\python27\lib\site-packages\django\template\debug.py", line 79, in render_node
    return node.render(context)
  File "c:\python27\lib\site-packages\django\template\defaulttags.py", line 507, in render
    six.reraise(*exc_info)
  File "c:\python27\lib\site-packages\django\template\defaulttags.py", line 493, in render
    url = reverse(view_name, args=args, kwargs=kwargs, current_app=current_app)
  File "c:\python27\lib\site-packages\django\core\urlresolvers.py", line 579, in reverse
    return force_text(iri_to_uri(resolver._reverse_with_prefix(view, prefix, *args, **kwargs)))
  File "c:\python27\lib\site-packages\django\core\urlresolvers.py", line 496, in _reverse_with_prefix
    (lookup_view_s, args, kwargs, len(patterns), patterns))
NoReverseMatch: Reverse for 'blog' with arguments '()' and keyword arguments '{}' not found. 0 pattern(s) tried: []
2017-04-05 18:15:26,062 [Thread-72:13944] [django.request:256] [base:handle_uncaught_exception] [ERROR]- Internal Server Error: /
Traceback (most recent call last):
  File "c:\python27\lib\site-packages\django\core\handlers\base.py", line 132, in get_response
    response = wrapped_callback(request, *callback_args, **callback_kwargs)
  File "F:\workspaces\Linux_learn2\VideoHome\views.py", line 18, in videohome
    return render(request, 'videohome.html', locals())
  File "c:\python27\lib\site-packages\django\shortcuts.py", line 67, in render
    template_name, context, request=request, using=using)
  File "c:\python27\lib\site-packages\django\template\loader.py", line 99, in render_to_string
    return template.render(context, request)
  File "c:\python27\lib\site-packages\django\template\backends\django.py", line 74, in render
    return self.template.render(context)
  File "c:\python27\lib\site-packages\django\template\base.py", line 209, in render
    return self._render(context)
  File "c:\python27\lib\site-packages\django\template\base.py", line 201, in _render
    return self.nodelist.render(context)
  File "c:\python27\lib\site-packages\django\template\base.py", line 903, in render
    bit = self.render_node(node, context)
  File "c:\python27\lib\site-packages\django\template\debug.py", line 79, in render_node
    return node.render(context)
  File "c:\python27\lib\site-packages\django\template\defaulttags.py", line 507, in render
    six.reraise(*exc_info)
  File "c:\python27\lib\site-packages\django\template\defaulttags.py", line 493, in render
    url = reverse(view_name, args=args, kwargs=kwargs, current_app=current_app)
  File "c:\python27\lib\site-packages\django\core\urlresolvers.py", line 579, in reverse
    return force_text(iri_to_uri(resolver._reverse_with_prefix(view, prefix, *args, **kwargs)))
  File "c:\python27\lib\site-packages\django\core\urlresolvers.py", line 496, in _reverse_with_prefix
    (lookup_view_s, args, kwargs, len(patterns), patterns))
NoReverseMatch: Reverse for 'blog' with arguments '()' and keyword arguments '{}' not found. 0 pattern(s) tried: []
2017-04-05 18:16:33,411 [Thread-76:13852] [django.request:256] [base:handle_uncaught_exception] [ERROR]- Internal Server Error: /
Traceback (most recent call last):
  File "c:\python27\lib\site-packages\django\core\handlers\base.py", line 132, in get_response
    response = wrapped_callback(request, *callback_args, **callback_kwargs)
  File "F:\workspaces\Linux_learn2\VideoHome\views.py", line 18, in videohome
    return render(request, 'videohome.html', locals())
  File "c:\python27\lib\site-packages\django\shortcuts.py", line 67, in render
    template_name, context, request=request, using=using)
  File "c:\python27\lib\site-packages\django\template\loader.py", line 99, in render_to_string
    return template.render(context, request)
  File "c:\python27\lib\site-packages\django\template\backends\django.py", line 74, in render
    return self.template.render(context)
  File "c:\python27\lib\site-packages\django\template\base.py", line 209, in render
    return self._render(context)
  File "c:\python27\lib\site-packages\django\template\base.py", line 201, in _render
    return self.nodelist.render(context)
  File "c:\python27\lib\site-packages\django\template\base.py", line 903, in render
    bit = self.render_node(node, context)
  File "c:\python27\lib\site-packages\django\template\debug.py", line 79, in render_node
    return node.render(context)
  File "c:\python27\lib\site-packages\django\template\defaulttags.py", line 507, in render
    six.reraise(*exc_info)
  File "c:\python27\lib\site-packages\django\template\defaulttags.py", line 493, in render
    url = reverse(view_name, args=args, kwargs=kwargs, current_app=current_app)
  File "c:\python27\lib\site-packages\django\core\urlresolvers.py", line 579, in reverse
    return force_text(iri_to_uri(resolver._reverse_with_prefix(view, prefix, *args, **kwargs)))
  File "c:\python27\lib\site-packages\django\core\urlresolvers.py", line 496, in _reverse_with_prefix
    (lookup_view_s, args, kwargs, len(patterns), patterns))
NoReverseMatch: Reverse for 'blog' with arguments '()' and keyword arguments '{}' not found. 0 pattern(s) tried: []
2017-04-05 18:16:35,308 [Thread-77:13848] [django.request:256] [base:handle_uncaught_exception] [ERROR]- Internal Server Error: /
Traceback (most recent call last):
  File "c:\python27\lib\site-packages\django\core\handlers\base.py", line 132, in get_response
    response = wrapped_callback(request, *callback_args, **callback_kwargs)
  File "F:\workspaces\Linux_learn2\VideoHome\views.py", line 18, in videohome
    return render(request, 'videohome.html', locals())
  File "c:\python27\lib\site-packages\django\shortcuts.py", line 67, in render
    template_name, context, request=request, using=using)
  File "c:\python27\lib\site-packages\django\template\loader.py", line 99, in render_to_string
    return template.render(context, request)
  File "c:\python27\lib\site-packages\django\template\backends\django.py", line 74, in render
    return self.template.render(context)
  File "c:\python27\lib\site-packages\django\template\base.py", line 209, in render
    return self._render(context)
  File "c:\python27\lib\site-packages\django\template\base.py", line 201, in _render
    return self.nodelist.render(context)
  File "c:\python27\lib\site-packages\django\template\base.py", line 903, in render
    bit = self.render_node(node, context)
  File "c:\python27\lib\site-packages\django\template\debug.py", line 79, in render_node
    return node.render(context)
  File "c:\python27\lib\site-packages\django\template\defaulttags.py", line 507, in render
    six.reraise(*exc_info)
  File "c:\python27\lib\site-packages\django\template\defaulttags.py", line 493, in render
    url = reverse(view_name, args=args, kwargs=kwargs, current_app=current_app)
  File "c:\python27\lib\site-packages\django\core\urlresolvers.py", line 579, in reverse
    return force_text(iri_to_uri(resolver._reverse_with_prefix(view, prefix, *args, **kwargs)))
  File "c:\python27\lib\site-packages\django\core\urlresolvers.py", line 496, in _reverse_with_prefix
    (lookup_view_s, args, kwargs, len(patterns), patterns))
NoReverseMatch: Reverse for 'blog' with arguments '()' and keyword arguments '{}' not found. 0 pattern(s) tried: []
2017-04-05 18:18:08,168 [Thread-101:13624] [django.request:256] [base:handle_uncaught_exception] [ERROR]- Internal Server Error: /
Traceback (most recent call last):
  File "c:\python27\lib\site-packages\django\core\handlers\base.py", line 132, in get_response
    response = wrapped_callback(request, *callback_args, **callback_kwargs)
  File "F:\workspaces\Linux_learn2\VideoHome\views.py", line 18, in videohome
    return render(request, 'videohome.html', locals())
  File "c:\python27\lib\site-packages\django\shortcuts.py", line 67, in render
    template_name, context, request=request, using=using)
  File "c:\python27\lib\site-packages\django\template\loader.py", line 99, in render_to_string
    return template.render(context, request)
  File "c:\python27\lib\site-packages\django\template\backends\django.py", line 74, in render
    return self.template.render(context)
  File "c:\python27\lib\site-packages\django\template\base.py", line 209, in render
    return self._render(context)
  File "c:\python27\lib\site-packages\django\template\base.py", line 201, in _render
    return self.nodelist.render(context)
  File "c:\python27\lib\site-packages\django\template\base.py", line 903, in render
    bit = self.render_node(node, context)
  File "c:\python27\lib\site-packages\django\template\debug.py", line 79, in render_node
    return node.render(context)
  File "c:\python27\lib\site-packages\django\template\defaulttags.py", line 507, in render
    six.reraise(*exc_info)
  File "c:\python27\lib\site-packages\django\template\defaulttags.py", line 493, in render
    url = reverse(view_name, args=args, kwargs=kwargs, current_app=current_app)
  File "c:\python27\lib\site-packages\django\core\urlresolvers.py", line 579, in reverse
    return force_text(iri_to_uri(resolver._reverse_with_prefix(view, prefix, *args, **kwargs)))
  File "c:\python27\lib\site-packages\django\core\urlresolvers.py", line 496, in _reverse_with_prefix
    (lookup_view_s, args, kwargs, len(patterns), patterns))
NoReverseMatch: Reverse for 'blog' with arguments '()' and keyword arguments '{}' not found. 0 pattern(s) tried: []
2017-04-05 18:35:21,933 [Thread-129:13624] [django.request:170] [base:get_response] [WARNING]- Not Found: /other/about
2017-04-05 18:58:13,994 [Thread-44:18720] [django.request:98] [csrf:_reject] [WARNING]- Forbidden (CSRF token missing or incorrect.): /bloglogin
2017-04-05 18:58:16,780 [Thread-45:16148] [django.request:98] [csrf:_reject] [WARNING]- Forbidden (CSRF token missing or incorrect.): /bloglogin
2017-04-05 18:59:12,618 [Thread-2:19592] [django.request:170] [base:get_response] [WARNING]- Not Found: /blogcategory/
2017-04-06 04:20:09,463 [Thread-3:29460] [django.request:170] [base:get_response] [WARNING]- Not Found: /favicon.ico
2017-04-06 04:31:44,039 [Thread-5:31340] [django.request:170] [base:get_response] [WARNING]- Not Found: /book/css/libs/bootstrap.min.css
2017-04-06 04:31:44,043 [Thread-6:31348] [django.request:170] [base:get_response] [WARNING]- Not Found: /book/javascript/libs/jquery-3.1.0.min.js
2017-04-06 04:31:44,049 [Thread-7:31352] [django.request:170] [base:get_response] [WARNING]- Not Found: /book/javascript/libs/bootstrap.min.js
2017-04-06 04:31:54,703 [Thread-11:31508] [django.request:170] [base:get_response] [WARNING]- Not Found: /book/css/libs/bootstrap.min.css
2017-04-06 04:31:54,706 [Thread-12:31512] [django.request:170] [base:get_response] [WARNING]- Not Found: /book/javascript/libs/jquery-3.1.0.min.js
2017-04-06 04:31:54,706 [Thread-13:31516] [django.request:170] [base:get_response] [WARNING]- Not Found: /book/javascript/libs/bootstrap.min.js
2017-04-06 05:16:39,523 [Thread-5:34652] [django.request:256] [base:handle_uncaught_exception] [ERROR]- Internal Server Error: /admin/BOOK/book_info/add/
Traceback (most recent call last):
  File "c:\python27\lib\site-packages\django\core\handlers\base.py", line 132, in get_response
    response = wrapped_callback(request, *callback_args, **callback_kwargs)
  File "c:\python27\lib\site-packages\django\contrib\admin\options.py", line 616, in wrapper
    return self.admin_site.admin_view(view)(*args, **kwargs)
  File "c:\python27\lib\site-packages\django\utils\decorators.py", line 110, in _wrapped_view
    response = view_func(request, *args, **kwargs)
  File "c:\python27\lib\site-packages\django\views\decorators\cache.py", line 57, in _wrapped_view_func
    response = view_func(request, *args, **kwargs)
  File "c:\python27\lib\site-packages\django\contrib\admin\sites.py", line 233, in inner
    return view(request, *args, **kwargs)
  File "c:\python27\lib\site-packages\django\contrib\admin\options.py", line 1516, in add_view
    return self.changeform_view(request, None, form_url, extra_context)
  File "c:\python27\lib\site-packages\django\utils\decorators.py", line 34, in _wrapper
    return bound_func(*args, **kwargs)
  File "c:\python27\lib\site-packages\django\utils\decorators.py", line 110, in _wrapped_view
    response = view_func(request, *args, **kwargs)
  File "c:\python27\lib\site-packages\django\utils\decorators.py", line 30, in bound_func
    return func.__get__(self, type(self))(*args2, **kwargs2)
  File "c:\python27\lib\site-packages\django\utils\decorators.py", line 145, in inner
    return func(*args, **kwargs)
  File "c:\python27\lib\site-packages\django\contrib\admin\options.py", line 1456, in changeform_view
    ModelForm = self.get_form(request, obj)
  File "c:\python27\lib\site-packages\django\contrib\admin\options.py", line 703, in get_form
    % (e, self.__class__.__name__))
FieldError: Unknown field(s) (book_date_publish) specified for book_info. Check fields/fieldsets/exclude attributes of class book_infoAdmin.
2017-04-06 05:17:11,407 [Thread-21:30956] [django.request:256] [base:handle_uncaught_exception] [ERROR]- Internal Server Error: /admin/BOOK/book_info/add/
Traceback (most recent call last):
  File "c:\python27\lib\site-packages\django\core\handlers\base.py", line 132, in get_response
    response = wrapped_callback(request, *callback_args, **callback_kwargs)
  File "c:\python27\lib\site-packages\django\contrib\admin\options.py", line 616, in wrapper
    return self.admin_site.admin_view(view)(*args, **kwargs)
  File "c:\python27\lib\site-packages\django\utils\decorators.py", line 110, in _wrapped_view
    response = view_func(request, *args, **kwargs)
  File "c:\python27\lib\site-packages\django\views\decorators\cache.py", line 57, in _wrapped_view_func
    response = view_func(request, *args, **kwargs)
  File "c:\python27\lib\site-packages\django\contrib\admin\sites.py", line 233, in inner
    return view(request, *args, **kwargs)
  File "c:\python27\lib\site-packages\django\contrib\admin\options.py", line 1516, in add_view
    return self.changeform_view(request, None, form_url, extra_context)
  File "c:\python27\lib\site-packages\django\utils\decorators.py", line 34, in _wrapper
    return bound_func(*args, **kwargs)
  File "c:\python27\lib\site-packages\django\utils\decorators.py", line 110, in _wrapped_view
    response = view_func(request, *args, **kwargs)
  File "c:\python27\lib\site-packages\django\utils\decorators.py", line 30, in bound_func
    return func.__get__(self, type(self))(*args2, **kwargs2)
  File "c:\python27\lib\site-packages\django\utils\decorators.py", line 145, in inner
    return func(*args, **kwargs)
  File "c:\python27\lib\site-packages\django\contrib\admin\options.py", line 1456, in changeform_view
    ModelForm = self.get_form(request, obj)
  File "c:\python27\lib\site-packages\django\contrib\admin\options.py", line 703, in get_form
    % (e, self.__class__.__name__))
FieldError: Unknown field(s) (book_date_publish) specified for book_info. Check fields/fieldsets/exclude attributes of class book_infoAdmin.
2017-04-06 05:26:14,848 [Thread-8:34428] [django.request:170] [base:get_response] [WARNING]- Not Found: /admin/book
2017-04-06 18:51:53,091 [Thread-13:11012] [django.request:170] [base:get_response] [WARNING]- Not Found: /favicon.ico
2017-04-07 04:55:36,486 [Thread-13:9376] [django.request:170] [base:get_response] [WARNING]- Not Found: /favicon.ico
2017-04-07 05:00:11,160 [Thread-94:6896] [django.request:170] [base:get_response] [WARNING]- Not Found: /admin/BOOK/chapter_article/add/undefineddefault/default.css/
2017-04-07 05:00:12,109 [Thread-98:6824] [django.request:170] [base:get_response] [WARNING]- Not Found: /admin/BOOK/chapter_article/add/undefineddefault/default.css/
2017-04-07 05:00:12,681 [Thread-102:5452] [django.request:170] [base:get_response] [WARNING]- Not Found: /admin/BOOK/chapter_article/add/undefineddefault/default.css/
2017-04-07 05:01:17,835 [Thread-106:2852] [django.request:170] [base:get_response] [WARNING]- Not Found: /admin/BOOK/chapter_article/add/undefineddefault/default.css/
2017-04-07 05:01:18,655 [Thread-110:7388] [django.request:170] [base:get_response] [WARNING]- Not Found: /admin/BOOK/chapter_article/add/undefineddefault/default.css/
2017-04-07 05:01:19,440 [Thread-114:7548] [django.request:170] [base:get_response] [WARNING]- Not Found: /admin/BOOK/chapter_article/add/undefineddefault/default.css/
2017-04-07 05:01:20,220 [Thread-118:916] [django.request:170] [base:get_response] [WARNING]- Not Found: /admin/BOOK/chapter_article/add/undefineddefault/default.css/
2017-04-07 06:51:42,588 [Thread-3:13704] [django.request:256] [base:handle_uncaught_exception] [ERROR]- Internal Server Error: /book/
Traceback (most recent call last):
  File "c:\python27\lib\site-packages\django\core\handlers\base.py", line 132, in get_response
    response = wrapped_callback(request, *callback_args, **callback_kwargs)
  File "F:\workspaces\Linux_learn2\BOOK\views.py", line 33, in get_book
    return render(request, 'BookHome.html', locals())
  File "c:\python27\lib\site-packages\django\shortcuts.py", line 67, in render
    template_name, context, request=request, using=using)
  File "c:\python27\lib\site-packages\django\template\loader.py", line 98, in render_to_string
    template = get_template(template_name, using=using)
  File "c:\python27\lib\site-packages\django\template\loader.py", line 35, in get_template
    return engine.get_template(template_name, dirs)
  File "c:\python27\lib\site-packages\django\template\backends\django.py", line 30, in get_template
    return Template(self.engine.get_template(template_name, dirs))
  File "c:\python27\lib\site-packages\django\template\engine.py", line 167, in get_template
    template, origin = self.find_template(template_name, dirs)
  File "c:\python27\lib\site-packages\django\template\engine.py", line 141, in find_template
    source, display_name = loader(name, dirs)
  File "c:\python27\lib\site-packages\django\template\loaders\base.py", line 13, in __call__
    return self.load_template(template_name, template_dirs)
  File "c:\python27\lib\site-packages\django\template\loaders\base.py", line 23, in load_template
    template = Template(source, origin, template_name, self.engine)
  File "c:\python27\lib\site-packages\django\template\base.py", line 190, in __init__
    self.nodelist = engine.compile_string(template_string, origin)
  File "c:\python27\lib\site-packages\django\template\engine.py", line 261, in compile_string
    return parser.parse()
  File "c:\python27\lib\site-packages\django\template\base.py", line 341, in parse
    compiled_result = compile_func(self, token)
  File "c:\python27\lib\site-packages\django\template\defaulttags.py", line 872, in do_for
    nodelist_loop = parser.parse(('empty', 'endfor',))
  File "c:\python27\lib\site-packages\django\template\base.py", line 339, in parse
    self.invalid_block_tag(token, command, parse_until)
  File "c:\python27\lib\site-packages\django\template\base.py", line 394, in invalid_block_tag
    (command, get_text_list(["'%s'" % p for p in parse_until])))
TemplateSyntaxError: Invalid block tag: 'enffor', expected 'empty' or 'endfor'
2017-04-07 06:51:54,464 [Thread-5:2656] [django.request:256] [base:handle_uncaught_exception] [ERROR]- Internal Server Error: /book/
Traceback (most recent call last):
  File "c:\python27\lib\site-packages\django\core\handlers\base.py", line 132, in get_response
    response = wrapped_callback(request, *callback_args, **callback_kwargs)
  File "F:\workspaces\Linux_learn2\BOOK\views.py", line 33, in get_book
    return render(request, 'BookHome.html', locals())
  File "c:\python27\lib\site-packages\django\shortcuts.py", line 67, in render
    template_name, context, request=request, using=using)
  File "c:\python27\lib\site-packages\django\template\loader.py", line 98, in render_to_string
    template = get_template(template_name, using=using)
  File "c:\python27\lib\site-packages\django\template\loader.py", line 35, in get_template
    return engine.get_template(template_name, dirs)
  File "c:\python27\lib\site-packages\django\template\backends\django.py", line 30, in get_template
    return Template(self.engine.get_template(template_name, dirs))
  File "c:\python27\lib\site-packages\django\template\engine.py", line 167, in get_template
    template, origin = self.find_template(template_name, dirs)
  File "c:\python27\lib\site-packages\django\template\engine.py", line 141, in find_template
    source, display_name = loader(name, dirs)
  File "c:\python27\lib\site-packages\django\template\loaders\base.py", line 13, in __call__
    return self.load_template(template_name, template_dirs)
  File "c:\python27\lib\site-packages\django\template\loaders\base.py", line 23, in load_template
    template = Template(source, origin, template_name, self.engine)
  File "c:\python27\lib\site-packages\django\template\base.py", line 190, in __init__
    self.nodelist = engine.compile_string(template_string, origin)
  File "c:\python27\lib\site-packages\django\template\engine.py", line 261, in compile_string
    return parser.parse()
  File "c:\python27\lib\site-packages\django\template\base.py", line 341, in parse
    compiled_result = compile_func(self, token)
  File "c:\python27\lib\site-packages\django\template\defaulttags.py", line 872, in do_for
    nodelist_loop = parser.parse(('empty', 'endfor',))
  File "c:\python27\lib\site-packages\django\template\base.py", line 339, in parse
    self.invalid_block_tag(token, command, parse_until)
  File "c:\python27\lib\site-packages\django\template\base.py", line 394, in invalid_block_tag
    (command, get_text_list(["'%s'" % p for p in parse_until])))
TemplateSyntaxError: Invalid block tag: 'enfor', expected 'empty' or 'endfor'
2017-04-07 06:52:59,046 [Thread-11:9668] [django.request:170] [base:get_response] [WARNING]- Not Found: /other/about
2017-04-07 22:34:39,539 [Thread-9:8272] [django.request:170] [base:get_response] [WARNING]- Not Found: /favicon.ico
2017-04-07 22:42:58,505 [Thread-47:6960] [django.request:170] [base:get_response] [WARNING]- Not Found: /biook
2017-04-08 00:23:23,903 [Thread-13:6508] [django.request:170] [base:get_response] [WARNING]- Not Found: /favicon.ico
2017-04-08 01:40:44,430 [Thread-2:9492] [django.request:256] [base:handle_uncaught_exception] [ERROR]- Internal Server Error: /book/
Traceback (most recent call last):
  File "c:\python27\lib\site-packages\django\core\handlers\base.py", line 119, in get_response
    resolver_match = resolver.resolve(request.path_info)
  File "c:\python27\lib\site-packages\django\core\urlresolvers.py", line 366, in resolve
    for pattern in self.url_patterns:
  File "c:\python27\lib\site-packages\django\core\urlresolvers.py", line 402, in url_patterns
    patterns = getattr(self.urlconf_module, "urlpatterns", self.urlconf_module)
  File "c:\python27\lib\site-packages\django\core\urlresolvers.py", line 396, in urlconf_module
    self._urlconf_module = import_module(self.urlconf_name)
  File "c:\python27\Lib\importlib\__init__.py", line 37, in import_module
    __import__(name)
  File "F:\workspaces\Linux_learn2\Linux_learn2\urls.py", line 29, in <module>
    url(r'^book', include('BOOK.urls')),
  File "c:\python27\lib\site-packages\django\conf\urls\__init__.py", line 33, in include
    urlconf_module = import_module(urlconf_module)
  File "c:\python27\Lib\importlib\__init__.py", line 37, in import_module
    __import__(name)
  File "F:\workspaces\Linux_learn2\BOOK\urls.py", line 3, in <module>
    from BOOK.views import *
  File "F:\workspaces\Linux_learn2\BOOK\views.py", line 34
    except (InvalidPage, EmptyPage, PageNotAnInteger):
         ^
SyntaxError: invalid syntax
2017-04-08 01:41:15,464 [Thread-5:3320] [django.request:256] [base:handle_uncaught_exception] [ERROR]- Internal Server Error: /book/
Traceback (most recent call last):
  File "c:\python27\lib\site-packages\django\core\handlers\base.py", line 119, in get_response
    resolver_match = resolver.resolve(request.path_info)
  File "c:\python27\lib\site-packages\django\core\urlresolvers.py", line 366, in resolve
    for pattern in self.url_patterns:
  File "c:\python27\lib\site-packages\django\core\urlresolvers.py", line 402, in url_patterns
    patterns = getattr(self.urlconf_module, "urlpatterns", self.urlconf_module)
  File "c:\python27\lib\site-packages\django\core\urlresolvers.py", line 396, in urlconf_module
    self._urlconf_module = import_module(self.urlconf_name)
  File "c:\python27\Lib\importlib\__init__.py", line 37, in import_module
    __import__(name)
  File "F:\workspaces\Linux_learn2\Linux_learn2\urls.py", line 29, in <module>
    url(r'^book', include('BOOK.urls')),
  File "c:\python27\lib\site-packages\django\conf\urls\__init__.py", line 33, in include
    urlconf_module = import_module(urlconf_module)
  File "c:\python27\Lib\importlib\__init__.py", line 37, in import_module
    __import__(name)
  File "F:\workspaces\Linux_learn2\BOOK\urls.py", line 3, in <module>
    from BOOK.views import *
  File "F:\workspaces\Linux_learn2\BOOK\views.py", line 34
    except (InvalidPage, EmptyPage, PageNotAnInteger):
         ^
SyntaxError: invalid syntax
2017-04-08 01:41:18,223 [Thread-6:5668] [django.request:256] [base:handle_uncaught_exception] [ERROR]- Internal Server Error: /book/
Traceback (most recent call last):
  File "c:\python27\lib\site-packages\django\core\handlers\base.py", line 119, in get_response
    resolver_match = resolver.resolve(request.path_info)
  File "c:\python27\lib\site-packages\django\core\urlresolvers.py", line 366, in resolve
    for pattern in self.url_patterns:
  File "c:\python27\lib\site-packages\django\core\urlresolvers.py", line 402, in url_patterns
    patterns = getattr(self.urlconf_module, "urlpatterns", self.urlconf_module)
  File "c:\python27\lib\site-packages\django\core\urlresolvers.py", line 396, in urlconf_module
    self._urlconf_module = import_module(self.urlconf_name)
  File "c:\python27\Lib\importlib\__init__.py", line 37, in import_module
    __import__(name)
  File "F:\workspaces\Linux_learn2\Linux_learn2\urls.py", line 29, in <module>
    url(r'^book', include('BOOK.urls')),
  File "c:\python27\lib\site-packages\django\conf\urls\__init__.py", line 33, in include
    urlconf_module = import_module(urlconf_module)
  File "c:\python27\Lib\importlib\__init__.py", line 37, in import_module
    __import__(name)
  File "F:\workspaces\Linux_learn2\BOOK\urls.py", line 3, in <module>
    from BOOK.views import *
  File "F:\workspaces\Linux_learn2\BOOK\views.py", line 34
    except (InvalidPage, EmptyPage, PageNotAnInteger):
         ^
SyntaxError: invalid syntax
2017-04-08 01:41:19,081 [Thread-7:2056] [django.request:256] [base:handle_uncaught_exception] [ERROR]- Internal Server Error: /book/
Traceback (most recent call last):
  File "c:\python27\lib\site-packages\django\core\handlers\base.py", line 119, in get_response
    resolver_match = resolver.resolve(request.path_info)
  File "c:\python27\lib\site-packages\django\core\urlresolvers.py", line 366, in resolve
    for pattern in self.url_patterns:
  File "c:\python27\lib\site-packages\django\core\urlresolvers.py", line 402, in url_patterns
    patterns = getattr(self.urlconf_module, "urlpatterns", self.urlconf_module)
  File "c:\python27\lib\site-packages\django\core\urlresolvers.py", line 396, in urlconf_module
    self._urlconf_module = import_module(self.urlconf_name)
  File "c:\python27\Lib\importlib\__init__.py", line 37, in import_module
    __import__(name)
  File "F:\workspaces\Linux_learn2\Linux_learn2\urls.py", line 29, in <module>
    url(r'^book', include('BOOK.urls')),
  File "c:\python27\lib\site-packages\django\conf\urls\__init__.py", line 33, in include
    urlconf_module = import_module(urlconf_module)
  File "c:\python27\Lib\importlib\__init__.py", line 37, in import_module
    __import__(name)
  File "F:\workspaces\Linux_learn2\BOOK\urls.py", line 3, in <module>
    from BOOK.views import *
  File "F:\workspaces\Linux_learn2\BOOK\views.py", line 34
    except (InvalidPage, EmptyPage, PageNotAnInteger):
         ^
SyntaxError: invalid syntax
2017-04-08 01:41:19,937 [Thread-8:5624] [django.request:256] [base:handle_uncaught_exception] [ERROR]- Internal Server Error: /book/
Traceback (most recent call last):
  File "c:\python27\lib\site-packages\django\core\handlers\base.py", line 119, in get_response
    resolver_match = resolver.resolve(request.path_info)
  File "c:\python27\lib\site-packages\django\core\urlresolvers.py", line 366, in resolve
    for pattern in self.url_patterns:
  File "c:\python27\lib\site-packages\django\core\urlresolvers.py", line 402, in url_patterns
    patterns = getattr(self.urlconf_module, "urlpatterns", self.urlconf_module)
  File "c:\python27\lib\site-packages\django\core\urlresolvers.py", line 396, in urlconf_module
    self._urlconf_module = import_module(self.urlconf_name)
  File "c:\python27\Lib\importlib\__init__.py", line 37, in import_module
    __import__(name)
  File "F:\workspaces\Linux_learn2\Linux_learn2\urls.py", line 29, in <module>
    url(r'^book', include('BOOK.urls')),
  File "c:\python27\lib\site-packages\django\conf\urls\__init__.py", line 33, in include
    urlconf_module = import_module(urlconf_module)
  File "c:\python27\Lib\importlib\__init__.py", line 37, in import_module
    __import__(name)
  File "F:\workspaces\Linux_learn2\BOOK\urls.py", line 3, in <module>
    from BOOK.views import *
  File "F:\workspaces\Linux_learn2\BOOK\views.py", line 34
    except (InvalidPage, EmptyPage, PageNotAnInteger):
         ^
SyntaxError: invalid syntax
2017-04-08 01:44:04,611 [Thread-2:7084] [django.request:256] [base:handle_uncaught_exception] [ERROR]- Internal Server Error: /book/
Traceback (most recent call last):
  File "c:\python27\lib\site-packages\django\core\handlers\base.py", line 119, in get_response
    resolver_match = resolver.resolve(request.path_info)
  File "c:\python27\lib\site-packages\django\core\urlresolvers.py", line 366, in resolve
    for pattern in self.url_patterns:
  File "c:\python27\lib\site-packages\django\core\urlresolvers.py", line 402, in url_patterns
    patterns = getattr(self.urlconf_module, "urlpatterns", self.urlconf_module)
  File "c:\python27\lib\site-packages\django\core\urlresolvers.py", line 396, in urlconf_module
    self._urlconf_module = import_module(self.urlconf_name)
  File "c:\python27\Lib\importlib\__init__.py", line 37, in import_module
    __import__(name)
  File "F:\workspaces\Linux_learn2\Linux_learn2\urls.py", line 29, in <module>
    url(r'^book', include('BOOK.urls')),
  File "c:\python27\lib\site-packages\django\conf\urls\__init__.py", line 33, in include
    urlconf_module = import_module(urlconf_module)
  File "c:\python27\Lib\importlib\__init__.py", line 37, in import_module
    __import__(name)
  File "F:\workspaces\Linux_learn2\BOOK\urls.py", line 3, in <module>
    from BOOK.views import *
  File "F:\workspaces\Linux_learn2\BOOK\views.py", line 32
    except (InvalidPage, EmptyPage, PageNotAnInteger):
         ^
SyntaxError: invalid syntax
2017-04-08 01:44:07,923 [Thread-3:9284] [django.request:256] [base:handle_uncaught_exception] [ERROR]- Internal Server Error: /book/
Traceback (most recent call last):
  File "c:\python27\lib\site-packages\django\core\handlers\base.py", line 119, in get_response
    resolver_match = resolver.resolve(request.path_info)
  File "c:\python27\lib\site-packages\django\core\urlresolvers.py", line 366, in resolve
    for pattern in self.url_patterns:
  File "c:\python27\lib\site-packages\django\core\urlresolvers.py", line 402, in url_patterns
    patterns = getattr(self.urlconf_module, "urlpatterns", self.urlconf_module)
  File "c:\python27\lib\site-packages\django\core\urlresolvers.py", line 396, in urlconf_module
    self._urlconf_module = import_module(self.urlconf_name)
  File "c:\python27\Lib\importlib\__init__.py", line 37, in import_module
    __import__(name)
  File "F:\workspaces\Linux_learn2\Linux_learn2\urls.py", line 29, in <module>
    url(r'^book', include('BOOK.urls')),
  File "c:\python27\lib\site-packages\django\conf\urls\__init__.py", line 33, in include
    urlconf_module = import_module(urlconf_module)
  File "c:\python27\Lib\importlib\__init__.py", line 37, in import_module
    __import__(name)
  File "F:\workspaces\Linux_learn2\BOOK\urls.py", line 3, in <module>
    from BOOK.views import *
  File "F:\workspaces\Linux_learn2\BOOK\views.py", line 32
    except (InvalidPage, EmptyPage, PageNotAnInteger):
         ^
SyntaxError: invalid syntax
2017-04-08 01:44:23,348 [Thread-5:9788] [django.request:256] [base:handle_uncaught_exception] [ERROR]- Internal Server Error: /book/
Traceback (most recent call last):
  File "c:\python27\lib\site-packages\django\core\handlers\base.py", line 119, in get_response
    resolver_match = resolver.resolve(request.path_info)
  File "c:\python27\lib\site-packages\django\core\urlresolvers.py", line 366, in resolve
    for pattern in self.url_patterns:
  File "c:\python27\lib\site-packages\django\core\urlresolvers.py", line 402, in url_patterns
    patterns = getattr(self.urlconf_module, "urlpatterns", self.urlconf_module)
  File "c:\python27\lib\site-packages\django\core\urlresolvers.py", line 396, in urlconf_module
    self._urlconf_module = import_module(self.urlconf_name)
  File "c:\python27\Lib\importlib\__init__.py", line 37, in import_module
    __import__(name)
  File "F:\workspaces\Linux_learn2\Linux_learn2\urls.py", line 29, in <module>
    url(r'^book', include('BOOK.urls')),
  File "c:\python27\lib\site-packages\django\conf\urls\__init__.py", line 33, in include
    urlconf_module = import_module(urlconf_module)
  File "c:\python27\Lib\importlib\__init__.py", line 37, in import_module
    __import__(name)
  File "F:\workspaces\Linux_learn2\BOOK\urls.py", line 3, in <module>
    from BOOK.views import *
  File "F:\workspaces\Linux_learn2\BOOK\views.py", line 32
    except (InvalidPage, EmptyPage, PageNotAnInteger):
         ^
SyntaxError: invalid syntax
2017-04-08 04:51:21,938 [Thread-64:12028] [django.request:170] [base:get_response] [WARNING]- Not Found: /blog】、
2017-04-08 04:52:12,936 [Thread-90:13164] [django.request:170] [base:get_response] [WARNING]- Not Found: /blogarticle/portal.php
2017-04-08 05:05:03,595 [Thread-13:11884] [django.request:256] [base:handle_uncaught_exception] [ERROR]- Internal Server Error: /book/
Traceback (most recent call last):
  File "c:\python27\lib\site-packages\django\core\handlers\base.py", line 132, in get_response
    response = wrapped_callback(request, *callback_args, **callback_kwargs)
  File "F:\workspaces\Linux_learn2\BOOK\views.py", line 37, in get_book
    return render(request, 'BookHome.html', locals())
  File "c:\python27\lib\site-packages\django\shortcuts.py", line 67, in render
    template_name, context, request=request, using=using)
  File "c:\python27\lib\site-packages\django\template\loader.py", line 99, in render_to_string
    return template.render(context, request)
  File "c:\python27\lib\site-packages\django\template\backends\django.py", line 74, in render
    return self.template.render(context)
  File "c:\python27\lib\site-packages\django\template\base.py", line 209, in render
    return self._render(context)
  File "c:\python27\lib\site-packages\django\template\base.py", line 201, in _render
    return self.nodelist.render(context)
  File "c:\python27\lib\site-packages\django\template\base.py", line 903, in render
    bit = self.render_node(node, context)
  File "c:\python27\lib\site-packages\django\template\debug.py", line 79, in render_node
    return node.render(context)
  File "c:\python27\lib\site-packages\django\template\defaulttags.py", line 217, in render
    nodelist.append(node.render(context))
  File "c:\python27\lib\site-packages\django\template\defaulttags.py", line 507, in render
    six.reraise(*exc_info)
  File "c:\python27\lib\site-packages\django\template\defaulttags.py", line 493, in render
    url = reverse(view_name, args=args, kwargs=kwargs, current_app=current_app)
  File "c:\python27\lib\site-packages\django\core\urlresolvers.py", line 579, in reverse
    return force_text(iri_to_uri(resolver._reverse_with_prefix(view, prefix, *args, **kwargs)))
  File "c:\python27\lib\site-packages\django\core\urlresolvers.py", line 496, in _reverse_with_prefix
    (lookup_view_s, args, kwargs, len(patterns), patterns))
NoReverseMatch: Reverse for 'book' with arguments '()' and keyword arguments '{}' not found. 0 pattern(s) tried: []
2017-04-08 05:05:05,868 [Thread-14:13108] [django.request:256] [base:handle_uncaught_exception] [ERROR]- Internal Server Error: /book/
Traceback (most recent call last):
  File "c:\python27\lib\site-packages\django\core\handlers\base.py", line 132, in get_response
    response = wrapped_callback(request, *callback_args, **callback_kwargs)
  File "F:\workspaces\Linux_learn2\BOOK\views.py", line 37, in get_book
    return render(request, 'BookHome.html', locals())
  File "c:\python27\lib\site-packages\django\shortcuts.py", line 67, in render
    template_name, context, request=request, using=using)
  File "c:\python27\lib\site-packages\django\template\loader.py", line 99, in render_to_string
    return template.render(context, request)
  File "c:\python27\lib\site-packages\django\template\backends\django.py", line 74, in render
    return self.template.render(context)
  File "c:\python27\lib\site-packages\django\template\base.py", line 209, in render
    return self._render(context)
  File "c:\python27\lib\site-packages\django\template\base.py", line 201, in _render
    return self.nodelist.render(context)
  File "c:\python27\lib\site-packages\django\template\base.py", line 903, in render
    bit = self.render_node(node, context)
  File "c:\python27\lib\site-packages\django\template\debug.py", line 79, in render_node
    return node.render(context)
  File "c:\python27\lib\site-packages\django\template\defaulttags.py", line 217, in render
    nodelist.append(node.render(context))
  File "c:\python27\lib\site-packages\django\template\defaulttags.py", line 507, in render
    six.reraise(*exc_info)
  File "c:\python27\lib\site-packages\django\template\defaulttags.py", line 493, in render
    url = reverse(view_name, args=args, kwargs=kwargs, current_app=current_app)
  File "c:\python27\lib\site-packages\django\core\urlresolvers.py", line 579, in reverse
    return force_text(iri_to_uri(resolver._reverse_with_prefix(view, prefix, *args, **kwargs)))
  File "c:\python27\lib\site-packages\django\core\urlresolvers.py", line 496, in _reverse_with_prefix
    (lookup_view_s, args, kwargs, len(patterns), patterns))
NoReverseMatch: Reverse for 'book' with arguments '()' and keyword arguments '{}' not found. 0 pattern(s) tried: []
2017-04-08 05:07:10,674 [Thread-29:11728] [django.request:170] [base:get_response] [WARNING]- Not Found: /other/about
2017-04-08 05:07:27,983 [Thread-34:11460] [django.request:170] [base:get_response] [WARNING]- Not Found: /other/about
2017-04-08 06:07:31,648 [Thread-7:13924] [django.request:256] [base:handle_uncaught_exception] [ERROR]- Internal Server Error: /book/
Traceback (most recent call last):
  File "c:\python27\lib\site-packages\django\core\handlers\base.py", line 132, in get_response
    response = wrapped_callback(request, *callback_args, **callback_kwargs)
  File "F:\workspaces\Linux_learn2\BOOK\views.py", line 42, in get_book
    return render(request, 'BookHome.html', locals())
  File "c:\python27\lib\site-packages\django\shortcuts.py", line 67, in render
    template_name, context, request=request, using=using)
  File "c:\python27\lib\site-packages\django\template\loader.py", line 99, in render_to_string
    return template.render(context, request)
  File "c:\python27\lib\site-packages\django\template\backends\django.py", line 74, in render
    return self.template.render(context)
  File "c:\python27\lib\site-packages\django\template\base.py", line 209, in render
    return self._render(context)
  File "c:\python27\lib\site-packages\django\template\base.py", line 201, in _render
    return self.nodelist.render(context)
  File "c:\python27\lib\site-packages\django\template\base.py", line 903, in render
    bit = self.render_node(node, context)
  File "c:\python27\lib\site-packages\django\template\debug.py", line 79, in render_node
    return node.render(context)
  File "c:\python27\lib\site-packages\django\template\defaulttags.py", line 161, in render
    values = list(values)
TypeError: 'book_info' object is not iterable
2017-04-08 06:07:45,250 [Thread-9:10756] [django.request:256] [base:handle_uncaught_exception] [ERROR]- Internal Server Error: /book/
Traceback (most recent call last):
  File "c:\python27\lib\site-packages\django\core\handlers\base.py", line 132, in get_response
    response = wrapped_callback(request, *callback_args, **callback_kwargs)
  File "F:\workspaces\Linux_learn2\BOOK\views.py", line 42, in get_book
    return render(request, 'BookHome.html', locals())
  File "c:\python27\lib\site-packages\django\shortcuts.py", line 67, in render
    template_name, context, request=request, using=using)
  File "c:\python27\lib\site-packages\django\template\loader.py", line 99, in render_to_string
    return template.render(context, request)
  File "c:\python27\lib\site-packages\django\template\backends\django.py", line 74, in render
    return self.template.render(context)
  File "c:\python27\lib\site-packages\django\template\base.py", line 209, in render
    return self._render(context)
  File "c:\python27\lib\site-packages\django\template\base.py", line 201, in _render
    return self.nodelist.render(context)
  File "c:\python27\lib\site-packages\django\template\base.py", line 903, in render
    bit = self.render_node(node, context)
  File "c:\python27\lib\site-packages\django\template\debug.py", line 79, in render_node
    return node.render(context)
  File "c:\python27\lib\site-packages\django\template\defaulttags.py", line 161, in render
    values = list(values)
TypeError: 'book_info' object is not iterable
2017-04-08 06:07:47,918 [Thread-10:11948] [django.request:256] [base:handle_uncaught_exception] [ERROR]- Internal Server Error: /book/
Traceback (most recent call last):
  File "c:\python27\lib\site-packages\django\core\handlers\base.py", line 132, in get_response
    response = wrapped_callback(request, *callback_args, **callback_kwargs)
  File "F:\workspaces\Linux_learn2\BOOK\views.py", line 42, in get_book
    return render(request, 'BookHome.html', locals())
  File "c:\python27\lib\site-packages\django\shortcuts.py", line 67, in render
    template_name, context, request=request, using=using)
  File "c:\python27\lib\site-packages\django\template\loader.py", line 99, in render_to_string
    return template.render(context, request)
  File "c:\python27\lib\site-packages\django\template\backends\django.py", line 74, in render
    return self.template.render(context)
  File "c:\python27\lib\site-packages\django\template\base.py", line 209, in render
    return self._render(context)
  File "c:\python27\lib\site-packages\django\template\base.py", line 201, in _render
    return self.nodelist.render(context)
  File "c:\python27\lib\site-packages\django\template\base.py", line 903, in render
    bit = self.render_node(node, context)
  File "c:\python27\lib\site-packages\django\template\debug.py", line 79, in render_node
    return node.render(context)
  File "c:\python27\lib\site-packages\django\template\defaulttags.py", line 161, in render
    values = list(values)
TypeError: 'book_info' object is not iterable
2017-04-08 06:09:42,223 [Thread-4:13164] [django.request:256] [base:handle_uncaught_exception] [ERROR]- Internal Server Error: /book/
Traceback (most recent call last):
  File "c:\python27\lib\site-packages\django\core\handlers\base.py", line 132, in get_response
    response = wrapped_callback(request, *callback_args, **callback_kwargs)
  File "F:\workspaces\Linux_learn2\BOOK\views.py", line 42, in get_book
    return render(request, 'BookHome.html', locals())
  File "c:\python27\lib\site-packages\django\shortcuts.py", line 67, in render
    template_name, context, request=request, using=using)
  File "c:\python27\lib\site-packages\django\template\loader.py", line 99, in render_to_string
    return template.render(context, request)
  File "c:\python27\lib\site-packages\django\template\backends\django.py", line 74, in render
    return self.template.render(context)
  File "c:\python27\lib\site-packages\django\template\base.py", line 209, in render
    return self._render(context)
  File "c:\python27\lib\site-packages\django\template\base.py", line 201, in _render
    return self.nodelist.render(context)
  File "c:\python27\lib\site-packages\django\template\base.py", line 903, in render
    bit = self.render_node(node, context)
  File "c:\python27\lib\site-packages\django\template\debug.py", line 79, in render_node
    return node.render(context)
  File "c:\python27\lib\site-packages\django\template\defaulttags.py", line 161, in render
    values = list(values)
TypeError: 'book_info' object is not iterable
2017-04-08 06:09:45,687 [Thread-5:16116] [django.request:256] [base:handle_uncaught_exception] [ERROR]- Internal Server Error: /book/
Traceback (most recent call last):
  File "c:\python27\lib\site-packages\django\core\handlers\base.py", line 132, in get_response
    response = wrapped_callback(request, *callback_args, **callback_kwargs)
  File "F:\workspaces\Linux_learn2\BOOK\views.py", line 42, in get_book
    return render(request, 'BookHome.html', locals())
  File "c:\python27\lib\site-packages\django\shortcuts.py", line 67, in render
    template_name, context, request=request, using=using)
  File "c:\python27\lib\site-packages\django\template\loader.py", line 99, in render_to_string
    return template.render(context, request)
  File "c:\python27\lib\site-packages\django\template\backends\django.py", line 74, in render
    return self.template.render(context)
  File "c:\python27\lib\site-packages\django\template\base.py", line 209, in render
    return self._render(context)
  File "c:\python27\lib\site-packages\django\template\base.py", line 201, in _render
    return self.nodelist.render(context)
  File "c:\python27\lib\site-packages\django\template\base.py", line 903, in render
    bit = self.render_node(node, context)
  File "c:\python27\lib\site-packages\django\template\debug.py", line 79, in render_node
    return node.render(context)
  File "c:\python27\lib\site-packages\django\template\defaulttags.py", line 161, in render
    values = list(values)
TypeError: 'book_info' object is not iterable
2017-04-08 06:35:05,665 [Thread-20:16300] [django.request:170] [base:get_response] [WARNING]- Not Found: //chapter
2017-04-08 06:35:05,915 [Thread-21:1936] [django.request:170] [base:get_response] [WARNING]- Not Found: /favicon.ico
2017-04-08 06:35:40,236 [Thread-24:16564] [django.request:170] [base:get_response] [WARNING]- Not Found: //chapter
2017-04-08 06:35:50,411 [Thread-25:16800] [django.request:170] [base:get_response] [WARNING]- Not Found: //chapter
2017-04-08 06:35:53,459 [Thread-33:15740] [django.request:170] [base:get_response] [WARNING]- Not Found: //chapter
2017-04-08 06:35:58,517 [Thread-32:16304] [django.request:170] [base:get_response] [WARNING]- Not Found: /book/book/chapter
2017-04-08 06:36:18,688 [Thread-41:16000] [django.request:170] [base:get_response] [WARNING]- Not Found: /book/chapter
2017-04-08 06:36:25,427 [Thread-43:15064] [django.request:170] [base:get_response] [WARNING]- Not Found: /book/chapter
2017-04-08 06:37:41,849 [Thread-2:12248] [django.request:170] [base:get_response] [WARNING]- Not Found: /book/chapter
2017-04-08 06:37:42,749 [Thread-3:11656] [django.request:170] [base:get_response] [WARNING]- Not Found: /book/chapter
2017-04-08 06:37:45,528 [Thread-4:16964] [django.request:170] [base:get_response] [WARNING]- Not Found: /book/chapter
2017-04-08 06:39:13,069 [Thread-2:15184] [django.request:170] [base:get_response] [WARNING]- Not Found: /book/chapter
2017-04-08 06:39:42,882 [Thread-4:16388] [django.request:170] [base:get_response] [WARNING]- Not Found: /book/chapter
2017-04-08 06:39:54,421 [Thread-7:13860] [django.request:170] [base:get_response] [WARNING]- Not Found: /book/chapter
2017-04-08 06:40:56,388 [Thread-4:13868] [django.request:170] [base:get_response] [WARNING]- Not Found: /book/chapter
2017-04-08 06:42:28,553 [Thread-4:17280] [django.request:170] [base:get_response] [WARNING]- Not Found: /book/chapter
2017-04-08 06:42:56,323 [Thread-5:17136] [django.request:170] [base:get_response] [WARNING]- Not Found: /book/chapter
2017-04-08 06:45:46,319 [Thread-4:15096] [django.request:170] [base:get_response] [WARNING]- Not Found: /book/chapter
2017-04-08 06:46:22,107 [Thread-7:16928] [django.request:170] [base:get_response] [WARNING]- Not Found: /book/chapter
2017-04-08 06:48:18,497 [Thread-4:15548] [django.request:170] [base:get_response] [WARNING]- Not Found: /book/chapter
2017-04-08 06:49:28,283 [Thread-3:18152] [django.request:170] [base:get_response] [WARNING]- Not Found: /book/chapter
2017-04-08 06:49:35,973 [Thread-4:18168] [django.request:170] [base:get_response] [WARNING]- Not Found: /book/chapter
2017-04-08 06:50:19,950 [Thread-6:17716] [django.request:170] [base:get_response] [WARNING]- Not Found: /book/chapter
2017-04-08 06:51:38,579 [Thread-9:16636] [django.request:170] [base:get_response] [WARNING]- Not Found: /book1
2017-04-08 06:52:19,494 [Thread-2:16160] [django.request:170] [base:get_response] [WARNING]- Not Found: /book/chapter
2017-04-08 06:52:23,615 [Thread-5:17536] [django.request:170] [base:get_response] [WARNING]- Not Found: /book/chapter
2017-04-08 06:52:35,190 [Thread-7:17020] [django.request:170] [base:get_response] [WARNING]- Not Found: /book/chapter
2017-04-08 06:53:07,650 [Thread-11:15872] [django.request:170] [base:get_response] [WARNING]- Not Found: /book/chapter
2017-04-08 06:54:30,450 [Thread-2:17904] [django.request:170] [base:get_response] [WARNING]- Not Found: /book/chapter
2017-04-08 06:54:31,249 [Thread-3:15748] [django.request:170] [base:get_response] [WARNING]- Not Found: /book/chapter
2017-04-08 06:54:32,977 [Thread-4:18296] [django.request:170] [base:get_response] [WARNING]- Not Found: /book/chapter
2017-04-08 06:54:48,431 [Thread-6:17428] [django.request:170] [base:get_response] [WARNING]- Not Found: /book/chapter
2017-04-08 06:57:25,904 [Thread-3:18348] [django.request:170] [base:get_response] [WARNING]- Not Found: /book/chapter
2017-04-08 06:57:51,744 [Thread-2:17756] [django.request:170] [base:get_response] [WARNING]- Not Found: /book/chapter
2017-04-08 06:57:54,119 [Thread-3:16320] [django.request:170] [base:get_response] [WARNING]- Not Found: /book/chapter
2017-04-08 06:58:20,095 [Thread-2:17188] [django.request:170] [base:get_response] [WARNING]- Not Found: /book/chapter
2017-04-08 06:58:22,134 [Thread-3:12456] [django.request:170] [base:get_response] [WARNING]- Not Found: /book/chapter
2017-04-08 07:02:41,470 [Thread-4:3244] [django.request:170] [base:get_response] [WARNING]- Not Found: /book/chapter
2017-04-09 05:23:15,921 [Thread-13:5452] [django.request:170] [base:get_response] [WARNING]- Not Found: /favicon.ico
2017-04-09 05:42:50,367 [Thread-8:3244] [django.request:170] [base:get_response] [WARNING]- Not Found: /admin/BOOK/chapter_article/add/assets/img/bullet.png/
2017-04-09 05:43:50,940 [Thread-12:14264] [django.request:170] [base:get_response] [WARNING]- Not Found: /admin/BOOK/chapter_article/add/assets/img/bullet.png/
2017-04-09 05:44:21,346 [Thread-16:12572] [django.request:170] [base:get_response] [WARNING]- Not Found: /images/codecolorer_bg.gif
2017-04-09 05:44:21,588 [Thread-17:12584] [django.request:170] [base:get_response] [WARNING]- Not Found: /admin/BOOK/chapter_article/add/assets/img/bullet.png/
2017-04-09 05:44:46,312 [Thread-21:14124] [django.request:170] [base:get_response] [WARNING]- Not Found: /images/codecolorer_bg.gif
2017-04-09 05:44:46,390 [Thread-22:7772] [django.request:170] [base:get_response] [WARNING]- Not Found: /admin/BOOK/chapter_article/add/assets/img/bullet.png/
2017-04-09 05:45:38,628 [Thread-26:10524] [django.request:170] [base:get_response] [WARNING]- Not Found: /admin/BOOK/chapter_article/add/assets/img/bullet.png/
2017-04-09 05:52:57,821 [Thread-54:14924] [django.request:170] [base:get_response] [WARNING]- Not Found: /images/codecolorer_bg.gif
2017-04-09 05:52:57,946 [Thread-55:14960] [django.request:170] [base:get_response] [WARNING]- Not Found: /admin/BOOK/chapter_article/add/assets/img/bullet.png/
2017-04-09 05:53:57,339 [Thread-59:14548] [django.request:170] [base:get_response] [WARNING]- Not Found: /images/codecolorer_bg.gif
2017-04-09 05:53:57,529 [Thread-60:14380] [django.request:170] [base:get_response] [WARNING]- Not Found: /admin/BOOK/chapter_article/add/assets/img/bullet.png/
2017-04-09 05:55:42,407 [Thread-12:14092] [django.request:170] [base:get_response] [WARNING]- Not Found: /images/codecolorer_bg.gif
2017-04-09 05:55:42,878 [Thread-13:15212] [django.request:170] [base:get_response] [WARNING]- Not Found: /admin/BOOK/chapter_article/add/assets/img/bullet.png/
2017-04-09 05:56:11,992 [Thread-17:15052] [django.request:170] [base:get_response] [WARNING]- Not Found: /images/codecolorer_bg.gif
2017-04-09 05:56:12,168 [Thread-18:13620] [django.request:170] [base:get_response] [WARNING]- Not Found: /admin/BOOK/chapter_article/add/assets/img/bullet.png/
2017-04-09 05:56:46,367 [Thread-22:14440] [django.request:170] [base:get_response] [WARNING]- Not Found: /images/codecolorer_bg.gif
2017-04-09 05:56:46,569 [Thread-23:5496] [django.request:170] [base:get_response] [WARNING]- Not Found: /admin/BOOK/chapter_article/add/assets/img/bullet.png/
2017-04-09 05:57:14,631 [Thread-27:13856] [django.request:170] [base:get_response] [WARNING]- Not Found: /images/codecolorer_bg.gif
2017-04-09 05:57:14,709 [Thread-28:14408] [django.request:170] [base:get_response] [WARNING]- Not Found: /admin/BOOK/chapter_article/add/assets/img/bullet.png/
2017-04-09 06:02:59,982 [Thread-43:14592] [django.request:170] [base:get_response] [WARNING]- Not Found: /book'
2017-04-09 06:03:16,174 [Thread-46:12464] [django.request:170] [base:get_response] [WARNING]- Not Found: /book/chapter
2017-04-09 06:03:18,190 [Thread-47:15052] [django.request:170] [base:get_response] [WARNING]- Not Found: /book/chapter
2017-04-09 06:38:46,114 [Thread-3:15600] [django.request:170] [base:get_response] [WARNING]- Not Found: /book/chapter
2017-04-09 06:38:47,483 [Thread-4:16336] [django.request:170] [base:get_response] [WARNING]- Not Found: /book/chapter
2017-04-09 06:38:48,092 [Thread-5:15192] [django.request:170] [base:get_response] [WARNING]- Not Found: /book/chapter
2017-04-09 06:41:15,105 [Thread-16:14656] [django.request:170] [base:get_response] [WARNING]- Not Found: /book/chapter
2017-04-10 03:23:03,305 [Thread-13:12624] [django.request:170] [base:get_response] [WARNING]- Not Found: /favicon.ico
2017-04-10 03:23:23,984 [Thread-14:12740] [django.request:170] [base:get_response] [WARNING]- Not Found: /other/about
2017-04-10 04:30:36,009 [Thread-100:5468] [django.request:256] [base:handle_uncaught_exception] [ERROR]- Internal Server Error: /blogarticle/
Traceback (most recent call last):
  File "c:\python27\lib\site-packages\django\core\handlers\base.py", line 132, in get_response
    response = wrapped_callback(request, *callback_args, **callback_kwargs)
  File "F:\workspaces\Linux_learn2\blog\views.py", line 129, in article
    return render(request, 'article.html', locals())
  File "c:\python27\lib\site-packages\django\shortcuts.py", line 67, in render
    template_name, context, request=request, using=using)
  File "c:\python27\lib\site-packages\django\template\loader.py", line 99, in render_to_string
    return template.render(context, request)
  File "c:\python27\lib\site-packages\django\template\backends\django.py", line 74, in render
    return self.template.render(context)
  File "c:\python27\lib\site-packages\django\template\base.py", line 209, in render
    return self._render(context)
  File "c:\python27\lib\site-packages\django\template\base.py", line 201, in _render
    return self.nodelist.render(context)
  File "c:\python27\lib\site-packages\django\template\base.py", line 903, in render
    bit = self.render_node(node, context)
  File "c:\python27\lib\site-packages\django\template\debug.py", line 79, in render_node
    return node.render(context)
  File "c:\python27\lib\site-packages\django\template\loader_tags.py", line 135, in render
    return compiled_parent._render(context)
  File "c:\python27\lib\site-packages\django\template\base.py", line 201, in _render
    return self.nodelist.render(context)
  File "c:\python27\lib\site-packages\django\template\base.py", line 903, in render
    bit = self.render_node(node, context)
  File "c:\python27\lib\site-packages\django\template\debug.py", line 79, in render_node
    return node.render(context)
  File "c:\python27\lib\site-packages\django\template\loader_tags.py", line 65, in render
    result = block.nodelist.render(context)
  File "c:\python27\lib\site-packages\django\template\base.py", line 903, in render
    bit = self.render_node(node, context)
  File "c:\python27\lib\site-packages\django\template\debug.py", line 79, in render_node
    return node.render(context)
  File "c:\python27\lib\site-packages\django\template\debug.py", line 89, in render
    output = self.filter_expression.resolve(context)
  File "c:\python27\lib\site-packages\django\template\base.py", line 674, in resolve
    new_obj = func(obj, *arg_vals)
  File "F:\workspaces\Linux_learn2\blog\templatetags\myfilter.py", line 8, in month_to_upper
    return ['涓€', '浜?, '涓?, '鍥?, '浜?, '鍏?, '涓?, '鍏?, '涔?, '鍗?, '鍗佷竴', '鍗佷簩'][key.month-1]
AttributeError: 'str' object has no attribute 'month'
2017-04-10 04:38:27,092 [Thread-120:12700] [django.request:170] [base:get_response] [WARNING]- Not Found: /book/cid=1
2017-04-10 05:49:52,954 [Thread-11:10244] [django.request:170] [base:get_response] [WARNING]- Not Found: /other/about
2017-04-10 06:25:13,240 [Thread-13:5508] [django.request:170] [base:get_response] [WARNING]- Not Found: /favicon.ico
2017-04-10 18:34:12,667 [Thread-3:6816] [django.request:170] [base:get_response] [WARNING]- Not Found: /favicon.ico
2017-04-12 02:28:19,102 [Thread-13:18404] [django.request:170] [base:get_response] [WARNING]- Not Found: /favicon.ico
2017-04-12 16:39:56,492 [Thread-13:8132] [django.request:170] [base:get_response] [WARNING]- Not Found: /favicon.ico
2017-04-12 17:03:55,108 [Thread-28:8444] [django.request:170] [base:get_response] [WARNING]- Not Found: /other/about
2017-04-12 17:03:57,631 [Thread-29:3440] [django.request:170] [base:get_response] [WARNING]- Not Found: /other/contact
2017-04-12 20:01:41,434 [Thread-80:9756] [django.request:170] [base:get_response] [WARNING]- Not Found: /home
2017-04-12 20:01:41,618 [Thread-81:9768] [django.request:170] [base:get_response] [WARNING]- Not Found: /home
2017-04-12 20:01:49,470 [Thread-82:9548] [django.request:170] [base:get_response] [WARNING]- Not Found: /video
2017-04-12 20:03:26,246 [Thread-92:12832] [django.request:170] [base:get_response] [WARNING]- Not Found: /other/follow
2017-04-12 20:03:29,065 [Thread-93:13036] [django.request:170] [base:get_response] [WARNING]- Not Found: /other/follow
2017-04-13 02:03:52,851 [Thread-13:19548] [django.request:170] [base:get_response] [WARNING]- Not Found: /favicon.ico
2017-04-13 02:29:39,127 [Thread-10:20420] [django.request:256] [base:handle_uncaught_exception] [ERROR]- Internal Server Error: /admin/VideoHome/video_category/add/
Traceback (most recent call last):
  File "c:\python27\lib\site-packages\django\core\handlers\base.py", line 132, in get_response
    response = wrapped_callback(request, *callback_args, **callback_kwargs)
  File "c:\python27\lib\site-packages\django\contrib\admin\options.py", line 616, in wrapper
    return self.admin_site.admin_view(view)(*args, **kwargs)
  File "c:\python27\lib\site-packages\django\utils\decorators.py", line 110, in _wrapped_view
    response = view_func(request, *args, **kwargs)
  File "c:\python27\lib\site-packages\django\views\decorators\cache.py", line 57, in _wrapped_view_func
    response = view_func(request, *args, **kwargs)
  File "c:\python27\lib\site-packages\django\contrib\admin\sites.py", line 233, in inner
    return view(request, *args, **kwargs)
  File "c:\python27\lib\site-packages\django\contrib\admin\options.py", line 1516, in add_view
    return self.changeform_view(request, None, form_url, extra_context)
  File "c:\python27\lib\site-packages\django\utils\decorators.py", line 34, in _wrapper
    return bound_func(*args, **kwargs)
  File "c:\python27\lib\site-packages\django\utils\decorators.py", line 110, in _wrapped_view
    response = view_func(request, *args, **kwargs)
  File "c:\python27\lib\site-packages\django\utils\decorators.py", line 30, in bound_func
    return func.__get__(self, type(self))(*args2, **kwargs2)
  File "c:\python27\lib\site-packages\django\utils\decorators.py", line 145, in inner
    return func(*args, **kwargs)
  File "c:\python27\lib\site-packages\django\contrib\admin\options.py", line 1470, in changeform_view
    self.log_addition(request, new_object)
  File "c:\python27\lib\site-packages\django\contrib\admin\options.py", line 810, in log_addition
    object_repr=force_text(object),
  File "c:\python27\lib\site-packages\django\utils\encoding.py", line 92, in force_text
    s = six.text_type(s)
  File "F:\workspaces\Linux_learn2\VideoHome\models.py", line 17, in __unicode__
    return self.Category_name
AttributeError: 'Video_Category' object has no attribute 'Category_name'
2017-04-13 02:29:46,424 [Thread-11:21588] [django.request:256] [base:handle_uncaught_exception] [ERROR]- Internal Server Error: /admin/VideoHome/video_category/add/
Traceback (most recent call last):
  File "c:\python27\lib\site-packages\django\core\handlers\base.py", line 132, in get_response
    response = wrapped_callback(request, *callback_args, **callback_kwargs)
  File "c:\python27\lib\site-packages\django\contrib\admin\options.py", line 616, in wrapper
    return self.admin_site.admin_view(view)(*args, **kwargs)
  File "c:\python27\lib\site-packages\django\utils\decorators.py", line 110, in _wrapped_view
    response = view_func(request, *args, **kwargs)
  File "c:\python27\lib\site-packages\django\views\decorators\cache.py", line 57, in _wrapped_view_func
    response = view_func(request, *args, **kwargs)
  File "c:\python27\lib\site-packages\django\contrib\admin\sites.py", line 233, in inner
    return view(request, *args, **kwargs)
  File "c:\python27\lib\site-packages\django\contrib\admin\options.py", line 1516, in add_view
    return self.changeform_view(request, None, form_url, extra_context)
  File "c:\python27\lib\site-packages\django\utils\decorators.py", line 34, in _wrapper
    return bound_func(*args, **kwargs)
  File "c:\python27\lib\site-packages\django\utils\decorators.py", line 110, in _wrapped_view
    response = view_func(request, *args, **kwargs)
  File "c:\python27\lib\site-packages\django\utils\decorators.py", line 30, in bound_func
    return func.__get__(self, type(self))(*args2, **kwargs2)
  File "c:\python27\lib\site-packages\django\utils\decorators.py", line 145, in inner
    return func(*args, **kwargs)
  File "c:\python27\lib\site-packages\django\contrib\admin\options.py", line 1470, in changeform_view
    self.log_addition(request, new_object)
  File "c:\python27\lib\site-packages\django\contrib\admin\options.py", line 810, in log_addition
    object_repr=force_text(object),
  File "c:\python27\lib\site-packages\django\utils\encoding.py", line 92, in force_text
    s = six.text_type(s)
  File "F:\workspaces\Linux_learn2\VideoHome\models.py", line 17, in __unicode__
    return self.Category_name
AttributeError: 'Video_Category' object has no attribute 'Category_name'
2017-04-13 02:36:40,122 [Thread-76:22244] [django.request:170] [base:get_response] [WARNING]- Not Found: /video
2017-04-13 02:36:41,986 [Thread-77:21556] [django.request:170] [base:get_response] [WARNING]- Not Found: /video
2017-04-13 02:38:40,835 [Thread-109:21152] [django.request:170] [base:get_response] [WARNING]- Not Found: /other/about
2017-04-13 02:38:43,763 [Thread-110:22504] [django.request:170] [base:get_response] [WARNING]- Not Found: /other/about
2017-04-13 02:38:48,940 [Thread-111:17332] [django.request:170] [base:get_response] [WARNING]- Not Found: /other/about
2017-04-13 02:38:56,177 [Thread-115:21800] [django.request:170] [base:get_response] [WARNING]- Not Found: /other/about
2017-04-13 03:22:41,736 [Thread-8:26132] [django.request:170] [base:get_response] [WARNING]- Not Found: /uploads/video/default.png
2017-04-13 03:23:39,335 [Thread-5:25352] [django.request:170] [base:get_response] [WARNING]- Not Found: /uploads/video/default.png
2017-04-13 03:30:22,588 [Thread-30:3432] [django.request:170] [base:get_response] [WARNING]- Not Found: /other/contact
2017-04-13 03:37:59,385 [Thread-22:28196] [django.request:170] [base:get_response] [WARNING]- Not Found: /favicon.ico
2017-04-13 03:38:11,770 [Thread-24:24408] [django.request:170] [base:get_response] [WARNING]- Not Found: /favicon.ico
2017-04-18 17:53:10,404 [Thread-13:6204] [django.request:170] [base:get_response] [WARNING]- Not Found: /favicon.ico
2017-04-21 06:41:56,069 [Thread-13:4836] [django.request:170] [base:get_response] [WARNING]- Not Found: /favicon.ico
2017-04-21 06:50:14,444 [Thread-68:5952] [django.request:170] [base:get_response] [WARNING]- Not Found: /blo
2017-04-21 07:45:07,282 [Thread-3:8200] [django.request:170] [base:get_response] [WARNING]- Not Found: /favicon.ico
2017-04-21 07:50:11,180 [Thread-44:12216] [django.request:170] [base:get_response] [WARNING]- Not Found: /blogcategory/portal.php
2017-04-22 03:36:38,023 [Thread-3:8116] [django.request:170] [base:get_response] [WARNING]- Not Found: /favicon.ico
2017-04-22 03:36:53,289 [Thread-4:11296] [django.request:170] [base:get_response] [WARNING]- Not Found: /other/about
2017-04-22 03:36:55,780 [Thread-5:5960] [django.request:170] [base:get_response] [WARNING]- Not Found: /other/contact
2017-04-22 03:37:01,151 [Thread-6:9320] [django.request:170] [base:get_response] [WARNING]- Not Found: /other/contact
2017-04-22 03:38:00,105 [Thread-18:11808] [django.request:170] [base:get_response] [WARNING]- Not Found: /other/follow
2017-04-22 03:38:23,696 [Thread-24:11424] [django.request:170] [base:get_response] [WARNING]- Not Found: /other/follow
2017-04-22 03:38:36,342 [Thread-29:6380] [django.request:170] [base:get_response] [WARNING]- Not Found: /other/about
2017-04-24 18:58:07,226 [Thread-13:11832] [django.request:170] [base:get_response] [WARNING]- Not Found: /favicon.ico
2017-04-25 01:46:47,142 [Thread-3:9896] [django.request:170] [base:get_response] [WARNING]- Not Found: /favicon.ico
2017-04-25 01:48:48,388 [Thread-21:13940] [django.request:170] [base:get_response] [WARNING]- Not Found: /admin/video
2017-04-25 01:55:48,648 [Thread-135:13652] [django.request:98] [csrf:_reject] [WARNING]- Forbidden (CSRF token missing or incorrect.): /admin/auth/group/1/
2017-04-25 02:48:46,382 [Thread-29:11376] [django.request:170] [base:get_response] [WARNING]- Not Found: /school/students
2017-04-25 02:48:46,453 [Thread-30:13672] [django.request:170] [base:get_response] [WARNING]- Not Found: /favicon.ico
